Workbook

Sheet 2026 OKR
A1: 维度 | B1: O（目标） | C1: KR | D1: 关键执行计划 | E1: 执行结果-修正
A2: 质量 | B2: O1: 消除Top质量问题，赋能一线排查能力，显著提升质量感受 | C2: KR1: 针对整网业务中断、全网智能巡检项异常 top2 问题进行攻坚，今年此类引发网上问题降低 30% | D2: 关键行动1: 整体梳理top2质量问题情况，包括工单分析与专家调研，与已有关键质量点合并，整体梳理优先事项，4月底完成 关键行动2: 6月底前梳理并落地交换机配置可靠专项计划及部分已知严重问题 关键行动3: H2逐步落地其他专项质量方案，从架构可靠性层面降低top 2问题发生风险
C3: KR2: 持续开发、迭代针对各类典型故障的专用AI skill，通用信息采集与排障工具，远程穿透工具，针对P1 P2问题开发排查效率提升100%，一线针对配置、网络类问题诊断能力，提效50% | D3: 关键行动1: 4月开发并推广内网代理工具 关键行动2: Q2逐步开发针对各类典型故障的专用AI skill，开发通用的 信息采集诊断工具箱，帮助快速诊断问题 关键行动3: Q3 排障skill持续优化，并与新版本AI排障相关优化l融合，做到新版本控制器P1 P2问题定位恢复效能提升150%，老版本会须效率提升100% 关键行动4： H2 排障skill叠加安全机制与封装，搭配远程穿透平台，信息收集工具封装成专用排障系统供一线使用，一线针对认证、配置、网络 top3问题项诊断能力，提效50%
C4: KR3: 完成自动化兜底搭建，客户核心业务场景用例库建立并覆盖其中70%场景，杜绝改动引发导致核心业务中断 | D4: 关键行动1: 4月中旬，与AI Coding结合的重构自动化开发与执行框架落地，Demo跑通 关键行动2: 6月底，核心业务场景用例库覆盖10%，提效到人均用例开发效能提升15例天 关键行动3: 9月底，核心业务场景用例库覆盖40%，提效到人均用例开发效能提升20例天 关键行动4: 12月底，核心业务场景用例库覆盖70%
A5: 价值 | B5: O2: 打造 AI Native 赋能网络，显著提升客户产品易用性与智能化感受 | C5: KR1: 锚定痛点运维场景给予Ai Native赋能。通过自然语言交互，在目标价值场景做到Job闭环 | D5: 关键行动1: 4月,调研清楚客户管理、运维网络高频top痛点场景，确定2026年目标场景 关键行动2: 5月底通过AI Native网络1.0charter规划 关键行动3: H2完成版本开发，完成前3beta认可 关键行动4: H2完成AI Native网络2.0需求洞察与charter规划
C6: KR2: AI Native网络版本过程与至少 3 家高价值客户/渠道论证、共创与落地，完成标杆打造与价值论证 | D6: 关键行动1: AI Native网络版本过程与至少 3 家高价值客户/渠道论证、共创与落地，完成标杆打造与价值论证
B7: O3: 可成长网络架构落地，集群支持业务不间断扩容/改造/upgrade，最大化客户网络资产长效使用价值 | C7: KR1: 完成已规划集群版本顺利落地，梳理补齐剩余场景，集群设备间支持软硬件兼容，单机平台、独立交换机无损加平台。 | D7: 关键行动1: 5月中旬完成集群1.0版本发布，支持集群设备间支持软硬件兼容 关键行动2: 6月底完成N合一版本发布，支持单机平台无损加平台 关键行动3: H2梳理并完成价值回收及主要高价值需求点落地
C8: KR2: beta 客户重点保障，完成top 3客户平稳落地集群，无整网中断，保障价值推广 | D8: 关键行动1:beta 客户重点保障，完成top 3客户平稳落地集群，无整网中断，保障价值推广
A9: AI转身 | B9: O4: 完成AI Native转身，打造AI业务创新孵化池，大幅提升部门效能、创新能力 | C9: KR1: 完成AI Native 全流程改造，前后端融合，测试前移，测开效能100%，项目周期缩短40% | D9: 关键行动1: 4月完成主要开发环节AI Coding改造，CI集成，编码、调试环节效能提升40% 关键行动2: 5月实现简单bug与简单需求实现黑灯模式开发，整个环节彻底打通，形成稳定高效的AI基建，测开效能提升50% 关键行动3: 7月完成前后端融合，测开效能提升70% 关键行动4: 10月底，测试测开工作左移，各主要开发环节完成Ai Native改造并全员赋能，测开效能提升100%，项目端到端开发周期缩短40%
C10: KR2:完成 Ai Native业务创新基建，让部门同事可通过简易编排AI业务流进行创新孵化，全年落地不少于10项出自团队的AI创新，不少于10篇AI专利 | D10: 关键行动1: 5月完成AI Native业务创新平台开发，可支持智能编排基础业务，支撑部门业务创新 关键行动2: 全年落地不少于10项出自团队的AI创新，不少于10篇AI专利
A11: 组织建设 | B11: O5: 构建贴近客户、攻坚克难的骨干班子，建立配比合理的关键人才储备 | C11: KR1： 打造走进客户的研发骨干团队，每季度均有核心骨干探访客户，深入理解客户用网、管网痛点，产出高质量拜访报告，至少3项易用性价值创新
C12: KR2: 对关键岗位人员高要求，每半年在技术领先、疑难攻克、AI创新上不止一项关键难题，作为考核点，勇于攻坚克难
C13: KR3: 关键岗位1:2后备（含年轻后备），年轻人员在核心任务贡献比例大幅提升
A14: 需要协助: 1. 体系外部: 技服体系一起识别、共创、推广AI排障平台系列工具 2. 体系内部: 下半年AI项目，会涉及到AP、SW侧能力开发，预计各2人

Sheet 2026人力计划
A1: 工号 | B1: 姓名 | C1: （任职认证）任职等级1 | D1: 岗位 | E1: 关键岗位 | F1: 入职时间 | G1: 毕业学校 | H1: 最高学历 | I1: 团队 | J1: 年度定位 | K1: 46113 | L1: 46143 | M1: 46174 | N1: 46204 | O1: 46235 | P1: 46266 | Q1: 46296 | R1: 46327 | S1: 46357 | U1: 资源缺口
A2: 22026 | B2: 刘涛 | C2: P4 | D2: 管理 | E2: 部门主管 | F2: 43291 | G2: 中南大学 | H2: 本科 | K2: 管理 | L2: 管理 | M2: 管理 | N2: 管理 | O2: 管理 | P2: 管理 | Q2: 管理 | R2: 管理 | S2: 管理 | U2: 测试 4
A3: 89476 | B3: 王毅 | C3: NA | D3: 规划 | E3: 规划经理 | F3: 44099 | G3: 华南理工大学广州学院 | H3: 本科 | K3: 规划 | L3: 规划 | M3: 规划 | N3: 规划 | O3: 规划 | P3: 规划 | Q3: 规划 | R3: 规划 | S3: 规划 | U3: 开发 3
A4: 24934 | B4: 朱辉 | C4: M6 | D4: 管理 | E4: PMO | F4: 41036 | G4: 武汉大学 | H4: 本科 | J4: 项目管理，为项目进度、质量、跨部门协作负责 | K4: 管理 | L4: 管理 | M4: 管理 | N4: 管理 | O4: 管理 | P4: 管理 | Q4: 管理 | R4: 管理 | S4: 管理
A5: 12383 | B5: 曹奕 | C5: T4 | D5: 开发 | E5: AI专家 | F5: 44627 | G5: 成都信息工程学院 | H5: 本科 | I5: AI智网 | J5: AI Agent选项、设计、开发核心专家 | K5: AI业务编排Demo | L5: AI业务编排Demo | M5: AI智网1.0 | N5: AI智网1.0 | O5: AI智网1.0 | P5: AI智网1.0 | Q5: AI智网1.0 | R5: AI智网1.0 | S5: AI智网1.0
A6: 12944 | B6: 张志 | C6: T3 | D6: 开发 | E6: AI布道师 | F6: 44440 | G6: 华南理工大学 | H6: 本科 | I6: AI智网 | K6: AI基建打造 | L6: AI基建打造 | M6: AI基建打造 | N6: AI基建打造 | O6: AI基建打造 | P6: AI基建打造 | Q6: AI智网1.0 | R6: AI智网1.0 | S6: AI智网1.0
A7: 17795 | B7: 彭清华 | C7: T5 | D7: 开发 | F7: 44265 | G7: 安徽科技学院 | H7: 本科 | I7: 云切换 | K7: 集群1.0 | L7: 集群1.0 | M7: 集群1.0 | N7: 云切换 | O7: 云切换 | P7: 云切换 | Q7: 集群2.0 | R7: 集群2.0 | S7: 集群2.0
A8: 19083 | B8: 陈加广 | C8: T4 | D8: 开发 | F8: 42459 | G8: 北京理工大学珠海学院 | H8: 本科 | I8: go | K8: 技术支持
A9: 20811 | B9: 黄宇成 | C9: T4 | D9: 开发 | F9: 43245 | G9: 北京理工大学珠海学院 | H9: 本科 | I9: AI智网 | K9: 集群1.0 | L9: 集群1.0 | M9: 集群1.0 | N9: Q3大质量 | O9: Q3大质量 | P9: 技术支持 | Q9: 技术支持 | R9: 技术支持 | S9: Q4大质量
A10: 23418 | B10: 吴盾 | C10: T2 | D10: 开发 | F10: 46099 | G10: 北京联合大学 | H10: 本科 | I10: 支撑 | K10: 定制 | L10: 定制 | M10: 定制 | N10: 技术支持 | O10: 技术支持 | P10: 技术支持 | Q10: 技术支持 | R10: 技术支持 | S10: 技术支持
A11: 29050 | B11: 杨旭 | C11: T4 | D11: 开发 | F11: 43915 | G11: 广东工业大学 | H11: 本科 | I11: 质量 | K11: 集群1.0 | L11: 集群1.0 | M11: 技术支持 | N11: 技术支持 | O11: 技术支持 | P11: AI智网1.0 | Q11: AI智网1.0 | R11: AI智网1.0 | S11: AI智网1.0
A12: 37791 | B12: 商书畅 | C12: T2 | D12: 开发 | F12: 44193 | G12: 华南农业大学 | H12: 本科 | I12: AI智网 | K12: 易用性1.0 | L12: 易用性1.0 | M12: AI业务编排Demo | N12: AI智网1.0 | O12: AI智网1.0 | P12: AI智网1.0 | Q12: AI智网1.0 | R12: AI智网1.0 | S12: AI智网1.0
A13: 52012 | B13: 张浩 | C13: T2 | D13: 开发 | F13: 43983 | G13: 广东工业大学 | H13: 本科 | I13: 技术支持 | K13: 定制 | L13: 技术支持 | M13: 技术支持 | N13: 技术支持 | O13: 技术支持 | P13: 技术支持 | Q13: 技术支持 | R13: 技术支持 | S13: 技术支持
A14: 53558 | B14: 伍连啟 | C14: T4 | D14: 开发 | F14: 42562 | G14: 华中科技大学 | H14: 硕士 | I14: 质量 | K14: 交换机无损 | L14: 交换机无损 | M14: 交换机无损 | N14: 交换机无损 | O14: 交换机无损 | P14: 交换机无损 | Q14: Q4大质量 | R14: Q4大质量 | S14: Q4大质量
A15: 54477 | B15: 张晓东 | C15: T5 | D15: 开发 | E15: TL | F15: 43068 | G15: 深圳大学 | H15: 本科 | I15: AI智网 | K15: 集群1.0 | L15: 集群1.0 | M15: 集群1.0 | N15: AI智网1.0 | O15: AI智网1.0 | P15: AI智网1.0 | Q15: AI智网1.0 | R15: AI智网1.0 | S15: AI智网1.0
A16: 56862 | B16: 林颖 | C16: T2 | D16: 开发 | F16: 45362 | G16: 辽宁工程技术大学 | H16: 本科 | I16: 定制 | K16: 集群1.0 | L16: 集群1.0 | M16: 集群1.0 | N16: 定制 | O16: 定制 | P16: 定制 | Q16: 定制 | R16: 定制 | S16: 定制
A17: 62555 | B17: 马垣德 | C17: T2 | D17: 开发 | F17: 41071 | G17: 鲁东大学 | H17: 本科 | I17: AI智网 | K17: 集群1.0 | L17: 集群1.0 | M17: 集群1.0 | N17: AI智网1.0 | O17: AI智网1.0 | P17: AI智网1.0 | Q17: AI智网1.0 | R17: AI智网1.0 | S17: AI智网1.0
A18: 72205 | B18: 李辉 | C18: T2 | D18: 开发 | F18: 43291 | G18: 华南理工大学 | H18: 硕士 | I18: AI智网 | K18: 集群1.0 | L18: 集群1.0 | M18: AI智网1.0 | N18: AI智网1.0 | O18: AI智网1.0 | P18: AI智网1.0 | Q18: AI智网1.0 | R18: AI智网1.0 | S18: AI智网1.0
A19: 72479 | B19: 冯皓洋 | C19: T2 | D19: 开发 | F19: 43035 | G19: 龙岩学院 | H19: 本科 | I19: 定制 | K19: 集群1.0 | L19: 定制 | M19: 定制 | N19: 定制 | O19: 定制 | P19: 定制 | Q19: 定制 | R19: 定制 | S19: 定制
A20: 72949 | B20: 孟洋 | C20: T7 | D20: 开发 | F20: 42552 | G20: 武汉科技大学 | H20: 本科 | I20: AI智网 | K20: 集群1.0 | L20: 集群1.0 | M20: 集群1.0 | N20: AI智网1.0 | O20: AI智网1.0 | P20: AI智网1.0 | Q20: AI智网1.0 | R20: AI智网1.0 | S20: AI智网1.0
A21: 76442 | B21: 韩文龙 | C21: T7 | D21: 开发 | E21: TL | F21: 46003 | G21: 郑州轻工业大学 | H21: 本科 | I21: 质量 | K21: 集群1.0 | L21: 集群1.0 | M21: 易用性1.0 | N21: Q3大质量 | O21: Q3大质量 | P21: Q3大质量 | Q21: Q4大质量 | R21: Q4大质量 | S21: Q4大质量
A22: 77251 | B22: 陈金俊 | C22: T7 | D22: 开发 | E22: 架构师 | F22: 45901 | G22: 深圳大学 | H22: 硕士 | I22: 架构师 | K22: Q2大质量 | L22: Q2大质量 | M22: Q2大质量 | N22: Q3大质量 | O22: Q3大质量 | P22: Q3大质量 | Q22: Q4大质量 | R22: Q4大质量 | S22: Q4大质量
A23: 77303 | B23: 李菁 | C23: T2 | D23: 开发 | F23: 41099 | G23: 汕头大学 | H23: 本科 | I23: AI智网 | K23: 集群1.0 | L23: 集群1.0 | M23: 易用性1.0 | N23: AI智网1.0 | O23: AI智网1.0 | P23: AI智网1.0 | Q23: AI智网1.0 | R23: AI智网1.0 | S23: AI智网1.0
A24: 81343 | B24: 詹智钦 | C24: T2 | D24: 开发 | F24: 45110 | G24: 哈尔滨理工大学 | H24: 本科 | I24: AI智网 | K24: 集群1.0 | L24: 集群1.0 | M24: 易用性1.0 | N24: AI智网1.0 | O24: AI智网1.0 | P24: AI智网1.0 | Q24: AI智网1.0 | R24: AI智网1.0 | S24: AI智网1.0
A25: 91418 | B25: 刘威 | C25: T2 | D25: 开发 | F25: 42919 | G25: 重庆邮电大学 | H25: 硕士 | I25: 质量 | K25: 集群1.0 | L25: 集群1.0 | M25: 易用性1.0 | N25: Q3大质量 | O25: Q3大质量 | P25: Q3大质量 | Q25: Q4大质量 | R25: Q4大质量 | S25: Q4大质量
A26: 92042 | B26: 唐小伟 | C26: T5 | D26: 开发 | F26: 42555 | G26: 重庆邮电大学 | H26: 硕士 | I26: AI智网 | K26: 集群1.0 | L26: 集群1.0 | M26: 集群1.0 | N26: AI智网1.0 | O26: AI智网1.0 | P26: AI智网1.0 | Q26: AI智网1.0 | R26: AI智网1.0 | S26: AI智网1.0
A27: 96208 | B27: 王维 | C27: T7 | D27: 开发 | F27: 45901 | G27: 广东工业大学 | H27: 硕士 | I27: 质量 | K27: 技术支持 | L27: 技术支持 | M27: Q3大质量 | N27: Q3大质量 | O27: Q3大质量 | P27: Q3大质量 | Q27: Q4大质量 | R27: Q4大质量 | S27: Q4大质量
A28: 96634 | B28: 涂瀚宇 | C28: T2 | D28: 开发 | F28: 44746 | G28: 江西财经大学 | H28: 本科 | I28: go | K28: 集群1.0 | L28: 集群1.0 | M28: 集群1.0
A29: 97224 | B29: 孙忠彦 | C29: T2 | D29: 开发 | F29: 45954 | G29: 华南农业大学 | H29: 硕士 | I29: AI智网 | K29: 自动化 | L29: 自动化 | M29: 自动化 | N29: AI智网1.0 | O29: AI智网1.0 | P29: AI智网1.0 | Q29: AI智网1.0 | R29: AI智网1.0 | S29: AI智网1.0
B30: 校招1 | D30: 开发 | I30: AI智网 | J30: AI智网 | K30: AI智网 | L30: AI智网 | M30: AI智网 | N30: AI智网1.0 | O30: AI智网1.0 | P30: AI智网1.0 | Q30: AI智网1.0 | R30: AI智网1.0 | S30: AI智网1.0
B31: 校招2 | D31: 开发 | I31: AI智网 | J31: AI智网 | K31: AI智网 | L31: AI智网 | M31: AI智网 | N31: AI智网1.0 | O31: AI智网1.0 | P31: AI智网1.0 | Q31: AI智网1.0 | R31: AI智网1.0 | S31: AI智网1.0
B32: 校招3 | D32: 开发 | I32: AI智网 | J32: AI智网 | K32: AI智网 | L32: AI智网 | M32: AI智网 | N32: AI智网1.0 | O32: AI智网1.0 | P32: AI智网1.0 | Q32: AI智网1.0 | R32: AI智网1.0 | S32: AI智网1.0
A33: 99812 | B33: 赵呈祥 | C33: T2 | D33: 开发 | F33: 45839 | G33: 广东工业大学 | H33: 硕士 | I33: go | K33: 集群1.0 | L33: 集群1.0 | M33: 集群1.0
A34: 93622 | B34: 黄涛 | C34: T4 | D34: UI | E34: js专家 | F34: 42562 | G34: 电子科技大学 | H34: 本科 | I34: AI智网 | K34: 集群1.0 | L34: 集群1.0 | M34: 集群1.0 | N34: AI智网1.0 | O34: AI智网1.0 | P34: AI智网1.0 | Q34: AI智网1.0 | R34: AI智网1.0 | S34: AI智网1.0
A35: 89973 | B35: 苏华迪 | C35: T5 | D35: UI | F35: 43672 | G35: 广东工业大学 | H35: 本科 | I35: go | K35: 技术支持 | L35: 技术支持 | M35: 技术支持
A36: 29586 | B36: 刘秋兰 | C36: T4.3 | D36: UI | E36: 视觉 | F36: 42499 | G36: 武汉纺织大学 | H36: 本科 | I36: 视觉 | K36: 视觉 | L36: 视觉 | M36: 视觉 | N36: 视觉 | O36: 视觉 | P36: 视觉 | Q36: 视觉 | R36: 视觉 | S36: 视觉
A37: 37038 | B37: 王永强 | C37: T4 | D37: UI | F37: 41019 | G37: 哈尔滨理工大学 | H37: 硕士 | I37: go | K37: 支撑(无线、交换) | L37: 支撑(无线、交换) | M37: 支撑(无线、交换)
A38: 14659 | B38: 夏国富 | C38: T4 | D38: UI | F38: 46036 | G38: 陕西理工大学 | H38: 本科 | I38: 技术支持 | K38: 集群1.0 | L38: 集群1.0 | M38: 集群1.0 | N38: 技术支持 | O38: 技术支持 | P38: 技术支持 | Q38: 技术支持 | R38: 技术支持 | S38: 技术支持
A39: 17220 | B39: 杨建锋 | C39: T4 | D39: UI | F39: 45840 | G39: 西安工业大学 | H39: 本科 | I39: go | K39: 集群1.0 | L39: 集群1.0 | M39: 集群1.0
A40: 75912 | B40: 刘华腾 | C40: T6.4 | D40: UI | E40: 交互 | F40: 42191 | G40: 武汉理工大学 | H40: 硕士 | I40: go | K40: 集群1.0
...

Sheet 2026业务投资地图(Q3)
A1: 业务投资分解(Q3) | H1: 人力分布 | L1: 目标客户
A2: 类型 | B2: 业务方向 | C2: 开发目标投入 | D2: 子方向 | E2: 开发 | F2: UED | G2: 测试 | H2: 开发 | I2: UED | J2: 测试 | K2: Q4 | L2: 制造业、大企业、医疗等行业上攻战略大客户
A3: AI智网1.0 | B3: AI | C3: 21 | D3: AI Agent核心框架 | E3: 2 | F3: 4 | G3: 4 | H3: 曹奕,孙忠彦 | I3: 彭依岳 黄双 赵锐辉 校招1 | J3: 朱鑫涛 张伟涛 校招1 校招2
D4: 整网能力Cli化框架设计与基建开发 | E4: 1 | H4: 孟洋
D5: AI Agent SKILL开发 | E5: 2 | H5: 商书畅，李菁
D6: NMC侧与设备侧-基础能力演进 | E6: 5 | H6: 张晓东,马垣德,唐小伟,校招生1,詹智钦
D7: NMC侧开发-接口改造 | E7: 2 | H7: 校招生2,校招生3
D8: 设备侧开发-接口改造 | E8: 1 | H8: 李辉
D9: 全网智能巡检项优化 | E9: 1 | H9: 刘威
A10: Q3质量版本 | B10: 质量 | C10: 11 | D10: portal性能优化+去数据面 | E10: 2 | F10: 2 | G10: 3 | H10: 韩文龙，陈金俊 | I10: 张洁 黄涛 | J10: 许剑华 陈硕鑫 校招3
D11: 其他梳理出的断网专项优化、质量专项挖掘 | E11: 2 | H11: 王维,黄宇成
B12: 集群2.0 | D12: 交换机无损 | E12: 1 | H12: 伍连啟
B13: 网关 | D13: 小信云无损切换，关键价值补齐 | E13: 1 | H13: 彭清华
A14: 自动化 | B14: 自动化 | C14: 2 | D14: 自动化补全 | G14: 2 | I14: 郑泽滨 张碧玲
A15: 技术支持 | B15: 技术支持 | C15: 9 | D15: 技术支持 | E15: 3 | F15: 2 | G15: 2 | H15: 吴盾，杨旭，张浩 | I15: 夏国富 何星宇 | J15: 陈子龙
D16: 定制 | E16: 2 | H16: 林颖,冯皓洋 | J16: 校招4
A17: 支撑 | B17: 支撑 | C17: 3 | D17: 无线、交换UI | F17: 2 | I17: 罗彦淋 叶恩福
D18: 视觉 | F18: 1 | I18: 刘秋兰
A19: AI布道 | B19: AI布道 | C19: 1 | D19: AI布道 | E19: 1 | H19: 张志
A20: 规划 | B20: 规划 | C20: 1 | D20: AI智网系列洞察与规划 | E20: 1 | H20: 王毅
A21: 管理 | B21: 管理 | C21: 2 | D21: PMO | E21: 1 | H21: 朱辉
D22: 部门主管 | E22: 1 | H22: 刘涛
A23: 研发投资地图
A24: 版本 | B24: 开发 | C24: 测试 | D24: UED
A25: AI智网 | B25: 13 | C25: 4 | D25: 4
A26: Q3质量版本 | B26: 7 | C26: 3 | D26: 2
A27: 自动化 | C27: 2
A28: 技术支持 | B28: 5 | C28: 2 | D28: 2
A29: 支撑 | D29: 3
A30: 规划 | B30: 1
A31: AI布道 | B31: 1
A32: 管理 | B32: 2
A33: 总人数 | B33: ==SUM(B25:B32) -> 29 | C33: ==SUM(C25:C32) -> 11 | D33: ==SUM(D25:D32) -> 11

Sheet 26年roadmap
B1: 26Q1 | C1: 26Q2 | D1: 26Q3 | E1: 26Q4
A2: 集群 | C2: 集群1.0(5.15beta发布) - 灰度升级 - 双机切换优化 集群2.0 正式发布 (6.30) - 交换机管理易用性提升 - 单平台无损加入 - 运维操作连贯性
A3: AI智网1.0 | C3: AI智网Demo | D3: AI智网1.0 - | E3: AI智网1.0 -
A4: 大质量 | C4: Q2大质量 | D4: Q3大质量 | E4: Q4大质量

Sheet 责任田(2026)
A1: 团队-TL | B1: 责任田 | C1: 维度 | D1: 维度细分 | E1: 目标 | F1: 当前现状 | G1: 下一步举措
A2: NMC-全局数据 | B2: 整体质量 | C2: 客户满意度 | D2: 质量/SLA | E2: Top2问题下降20%
B3: AI转身
B4: 效能
A5: 测试-郑泽滨 | B5: 自动化 | C5: 可测试性 | D5: 自动化覆盖 | E5: 核心场景自动化端到端覆盖: 70% 新版本自动化用例覆盖: 80% | F5: 自动化系统老旧，难以维护高效开发 核心场景自动化覆盖率不足3%
A6: AI转身虚拟团队-张志 | B6: AI提效 | C6: AI效能
A7: 质量-韩文龙 | B7: 设备管理 认证授权 流量转发 网关
A8: AI-张晓东 | B8: 基础运维 全网智能 AI Agent

Sheet 跨部门协作需求
A1: 主导部门 | B1: 协作部门 | C1: 协作项 | D1: 协作项完成时间 | E1: 合入版本的发布时间 | F1: 主导部门合入版本 | G1: 是否达成一致 | H1: 是否完成 | I1: 备注 | J1: 协作接口人 | K1: 责任人 （产线主管） | L1: 状态
A2: NMC | B2: 无线/交换 | C2: AI智网1.0设备侧核心业务开发需要无线、交换支撑，以便在目标场景打造最佳闭环效果 | D2: 2026.Q4 | E2: 2026.Q4 | F2: 待定
A3: 无线 | B3: NMC | C3: 支撑无线下半年落地版本WEB开发 | F3: 待定
A4: 交换机 | B4: NMC | C4: 支撑交换机下半年版本WEB开发与控制器配置下发适配 | F4: 待定

Sheet 核心业务盘点
B1: 认证授权(核心) | G1: 集群设备管理(核心) | K1: 转发(核心) | N1: 运维(核心) | Q1: 合规 | S1: 小信云 | T1: 信锐conduct | U1: 云管家
A2: 业务 | B2: 二层认证 | C2: 三层认证 | D2: portal对接 | E2: 准入授权 | F2: 终端识别 | G2: 控制隧道 | H2: 配置下发 | I2: 双机 | J2: 集中管理 | K2: 数据面 | L2: 网关驱动 | M2: 网关业务 | N2: GPT AI | O2: 全网智能 | P2: 告警 | Q2: 网监 | R2: 数据中心 | S2: 小信云 | T2: app+小程序 | U2: 云管家
A3: 刘涛
A4: 陈金俊 | W4: 需要掌控
A5: 韩文龙 | W5: 已掌控
A6: 张晓东 | W6: 需要熟悉
A7: 曹奕
A8: 杨旭
A9: 黄宇成
A10: 刘威
A11: 孟洋
A12: 王维
A13: 彭清华
A14: 张志
A15: 2+3业务核心 | B15: 核心业务分为四块: 认证授权 集群管理 转发 运维，此块要分别有4人熟悉相关业务关键业务，衡量标准是能针对核心架构难点给出解决方案。分别为: 陈金俊，本身作为架构师，需要熟悉全部控制器、网关架构，需精通集群设备管理业务，衡量标准: 全面梳理平台到平台、平台到设备的配置下发流程，梳理出重构方案，提升设备管理性能与可靠性。做到: ① 梳理核心数据库的转换同步逻辑，消除现在各进程分别维护导致集群配置同步、双机配置同步的完整性、可靠性与性能参差不齐 ② AP、SW等边缘设备管理性能大幅提升，配置更新做到不全量刷新内存，修剪掉已不存在的无效耗性能业务，单机管理性能就配置层面比现在指标提升3倍，提升配置下发可靠性，消除目前存在的惊群效应 ③ 提升双机配置同步、消息同步服务性能，目标管理规模下双机配置、消息不丢，目前存在严重的单cpu瓶颈及万ap级单机双机同步丢消息 ④ 相关疑难问题兜底 韩文龙，需要精通认证授权业务，梳理出重构方案，提升认证授权性能与可靠性，做到: ① 如何防止改动引发导致的核心业务中断，或业务中断情况下能认证降级或逃生 ② 二层认证、三层认证、portal认证支持熔断限流，性能到瓶颈时，保证性能下终端认证业务正常，性能上终端灾备或有序上线 ② 整体提升在大并发下认证问题排查及时性，避免当前排查效率低下情况 ③ 大幅提升portal性能，应对突发大流量情况，满足大客户并发要求 ④ 双机情况，认证支持负载均衡，热备认证授权架构上保障无异常，对业务透明 ⑤ 相关疑难问题兜底 张晓东，需要精通转发业务，提升转发丢包可排查下，无损接管小信云场景设计梳理。做到: ① 无线转发丢包、ACL业务排查，大流量下可排查性 ② 小信云无损接管方案场景梳理、设计与监管落地 ③ 网卡损坏，数据面可除该网卡外，业务正常 ④ 相关疑难问题兜底 曹奕，需要精通运维业务，提升运维架构的可扩展性、探索支撑AI新场景、优化老场景。做到: ① 为常用运维需求设计统一数据存储分析平台，建立强管控上报机制(管控设备能否上报、上报频次、上报标准)，提升数据分析开发效能与性能，提升对边缘设备数据上报精细化管控 ② 提升目前AI工作流性能，以及构建面向AI的数据、配置架构，探索、支持更多AI应用场景在设备落地 ③ 告警及时性提升，严重问题1min内告警触达；人性化提升，告警合并与否，如何合并，推送频次可灵活满足需求，支持告警升级 ③ 相关疑难问题兜底 此外，针对UI支撑部门，张洁作为责任人，尝试能否用AI安全可靠的将JS架构全部转为VUE，php尝试转换为go，降低部门业务上手难度与提升技术栈复用性
A18: N | B18: 如上图所示
A19: 计划 | B19: 1. 分派专门质量项，安排各负责人进行总设，按月汇报进展 2. 版本落地，如下半年的去数据面、AI专项，安排对应培养方向人员支撑 3. 疑难问题排查，安排对应方向培养人才支撑

Sheet 计划roadmap
A1: 从9月开始，控制器高可用投入人力提升为10人，对其他项目和工作影响为： 1. gpt、全网智能无人力支撑优化 2. SIG三期预计延到明年1月底 3. 后台质量投入降为2人，勉强合入严重网上问题与支援其他产品线控制器问题，无人力支撑大客户定制 4. 易用性后台无法投入，需等Q4新人入职才能开发 5. UI质量投入变为1人，也无人力支撑突发大客户定制 6. bgp这块没人力做开发，方案研究可由刘涛承接研究
A2: 工号 | B2: 姓名 | C2: 职级 | D2: 一级部门 | E2: 二级部门 | F2: 三级部门 | G2: 原部门 | H2: 岗位 | I2: 入职时间 | J2: 当前 | K2: 8月 | L2: 9月 | M2: 10月 | N2: 11月 | O2: 12月 | P2: 1月 | Q2: 易用性1.0 | R2: 3月 | S2: 4月 | T2: 5月 | U2: 6月 | V2: 7月 | W2: 8月 | X2: 9月 | Y2: 10月 | Z2: 11月 | AA2: 12月
A3: 12383 | B3: 曹奕 | C3: T4 | D3: 软件研发体系 | E3: 基础网络 | F3: NMC软件研发部 | H3: 软件开发工程师 | I3: 44627 | J3: GPT | K3: GPT | L3: 控制器高可用 | M3: 控制器高可用 | N3: 控制器高可用 | O3: 控制器高可用 | P3: 控制器高可用 | Q3: 易用性1.0 | R3: 易用性1.0
A4: 72205 | B4: 李辉 | Q4: 易用性1.0 | R4: 易用性1.0
A5: 77303 | B5: 李菁 | Q5: 易用性1.0 | R5: 易用性1.0
A6: 37791 | B6: 商书畅 | Q6: 易用性1.0 | R6: 易用性1.0
A7: 71199 | B7: 阮文轩 | Q7: 易用性1.0 | R7: 易用性1.0
A8: 17795 | B8: 彭清华 | C8: T5 | D8: 软件研发体系 | E8: 基础网络 | F8: NMC软件研发部 | H8: 软件开发工程师 | I8: 43245 | J8: SIG二期 | K8: SIG二期 | L8: SIG三期 | M8: SIG三期 | N8: SIG三期 | O8: SIG三期 | P8: SIG三期 | Q8: 集群1.0 | R8: 集群1.0 | S8: 集群1.0 | T8: 集群1.0 | U8: 集群1.0
A9: 23418 | B9: 吴盾 | C9: T2 | D9: 软件研发体系 | E9: 基础网络 | F9: NMC软件研发部 | G9: FEX | H9: 软件开发工程师 | I9: 45362 | J9: SIG二期 | K9: N合一 | L9: 定制 | M9: 定制 | N9: 定制 | O9: 定制 | P9: 定制 | Q9: 定制 | R9: 定制
A10: 29050 | B10: 杨旭 | C10: T4 | D10: 软件研发体系 | E10: 基础网络 | F10: NMC软件研发部 | H10: 软件开发工程师 | I10: 43291 | J10: VILG国产化 | K10: 控制器高可用 | L10: 控制器高可用 | M10: 控制器高可用 | N10: 控制器高可用 | O10: 控制器高可用 | P10: 控制器高可用 | Q10: 集群1.0 | R10: 集群1.0 | S10: 集群1.0
A11: 54477 | B11: 张晓东 | C11: T5 | D11: 大研发体系 | E11: 基础网络 | F11: NMC软件研发部 | H11: 软件开发工程师 | I11: 42552 | J11: SIG二期 | K11: SIG二期 | L11: 控制器高可用 | M11: 控制器高可用 | N11: 控制器高可用 | O11: 控制器高可用 | P11: 控制器高可用 | Q11: 集群1.0 | R11: 集群1.0 | S11: 集群1.0
A12: 62555 | B12: 马垣德 | C12: T2 | D12: 软件研发体系 | E12: 基础网络 | F12: NMC软件研发部 | H12: 软件开发工程师 | I12: 45840 | J12: SIG二期 | K12: SIG二期 | L12: SIG三期 | M12: SIG三期 | N12: SIG三期 | O12: SIG三期 | P12: SIG三期 | Q12: 集群1.0 | R12: 集群1.0 | S12: 集群1.0
A13: 56862 | B13: 林颖 | C13: T2 | D13: 软件研发体系 | E13: 基础网络 | F13: NMC软件研发部 | L13: SIG三期 | M13: SIG三期 | N13: SIG三期 | O13: SIG三期 | P13: SIG三期 | Q13: SIG三期 | R13: SIG三期
A14: 72479 | B14: 冯皓洋 | C14: T2 | D14: 软件研发体系 | E14: 基础网络 | F14: NMC软件研发部 | H14: 软件开发工程师 | I14: 45840 | J14: SIG二期 | K14: SIG二期 | L14: 控制器高可用 | M14: 控制器高可用 | N14: 控制器高可用 | O14: 控制器高可用 | P14: 控制器高可用 | Q14: 易用性1.0 | R14: 易用性1.0
A15: 81343 | B15: 詹智钦 | C15: T2 | D15: 软件研发体系 | E15: 基础网络 | F15: NMC软件研发部 | H15: 软件开发工程师 | I15: 45840 | J15: SIG二期 | K15: SIG二期 | L15: 控制器高可用 | M15: 控制器高可用 | N15: 控制器高可用 | O15: 控制器高可用 | P15: 控制器高可用 | Q15: 集群1.0 | R15: 集群1.0 | S15: 集群1.0
A16: 96634 | B16: 涂瀚宇 | C16: T2 | D16: 软件研发体系 | E16: 基础网络 | F16: NMC软件研发部 | H16: 软件开发工程师 | I16: 45840 | J16: SIG二期 | K16: SIG二期 | L16: 控制器高可用 | M16: 控制器高可用 | N16: 控制器高可用 | O16: 控制器高可用 | P16: 控制器高可用 | Q16: 易用性1.0 | R16: 易用性1.0
A17: 72949 | B17: 孟洋 | C17: T7 | D17: 软件研发体系 | E17: 基础网络 | F17: NMC软件研发部 | J17: 无线 | K17: 控制器高可用 | L17: 控制器高可用 | M17: 控制器高可用 | N17: 控制器高可用 | O17: 控制器高可用 | P17: 控制器高可用 | Q17: 集群1.0 | R17: 集群1.0 | S17: 集群1.0 | T17: 集群1.0 | U17: 集群1.0
A18: 97224 | B18: 孙忠彦 | C18: T2 | D18: 软件研发体系 | E18: 基础网络 | F18: NMC软件研发部 | J18: 测试 | K18: 测试 | L18: SIG三期 | M18: SIG三期 | N18: SIG三期 | O18: SIG三期 | P18: SIG三期 | Q18: SIG三期 | R18: SIG三期
A19: 19083 | B19: 陈加广 | C19: T4 | D19: 软件研发体系 | E19: 基础网络 | F19: NMC软件研发部 | H19: 软件开发工程师 | I19: 44193 | J19: 技术支持 | K19: 技术支持 | L19: 技术支持 | M19: 技术支持 | N19: 技术支持 | O19: 技术支持 | P19: 技术支持 | Q19: 技术支持 | R19: 技术支持
A20: 76442 | B20: 韩文龙 | C20: T7 | D20: 软件研发体系 | E20: 基础网络 | F20: NMC软件研发部 | H20: 软件开发工程师 | I20: 42184 | J20: 控制器高可用 | K20: 控制器高可用 | L20: 控制器高可用 | M20: 控制器高可用 | N20: 控制器高可用 | O20: 控制器高可用 | P20: 控制器高可用 | Q20: 易用性1.0 | R20: 易用性1.0
A21: 12944 | B21: 张志 | C21: T3 | D21: 软件研发体系 | E21: 基础网络 | F21: NMC软件研发部 | H21: 软件开发工程师 | I21: 44440 | J21: 支援无线 | K21: 支援无线 | L21: 支援无线 | M21: 支援无线 | N21: 调去交换机 | Q21: 易用性1.0 | R21: 易用性1.0
A22: 20811 | B22: 黄宇成 | C22: T4 | D22: 软件研发体系 | E22: 基础网络 | F22: NMC软件研发部 | H22: 软件开发工程师 | I22: 43983 | J22: ios portal优化 | K22: ios portal优化 + N合一 | L22: 质量维护 | M22: 质量维护 | N22: 质量维护 | O22: 质量维护 | P22: 质量维护 | Q22: 100G一分四 | R22: 100G一分四 | S22: 100G一分四
A23: 77251 | B23: 陈金俊 | C23: T7 | D23: 软件研发体系 | E23: 基础网络 | F23: NMC软件研发部 | H23: 软件开发工程师 | I23: 41099 | J23: 控制器高可用 | K23: 控制器高可用 | L23: 控制器高可用 | M23: 控制器高可用 | N23: 控制器高可用 | O23: 控制器高可用 | P23: 控制器高可用 | Q23: 集群1.0 | R23: 集群1.0 | S23: 集群1.0 | T23: 集群1.0 | U23: 集群1.0
A24: 92042 | B24: 唐小伟 | C24: T5 | D24: 软件研发体系 | E24: 基础网络 | F24: NMC软件研发部 | G24: FEX | H24: 软件开发工程师 | I24: 43077 | J24: 小程序认证 | K24: 控制器高可用 | L24: 控制器高可用 | M24: 控制器高可用 | N24: 控制器高可用 | O24: 控制器高可用 | P24: 控制器高可用 | Q24: 集群1.0 | R24: 集群1.0 | S24: 集群1.0
A25: 91418 | B25: 刘威 | C25: T2 | D25: 软件研发体系 | E25: 基础网络 | F25: NMC软件研发部 | H25: 软件开发工程师 | I25: 44984 | J25: 技术支持 | K25: 技术支持 | L25: 技术支持 | M25: 技术支持 | N25: 技术支持 | O25: 技术支持 | P25: 技术支持 | Q25: 技术支持 | R25: 技术支持
A26: 96208 | B26: 王维 | C26: T7 | D26: 软件研发体系 | E26: 基础网络 | F26: NMC软件研发部 | H26: 软件开发工程师 | I26: 42191 | J26: 技术支持 | K26: 技术支持 | L26: 技术支持 | M26: 技术支持 | N26: 技术支持 | O26: 技术支持 | P26: 技术支持 | Q26: 技术支持 | R26: 技术支持
A27: 53558 | B27: 伍连啟 | C27: T4 | D27: 软件研发体系 | E27: 基础网络 | F27: NMC软件研发部 | H27: 软件开发工程师 | I27: 42919 | J27: N合一 | K27: 质量维护 | L27: 质量维护 | M27: 支援交换机 | N27: 支援交换机 | O27: 支援交换机 | P27: 机动 | Q27: 易用性1.0 | R27: 易用性1.0
A28: 52012 | B28: 张浩 | C28: T2 | D28: 软件研发体系 | E28: 基础网络 | F28: NMC软件研发部 | H28: 软件开发工程师 | I28: 45110 | J28: 定制 | K28: 定制 | L28: 定制 | M28: 定制 | N28: 定制 | O28: 定制 | P28: 定制 | Q28: 定制 | R28: 定制
A29: 99812 | B29: 赵呈祥 | C29: T2 | D29: 软件研发体系 | E29: 基础网络 | F29: NMC软件研发部 | H29: 软件开发工程师 | I29: 44746 | J29: N合一 | K29: N合一 | L29: 控制器高可用 | M29: 控制器高可用 | N29: 控制器高可用 | O29: 控制器高可用 | P29: 控制器高可用 | Q29: 集群1.0 | R29: 集群1.0 | S29: 集群1.0
A30: 22026 | B30: 刘涛 | D30: 软件研发体系 | E30: 基础网络 | F30: NMC软件研发部 | H30: 软件开发工程师 | I30: 42561 | J30: 管理 | K30: 管理 | L30: 管理 | M30: 管理 | N30: 管理 | O30: 管理 | P30: 管理 | Q30: 管理 | R30: 管理
A31: 65248 | B31: 彭依岳 | C31: T5 | D31: 软件研发体系 | E31: 基础网络 | F31: FEX(JS) | H31: 软件开发工程师 | I31: 43672 | J31: N合一 | K31: N合一 | L31: 质量 & 控制器高可用 | M31: 质量 & 控制器高可用 | N31: 质量 & 控制器高可用 | O31: 质量 & 控制器高可用 | P31: 质量 & 控制器高可用
A32: 14659 | B32: 夏国富 | C32: T4 | D32: 软件研发体系 | E32: 基础网络 | F32: FEX(PHP) | H32: 软件开发工程师 | I32: 44265 | J32: N合一 | K32: N合一 | L32: 质量 & 控制器高可用 | M32: 质量 & 控制器高可用 | N32: 质量 & 控制器高可用 | O32: 质量 & 控制器高可用 | P32: 质量 & 控制器高可用
A33: 70568 | B33: 黄双 | C33: T5.3 | D33: 软件研发体系 | E33: 基础网络 | F33: FEX(JS) | H33: 软件开发工程师 | I33: 42499 | J33: N合一 | K33: N合一 | L33: 质量 & 控制器高可用 | M33: 质量 & 控制器高可用 | N33: 质量 & 控制器高可用 | O33: 质量 & 控制器高可用 | P33: 质量 & 控制器高可用
A34: 93622 | B34: 黄涛 | C34: T4 | D34: 软件研发体系 | E34: 基础网络 | F34: FEX(JS) | H34: 软件开发工程师 | I34: 42880 | J34: 无线版本 | K34: 无线版本 | L34: 支援无线&交换机 | M34: 支援无线&交换机 | N34: 支援无线&交换机 | O34: 支援无线&交换机 | P34: 支援无线&交换机
A35: 37038 | B35: 王永强 | C35: T4 | D35: 软件研发体系 | E35: 基础网络 | F35: FEX(PHP) | H35: 软件开发工程师 | I35: 42552 | J35: 无线版本 | K35: 无线版本 | L35: 支援无线&交换机 | M35: 支援无线&交换机 | N35: 支援无线&交换机 | O35: 支援无线&交换机 | P35: 支援无线&交换机
A36: 17220 | B36: 杨建锋 | C36: T4 | D36: 软件研发体系 | E36: 基础网络 | F36: FEX(JS) | H36: 软件开发工程师 | I36: 42459 | J36: 无线版本 | K36: 无线版本 | L36: 支援无线&交换机 | M36: 支援无线&交换机 | N36: 支援无线&交换机 | O36: 支援无线&交换机 | P36: 支援无线&交换机
A37: 89973 | B37: 苏华迪 | C37: T5 | D37: 软件研发体系 | E37: 基础网络 | F37: FEX(JS) | H37: 软件开发工程师 | I37: 43675 | J37: 定制&技术支持 | K37: 定制&技术支持 | L37: 定制&技术支持 | M37: 定制&技术支持 | N37: 定制&技术支持 | O37: 定制&技术支持 | P37: 定制&技术支持
A38: 23167 | B38: 赵锐辉 | C38: T6 | D38: 软件研发体系 | E38: 基础网络 | F38: FEX(PHP) | H38: 软件开发工程师 | I38: 43068 | J38: 定制&技术支持 | K38: 定制&技术支持 | L38: 定制&技术支持 | M38: 定制&技术支持 | N38: 定制&技术支持 | O38: 定制&技术支持 | P38: 定制&技术支持
A39: 75912 | B39: 刘华腾 | C39: T6.4 | D39: 软件研发体系 | E39: 基础网络 | F39: FEX | H39: 软件开发工程师 | I39: 39639 | J39: 交互 | K39: 交互 | L39: 交互 | M39: 交互 | N39: 交互 | O39: 交互 | P39: 交互
A40: 29586 | B40: 刘秋兰 | C40: T4.3 | D40: 软件研发体系 | E40: 基础网络 | F40: FEX | H40: 软件开发工程师 | I40: 43035 | J40: 视觉 | K40: 视觉 | L40: 视觉 | M40: 视觉 | N40: 视觉 | O40: 视觉 | P40: 视觉
...

Sheet 控制器_v2
A1: 工号 | B1: 姓名 | C1: 一级部门 | D1: 二级部门 | E1: 三级部门 | F1: 原部门 | G1: 岗位 | H1: 入职时间 | I1: 25.02.10 | J1: 25.02.17 | K1: 25.02.24 | M1: 25.03.03 | O1: 25.03.10
A2: 12383 | B2: 曹奕 | C2: 软件研发体系 | D2: 基础网络 | E2: NMC软件研发部 | G2: 软件开发工程师 | H2: 44627 | I2: GPT | J2: GPT | K2: 价值 | L2: GPT AI Agent移植 | M2: 价值 | N2: GPT AI Agent移植
A3: 12944 | B3: 张志 | C3: 软件研发体系 | D3: 基础网络 | E3: NMC软件研发部 | G3: 软件开发工程师 | H3: 44440 | I3: GPT | J3: 安全加固 | K3: 价值 | L3: Xmeeting移植 | M3: 价值 | N3: Xmeeting移植
A4: 16761 | B4: 乔广大 | C4: 软件研发体系 | D4: 基础网络 | E4: NMC软件研发部 | G4: 软件开发工程师 | H4: 44382 | I4: 大客户定制 | J4: 承诺价值 | K4: 定制 | L4: 招行定制迁移 | M4: 支援 | N4: 交换机ipv6
A5: 29050 | B5: 杨旭 | C5: 软件研发体系 | D5: 基础网络 | E5: NMC软件研发部 | G5: 软件开发工程师 | H5: 43291 | I5: 大客户定制 | J5: 常规质量 | K5: 定制 | L5: 国寿财低版本控制器迁移 | M5: 价值 | N5: XRT管本地交换机
A6: 54477 | B6: 张晓东 | C6: 大研发体系 | D6: 基础网络 | E6: NMC软件研发部 | G6: 软件开发工程师 | H6: 42552 | I6: 大客户承诺 | J6: 大客户定制 | K6: 价值 | L6: pppoev6收尾 | M6: 定制 | N6: 柬埔寨
A7: 57305 | B7: 吕明洋 | C7: 软件研发体系 | D7: 基础网络 | E7: NMC软件研发部 | G7: 软件开发工程师 | H7: 43934 | I7: GPT | J7: GPT | K7: 价值 | L7: GPT AI Agent移植 | M7: 支援 | N7: 交换机ipv6
A8: 76442 | B8: 韩文龙 | C8: 软件研发体系 | D8: 基础网络 | E8: NMC软件研发部 | G8: 软件开发工程师 | H8: 42184 | I8: 支援-会议主机 | J8: 平滑切换 | K8: 精品化 | L8: 平滑切换 | M8: 精品化 | N8: 平滑切换
A9: 77251 | B9: 陈金俊 | C9: 软件研发体系 | D9: 基础网络 | E9: NMC软件研发部 | G9: 软件开发工程师 | H9: 41099 | I9: 安全加固 | J9: 控制器性能提升 | K9: 价值 | L9: Xmeeting移植 | M9: 价值 | N9: Xmeeting移植
A10: 95220 | B10: 温智皓 | C10: 软件研发体系 | D10: 基础网络 | E10: NMC软件研发部 | G10: 软件开发工程师 | H10: 44440 | I10: 常规质量 | J10: 常规质量 | K10: 质量 | L10: 常规质量 | M10: 质量 | N10: 常规质量
A11: 20811 | B11: 黄宇成 | C11: 软件研发体系 | D11: 基础网络 | E11: NMC软件研发部 | G11: 软件开发工程师 | H11: 43983 | I11: 管理认证移植 | J11: 管理认证移植 | K11: NMC8836适配 | L11: NMC8836适配 | M11: 硬件 | N11: NMC8836适配 & AI本地化
A12: 40226 | B12: 龙逸舒 | C12: 软件研发体系 | D12: 基础网络 | E12: NMC软件研发部 | G12: 软件开发工程师 | H12: 43934 | I12: 告警闭环 | J12: 告警闭环 | K12: 价值 | L12: 告警闭环 | M12: 价值 | N12: 合保隆 | O12: 已转交换机
A13: 23418 | B13: 吴盾 | C13: 软件研发体系 | D13: 基础网络 | E13: NMC软件研发部 | F13: FEX | G13: 软件开发工程师 | H13: 45362 | I13: 熟悉后台 | J13: 熟悉后台 | K13: 定制 | L13: 大船定制 | M13: 支援 | N13: 交换机IPv6UI
A14: 92042 | B14: 唐小伟 | C14: 软件研发体系 | D14: 基础网络 | E14: NMC软件研发部 | F14: FEX | G14: 软件开发工程师 | H14: 43077 | I14: 熟悉后台 | J14: 大客户定制 | K14: 定制 | L14: 华润电力ipv6 | M14: 价值 | N14: 定制合入
A15: 91418 | B15: 刘威 | C15: 软件研发体系 | D15: 基础网络 | E15: NMC软件研发部 | G15: 软件开发工程师 | H15: 44984 | I15: 大客户定制 | J15: 大客户定制 | K15: 定制 | L15: 豪生 | M15: 技术支持 | N15: 技术支持
A16: 96208 | B16: 王维 | C16: 软件研发体系 | D16: 基础网络 | E16: NMC软件研发部 | G16: 软件开发工程师 | H16: 42191 | I16: 技术支持 | J16: 技术支持 | K16: 质量 | L16: 技术支持 | M16: 质量 | N16: 技术支持
A17: 53558 | B17: 伍连啟 | C17: 软件研发体系 | D17: 基础网络 | E17: NMC软件研发部 | G17: 软件开发工程师 | H17: 42919 | I17: 技术支持 | J17: 技术支持 | K17: 质量 | L17: 技术支持 | M17: 质量 | N17: 技术支持
A18: 19083 | B18: 陈加广 | C18: 软件研发体系 | D18: 基础网络 | E18: NMC软件研发部 | G18: 软件开发工程师 | H18: 44193 | I18: 安全加固 | J18: 安全加固 | K18: 价值 | L18: Xmeeting移植 | M18: 价值 | N18: Xmeeting移植
A19: 17795 | B19: 彭清华 | C19: 软件研发体系 | D19: 基础网络 | E19: NMC软件研发部 | G19: 软件开发工程师 | H19: 43245 | I19: 大客户定制 | J19: 大客户定制 | K19: 定制 | L19: 豪生 | M19: 价值 | N19: 5229适配
A20: 40624 | B20: 熊宽 | C20: 软件研发体系 | D20: 基础网络 | E20: NMC软件研发部 | G20: 软件开发工程师 | H20: 44746 | I20: 定制 | J20: 定制 | K20: 定制 | L20: 常规定制 | M20: 定制 | N20: 定制
A21: 52012 | B21: 张浩 | C21: 软件研发体系 | D21: 基础网络 | E21: NMC软件研发部 | G21: 软件开发工程师 | H21: 45110 | I21: 定制 | J21: 定制 | K21: 定制 | L21: 常规定制 | M21: 定制 | N21: 定制
A22: 99812 | B22: 赵呈祥 | C22: 软件研发体系 | D22: 基础网络 | E22: NMC软件研发部 | G22: 软件开发工程师 | H22: 44746 | I22: 定制 | J22: 定制 | K22: 定制 | L22: 常规定制 | M22: 定制 | N22: 定制
A23: 28062 | B23: 任海斌 | C23: 软件研发体系 | D23: 基础网络 | E23: NMC软件研发部 | G23: 软件开发工程师 | H23: 41827 | I23: 管理 | J23: 管理 | K23: 价值 | L23: Xmeeting移植 | M23: 价值 | N23: Xmeeting移植
A24: 22026 | B24: 刘涛 | C24: 软件研发体系 | D24: 基础网络 | E24: NMC软件研发部 | G24: 软件开发工程师 | H24: 42561 | I24: 管理 | J24: 管理 | K24: 管理 | L24: 管理 | M24: 管理 | N24: 管理
A25: 93622 | B25: 黄涛(JS) | C25: 软件研发体系 | D25: 基础网络 | E25: FEX | G25: 软件开发工程师 | H25: 42880 | I25: N合一收尾 | J25: N合一收尾 | K25: 价值 | L25: Xmeeting移植 & portal优化 | M25: 价值 | N25: Xmeeting移植 & portal优化编码
A26: 65248 | B26: 彭依岳(JS) | C26: 软件研发体系 | D26: 基础网络 | E26: FEX | G26: 软件开发工程师 | H26: 43672 | I26: 大客户定制 | J26: 大客户定制 | K26: 定制 | L26: 华润IPv6定制 & Xmeeting移植(1天) | M26: 定制 | N26: 华润定制UI页面 & portal优化编码
... A38: 49087 | B38: 张洁 | C38: 软件研发体系 | D38: 基础网络 | E38: FEX | G38: 软件开发工程师 | H38: 41099 | I38: 管理 | J38: 管理 | K38: 管理 | L38: 管理 | M38: 管理 | N38: 管理

Sheet 控制器
A1: 工号 | B1: 姓名 | C1: 一级部门 | D1: 二级部门 | E1: 三级部门 | F1: 调动 | G1: 岗位 | H1: 入职时间 | I1: 25.02
A2: 12383 | B2: 曹奕 | C2: 软件研发体系 | D2: 基础网络 | E2: NMC软件研发部 | G2: 软件开发工程师 | H2: 44627
A3: 19288 | B3: 梁淮光 | C3: 软件研发体系 | D3: 基础网络 | E3: NMC软件研发部 | F3: 交换机 | G3: 软件开发工程师 | H3: 44382
A4: 10899 | B4: 徐鹏 | C4: 软件研发体系 | D4: 基础网络 | E4: NMC软件研发部 | F4: 无线 | G4: 软件开发工程师 | H4: 44067
A5: 91418 | B5: 刘威 | C5: 软件研发体系 | D5: 基础网络 | E5: NMC软件研发部 | G5: 软件开发工程师 | H5: 44984
A6: 95220 | B6: 温智皓 | C6: 软件研发体系 | D6: 基础网络 | E6: NMC软件研发部 | G6: 软件开发工程师 | H6: 44440
A7: 22026 | B7: 刘涛 | C7: 软件研发体系 | D7: 基础网络 | E7: NMC软件研发部 | G7: 软件开发工程师 | H7: 42561
A8: 28062 | B8: 任海斌 | C8: 软件研发体系 | D8: 基础网络 | E8: NMC软件研发部 | G8: 软件开发工程师 | H8: 41827
A9: 47808 | B9: 王健 | C9: 软件研发体系 | D9: 基础网络 | E9: NMC软件研发部 | F9: 规划 | G9: 软件开发工程师 | H9: 42569
A10: 50221 | B10: 黄森宇 | C10: 软件研发体系 | D10: 基础网络 | E10: NMC软件研发部 | F10: 新业务 | G10: 软件开发工程师 | H10: 42562
A11: 24934 | B11: 朱辉 | C11: 软件研发体系 | D11: 基础网络 | E11: NMC软件研发部 | F11: 测试 | G11: 测试开发工程师 | H11: 41071
A12: 57305 | B12: 吕明洋 | C12: 软件研发体系 | D12: 基础网络 | E12: NMC软件研发部 | G12: 软件开发工程师 | H12: 43934
A13: 12944 | B13: 张志 | C13: 软件研发体系 | D13: 基础网络 | E13: NMC软件研发部 | G13: 软件开发工程师 | H13: 44440
A14: 40226 | B14: 龙逸舒 | C14: 软件研发体系 | D14: 基础网络 | E14: NMC软件研发部 | G14: 软件开发工程师 | H14: 43934
A15: 19083 | B15: 陈加广 | C15: 软件研发体系 | D15: 基础网络 | E15: NMC软件研发部 | G15: 软件开发工程师 | H15: 44193
A16: 19906 | B16: 王惠杰 | C16: 软件研发体系 | D16: 基础网络 | E16: NMC软件研发部 | F16: 交换机 | G16: 软件开发工程师 | H16: 44648
A17: 76442 | B17: 韩文龙 | C17: 软件研发体系 | D17: 基础网络 | E17: NMC软件研发部 | G17: 软件开发工程师 | H17: 42184
A18: 75912 | B18: 刘华腾 | C18: 软件研发体系 | D18: 基础网络 | E18: FEX | G18: 软件开发工程师 | H18: 39639
A19: 96208 | B19: 王维 | C19: 软件研发体系 | D19: 基础网络 | E19: NMC软件研发部 | G19: 软件开发工程师 | H19: 42191
A20: 16761 | B20: 乔广大 | C20: 软件研发体系 | D20: 基础网络 | E20: NMC软件研发部 | G20: 软件开发工程师 | H20: 44382
A21: 17385 | B21: 张义军 | C21: 软件研发体系 | D21: 基础网络 | E21: NMC软件研发部 | F21: 无线 | G21: 软件开发工程师 | H21: 42919
A22: 17795 | B22: 彭清华 | C22: 软件研发体系 | D22: 基础网络 | E22: NMC软件研发部 | G22: 软件开发工程师 | H22: 43245
A23: 18483 | B23: 郑泽滨 | C23: 软件研发体系 | D23: 基础网络 | E23: NMC软件研发部 | F23: 测试 | G23: 软件开发工程师 | H23: 43915
A24: 77251 | B24: 陈金俊 | C24: 软件研发体系 | D24: 基础网络 | E24: NMC软件研发部 | G24: 软件开发工程师 | H24: 41099
A25: 20811 | B25: 黄宇成 | C25: 软件研发体系 | D25: 基础网络 | E25: NMC软件研发部 | G25: 软件开发工程师 | H25: 43983
A26: 29050 | B26: 杨旭 | C26: 软件研发体系 | D26: 基础网络 | E26: NMC软件研发部 | G26: 软件开发工程师 | H26: 43291
A27: 29586 | B27: 刘秋兰 | C27: 软件研发体系 | D27: 基础网络 | E27: FEX | G27: 软件开发工程师 | H27: 43035
A28: 31255 | B28: 黄安 | C28: 软件研发体系 | D28: 基础网络 | E28: NMC软件研发部 | F28: 交换机 | G28: 软件开发工程师 | H28: 44018
A29: 40624 | B29: 熊宽 | C29: 软件研发体系 | D29: 基础网络 | E29: NMC软件研发部 | G29: 软件开发工程师 | H29: 44746
A30: 52012 | B30: 张浩 | C30: 软件研发体系 | D30: 基础网络 | E30: NMC软件研发部 | G30: 软件开发工程师 | H30: 45110
A31: 53558 | B31: 伍连啟 | C31: 软件研发体系 | D31: 基础网络 | E31: NMC软件研发部 | G31: 软件开发工程师 | H31: 42919
A32: 54477 | B32: 张晓东 | C32: 软件研发体系 | D32: 基础网络 | E32: FEX | G32: 软件开发工程师 | H32: 42555
A33: 70568 | B33: 黄双 | C33: 软件研发体系 | D33: 基础网络 | E33: FEX | G33: 软件开发工程师 | H33: 42499
A34: 99812 | B34: 赵呈祥 | C34: 软件研发体系 | D34: 基础网络 | E34: NMC软件研发部 | G34: 软件开发工程师 | H34: 44746
A35: 32629 | B35: 罗政 | C35: 软件研发体系 | D35: 基础网络 | E35: FEX | G35: 软件开发工程师 | H35: 44125
A36: 65248 | B36: 彭依岳 | C36: 软件研发体系 | D36: 基础网络 | E36: FEX | G36: 软件开发工程师 | H36: 43672
A37: 49087 | B37: 张洁 | C37: 软件研发体系 | D37: 基础网络 | E37: FEX | G37: 软件开发工程师 | H37: 41099
A38: 60993 | B38: 何星宇 | C38: 软件研发体系 | D38: 基础网络 | E38: FEX | G38: 软件开发工程师 | H38: 44746
A39: 17855 | B39: 吕东锋 | C39: 软件研发体系 | D39: 基础网络 | E39: FEX | G39: 软件开发工程师 | H39: 43752
A40: 14659 | B40: 夏国富 | C40: 软件研发体系 | D40: 基础网络 | E40: FEX | G40: 软件开发工程师 | H40: 44265
...

Sheet 记录
A1: 工号 | B1: 姓名 | C1: 一级部门 | D1: 二级部门 | E1: 三级部门 | F1: 原部门 | G1: 岗位 | H1: 入职时间 | I1: Q1汇总 | J1: Q1绩效 | K1: Q2汇总 | L1: Q2绩效 | M1: Q3汇总 | N1: Q3绩效 | O1: Q4汇总 | P1: Q4绩效 | Q1: 累计加班 | R1: 熟悉业务 | S1: 员工信息/评价 | T1: 员工类型 | U1: 业务无备份 | V1: 潜力 | W1: 后续计划 | X1: 25.02.15 | Y1: 25.02.22 | Z1: 25.03.01 | AA1: 25.03.08 | AB1: 25.03.15 | AC1: 25.03.22 | AD1: 25.03.29 | AE1: Q1占比 | AF1: 25.04.12 | AG1: 25.04.19 | AH1: 25.04.26 | AI1: 25.05.17 | AJ1: 25.05.24 | AK1: 25.06.07 | AL1: 25.06.14 | AM1: 25.06.21 | AN1: 25.06.28 | AO1: 25.07.05 | AP1: Q2占比 | AQ1: 25.07.12 | AR1: 25.07.19 | AS1: 25.07.26 | AT1: 25.08.02 | AU1: 25.08.09 | AV1: 25.08.16 | AW1: 25.08.23 | AX1: 25.08.30 | AY1: 25.09.06 | AZ1: 25.09.13 | BA1: 25.09.20 | BB1: Q3占比 | BC1: 25.10.18 | BD1: 25.10.25 | BE1: 25.11.1 | BF1: 25.11.8 | BG1: 25.11.15 | BH1: 25.11.22 | BI1: 25.11.29 | BJ1: 25.12.06 | BK1: 25.12.13 | BL1: 25.12.20 | BM1: 25.12.27 | BN1: Q4占比 | BO1: 26.01.10 | BP1: 26.01.17
A2: 12383 | B2: 曹奕 | C2: 软件研发体系 | D2: 基础网络 | E2: NMC软件研发部 | G2: 软件开发工程师 | H2: 44627 | I2: ==SUM(X2:AD2) -> 2.5 | J2: ==VLOOKUP(A2,绩效计算表!A:AI,9,FALSE) -> A | K2: ==SUM(AF2:AO2) -> 1.5 | L2: ==VLOOKUP(A2,绩效计算表!A:AI,15,FALSE) -> A | M2: ==SUM(AQ2:BA2) -> 2.5 | N2: ==VLOOKUP(A2,绩效计算表!A:AI,23,FALSE) -> A | O2: ==SUM(BC2:BM2)+SUM(BO2:BP2) -> 5 | P2: ==VLOOKUP(A2,绩效计算表!A:AI,30,FALSE) -> A | Q2: ==I2+K2+M2+O2 -> 11.5 | R2: GPT AFU 控制器基本业务 | S2: 性格特点:开朗热情， 能力胜任: 上手快，学习能力强，执行力强 工作态度: 有责任心、目标感，主动性强 思维逻辑: 理的顺，讲的请，做的好 有没有复盘习惯不确定 其他关键信息:父母在深圳，目前还没女朋友，在乎尊重感，能被荣耀感激发 | T2: 核心 | U2: GPT AFU | V2: A | W2: 培养备份，今明两年依然在部门维护小信GPT | Z2: 0.5 | AA2: 0.5 | AB2: 0.5 | AC2: 0.5 | AD2: 0.5 | AE2: ==SUM(X2:AD2)/6 -> 0.41666667 | AI2: 0.5 | AM2: 0.5 | AO2: 0.5 | AP2: ==SUM(AF2:AO2)/7.5 -> 0.2 | AT2: 0.5 | AV2: 0.5 | AY2: 0.5 | BA2: 1 | BB2: ==SUM(AQ2:BA2)/7.5 -> 0.33333333 | BC2: 0.5 | BE2: 0.5 | BG2: 0.5 | BH2: 0.5 | BI2: 0.5 | BK2: 0.5 | BL2: 0.5 | BM2: 0.5 | BN2: ==SUM(BC2:BM2)/9 -> 0.44444444 | BO2: 0.5 | BP2: 0.5
A3: 62555 | B3: 马垣德 | C3: 软件研发体系 | D3: 基础网络 | E3: NMC软件研发部 | G3: 软件开发工程师 | H3: 45840 | M3: ==SUM(AQ3:BA3) -> 5.5 | N3: 无绩效 | O3: ==SUM(BC3:BM3)+SUM(BO3:BP3) -> 4.25 | P3: ==VLOOKUP(A3,绩效计算表!A:AI,30,FALSE) -> B | Q3: ==I3+K3+M3+O3 -> 9.75 | R3: 上手熟悉阶段 | T3: 新人 | V3: 待评估 | AU3: 0.5 | AV3: 1 | AW3: 1 | AX3: 1 | AY3: 0.5 | AZ3: 1 | BA3: 0.5 | BB3: ==SUM(AQ3:BA3)/7.5 -> 0.73333333 | BC3: 0.25 | BG3: 1 | BH3: 0.5 | BI3: 0.5 | BJ3: 0.5 | BK3: 1 | BM3: 0.5 | BN3: ==SUM(BC3:BM3)/9 -> 0.47222222
A4: 72479 | B4: 冯皓洋 | C4: 软件研发体系 | D4: 基础网络 | E4: NMC软件研发部 | G4: 软件开发工程师 | H4: 45840 | M4: ==SUM(AQ4:BA4) -> 9 | N4: 无绩效 | O4: ==SUM(BC4:BM4)+SUM(BO4:BP4) -> 9.75 | P4: ==VLOOKUP(A4,绩效计算表!A:AI,30,FALSE) -> B+ | Q4: ==I4+K4+M4+O4 -> 18.75 | R4: 上手熟悉阶段 | T4: 新人 | V4: 待评估 | AR4: 1 | AS4: 1 | AT4: 0.5 | AU4: 1 | AV4: 1 | AW4: 1 | AX4: 1 | AY4: 0.5 | AZ4: 1 | BA4: 1 | BB4: ==SUM(AQ4:BA4)/7.5 -> 1.2 | BC4: 0.25 | BD4: 1 | BF4: 0.5 | BG4: 1 | BH4: 1 | BI4: 1 | BJ4: 0.5 | BK4: 1 | BL4: 1 | BM4: 1 | BN4: ==SUM(BC4:BM4)/9 -> 0.91666667 | BO4: 1 | BP4: 0.5
A5: 81343 | B5: 詹智钦 | C5: 软件研发体系 | D5: 基础网络 | E5: NMC软件研发部 | G5: 软件开发工程师 | H5: 45840 | M5: ==SUM(AQ5:BA5) -> 7 | N5: 无绩效 | O5: ==SUM(BC5:BM5)+SUM(BO5:BP5) -> 2.5 | P5: ==VLOOKUP(A5,绩效计算表!A:AI,30,FALSE) -> B | Q5: ==I5+K5+M5+O5 -> 9.5 | R5: 上手熟悉阶段 | T5: 新人 | V5: 待评估 | AS5: 1 | AT5: 0.5 | AU5: 1 | AV5: 1 | AW5: 1 | AY5: 0.5 | AZ5: 1 | BA5: 1 | BB5: ==SUM(AQ5:BA5)/7.5 -> 0.93333333 | BH5: 0.5 | BI5: 0.5 | BK5: 0.5 | BM5: 0.5 | BN5: ==SUM(BC5:BM5)/9 -> 0.22222222 | BP5: 0.5
A6: 96634 | B6: 涂瀚宇 | C6: 软件研发体系 | D6: 基础网络 | E6: NMC软件研发部 | G6: 软件开发工程师 | H6: 45840 | M6: ==SUM(AQ6:BA6) -> 5.5 | N6: 无绩效 | O6: ==SUM(BC6:BM6)+SUM(BO6:BP6) -> 3 | P6: ==VLOOKUP(A6,绩效计算表!A:AI,30,FALSE) -> B | Q6: ==I6+K6+M6+O6 -> 8.5 | R6: 上手熟悉阶段 | T6: 新人 | V6: 待评估 | AU6: 0.5 | AV6: 1 | AW6: 1 | AX6: 1 | AY6: 0.5 | AZ6: 1 | BA6: 0.5 | BB6: ==SUM(AQ6:BA6)/7.5 -> 0.73333333 | BG6: 0.5 | BI6: 0.5 | BK6: 1 | BM6: 1 | BN6: ==SUM(BC6:BM6)/9 -> 0.33333333
A7: 97224 | B7: 孙忠彦 | C7: 软件研发体系 | D7: 基础网络 | E7: NMC软件研发部 | G7: 软件开发工程师 | H7: 45840 | M7: ==SUM(AQ7:BA7) -> 6 | N7: 无绩效 | O7: ==SUM(BC7:BM7)+SUM(BO7:BP7) -> 3.75 | P7: ==VLOOKUP(A7,绩效计算表!A:AI,30,FALSE) -> B+ | Q7: ==I7+K7+M7+O7 -> 9.75 | R7: 上手熟悉阶段 | T7: 新人 | V7: 待评估 | AS7: 0.5 | AT7: 0.5 | AV7: 1 | AW7: 1 | AX7: 1 | AY7: 0.5 | AZ7: 1 | BA7: 0.5 | BB7: ==SUM(AQ7:BA7)/7.5 -> 0.8 | BC7: 0.25 | BD7: 1 | BG7: 1 | BK7: 1 | BM7: 0.5 | BN7: ==SUM(BC7:BM7)/9 -> 0.41666667
A8: 56862 | B8: 林颖 | C8: T2 | D8: 软件研发体系 | E8: 基础网络 | F8: NMC软件研发部 | G8: 软件开发工程师 | H8: 45901 | O8: ==SUM(BC8:BM8)+SUM(BO8:BP8) -> 5.2 | P8: 无绩效 | Q8: ==I8+K8+M8+O8 -> 5.2 | BA8: 0.5 | BB8: ==SUM(AQ8:BA8)/7.5 -> 0.066666667 | BD8: 1 | BG8: 1 | BH8: 1 | BJ8: 0.5 | BK8: 1 | BM8: 0.7 | BN8: ==SUM(BC8:BM8)/9 -> 0.57777778
A9: 12944 | B9: 张志 | C9: 软件研发体系 | D9: 基础网络 | E9: NMC软件研发部 | G9: 软件开发工程师 | H9: 44440 | I9: ==SUM(X9:AD9) -> 3.5 | J9: ==VLOOKUP(A9,绩效计算表!A:AI,9,FALSE) -> A | K9: ==SUM(AF9:AO9) -> 0.5 | L9: ==VLOOKUP(A9,绩效计算表!A:AI,15,FALSE) -> B | M9: ==SUM(AQ9:BA9) -> 0.5 | N9: ==VLOOKUP(A9,绩效计算表!A:AI,23,FALSE) -> B | O9: ==SUM(BC9:BM9)+SUM(BO9:BP9) -> 4.7 | P9: ==VLOOKUP(A9,绩效计算表!A:AI,30,FALSE) -> A | Q9: ==I9+K9+M9+O9 -> 9.2 | R9: 控制器基本业务 | T9: 高潜 | V9: B+ | W9: 可在无线/SW进一步培养 | Z9: 0.5 | AA9: 1 | AB9: 1 | AC9: 1 | AE9: ==SUM(X9:AD9)/6 -> 0.58333333 | AO9: 0.5 | AP9: ==SUM(AF9:AO9)/7.5 -> 0.066666667 | AY9: 0.5 | BB9: ==SUM(AQ9:BA9)/7.5 -> 0.066666667 | BF9: 1 | BH9: 1 | BI9: 0.5 | BJ9: 0.5 | BK9: 1 | BM9: 0.7 | BN9: ==SUM(BC9:BM9)/9 -> 0.52222222
A10: 16761 | B10: 乔广大 | C10: 软件研发体系 | D10: 基础网络 | E10: NMC软件研发部 | G10: 软件开发工程师 | H10: 44382 | I10: ==SUM(X10:AD10) -> 0 | J10: ==VLOOKUP(A10,绩效计算表!A:AI,9,FALSE) -> B | K10: ==SUM(AF10:AO10) -> 0 | L10: ==VLOOKUP(A10,绩效计算表!A:AI,15,FALSE) -> B | M10: ==SUM(AQ10:BA10) -> 0 | N10: ==VLOOKUP(A10,绩效计算表!A:AI,23,FALSE) -> B | O10: ==SUM(BC10:BM10)+SUM(BO10:BP10) -> 0 | P10: ==VLOOKUP(A10,绩效计算表!A:AI,30,FALSE) -> C | Q10: ==I10+K10+M10+O10 -> 0 | R10: 控制器基本业务 | T10: 达标员工 | V10: B | W10: 学习能力一般，留在本部门 | AE10: ==SUM(X10:AD10)/6 -> 0 | AP10: ==SUM(AF10:AO10)/7.5 -> 0 | BB10: ==SUM(AQ10:BA10)/7.5 -> 0 | BN10: ==SUM(BC10:BM10)/9 -> 0
A11: 29050 | B11: 杨旭 | C11: 软件研发体系 | D11: 基础网络 | E11: NMC软件研发部 | G11: 软件开发工程师 | H11: 43291 | I11: ==SUM(X11:AD11) -> 2.5 | J11: ==VLOOKUP(A11,绩效计算表!A:AI,9,FALSE) -> B+ | K11: ==SUM(AF11:AO11) -> 2.5 | L11: ==VLOOKUP(A11,绩效计算表!A:AI,15,FALSE) -> B | M11: ==SUM(AQ11:BA11) -> 2.5 | N11: ==VLOOKUP(A11,绩效计算表!A:AI,23,FALSE) -> B | O11: ==SUM(BC11:BM11)+SUM(BO11:BP11) -> 3.25 | P11: ==VLOOKUP(A11,绩效计算表!A:AI,30,FALSE) -> B+ | Q11: ==I11+K11+M11+O11 -> 10.75 | R11: 控制器基本业务 网关业务 | T11: 核心 | V11: B+ | W11: 转部门意愿和学习能力一般，干本部门的活效率高 | Y11: 1 | Z11: 0.5 | AD11: 1 | AE11: ==SUM(X11:AD11)/6 -> 0.41666667 | AG11: 0.5 | AK11: 0.5 | AM11: 1 | AO11: 0.5 | AP11: ==SUM(AF11:AO11)/7.5 -> 0.33333333 | AT11: 0.5 | AW11: 1 | AZ11: 0.5 | BA11: 0.5 | BB11: ==SUM(AQ11:BA11)/7.5 -> 0.33333333 | BE11: 0.25 | BG11: 0.5 | BI11: 0.5 | BJ11: 0.5 | BL11: 0.5 | BN11: ==SUM(BC11:BM11)/9 -> 0.25 | BO11: 0.5 | BP11: 0.5
A12: 54477 | B12: 张晓东 | C12: 大研发体系 | D12: 基础网络 | E12: NMC软件研发部 | G12: 软件开发工程师 | H12: 42552 | I12: ==SUM(X12:AD12) -> 4 | J12: ==VLOOKUP(A12,绩效计算表!A:AI,9,FALSE) -> B+ | K12: ==SUM(AF12:AO12) -> 5.5 | L12: ==VLOOKUP(A12,绩效计算表!A:AI,15,FALSE) -> A | M12: ==SUM(AQ12:BA12) -> 7.5 | N12: ==VLOOKUP(A12,绩效计算表!A:AI,23,FALSE) -> A | O12: ==SUM(BC12:BM12)+SUM(BO12:BP12) -> 8.5 | P12: ==VLOOKUP(A12,绩效计算表!A:AI,30,FALSE) -> B | Q12: ==I12+K12+M12+O12 -> 25.5 | R12: 控制器基本业务 网关业务 | T12: 核心 | V12: B+ | X12: 0.5 | Z12: 0.5 | AA12: 1 | AB12: 1 | AD12: 1 | AE12: ==SUM(X12:AD12)/6 -> 0.66666667 | AG12: 1 | AI12: 1 | AJ12: 1 | AL12: 1 | AN12: 1 | AO12: 0.5 | AP12: ==SUM(AF12:AO12)/7.5 -> 0.73333333 | AQ12: 1 | AS12: 1 | AU12: 1 | AV12: 1 | AW12: 1 | AX12: 0.5 | AZ12: 1 | BA12: 1 | BB12: ==SUM(AQ12:BA12)/7.5 -> 1 | BC12: 0.5 | BD12: 1 | BE12: 0.5 | BG12: 1 | BH12: 1 | BI12: 0.5 | BJ12: 0.5 | BK12: 1 | BL12: 1 | BN12: ==SUM(BC12:BM12)/9 -> 0.77777778 | BO12: 1 | BP12: 0.5
A13: 57305 | B13: 吕明洋 | C13: 软件研发体系 | D13: 基础网络 | E13: NMC软件研发部 | G13: 软件开发工程师 | H13: 43934 | I13: ==SUM(X13:AD13) -> 3.5 | J13: ==VLOOKUP(A13,绩效计算表!A:AI,9,FALSE) -> #N/A | K13: ==SUM(AF13:AO13) -> 1.5 | L13: ==VLOOKUP(A13,绩效计算表!A:AI,15,FALSE) -> #N/A | M13: ==SUM(AQ13:BA13) -> 0 | N13: ==VLOOKUP(A13,绩效计算表!A:AI,23,FALSE) -> #N/A | O13: ==SUM(BC13:BM13)+SUM(BO13:BP13) -> 0 | P13: ==VLOOKUP(A13,绩效计算表!A:AI,30,FALSE) -> #N/A | Q13: ==I13+K13+M13+O13 -> 5 | X13: 0.5 | Y13: 1 | Z13: 0.5 | AB13: 1 | AC13: 0.5 | AE13: ==SUM(X13:AD13)/6 -> 0.58333333 | AG13: 0.5 | AI13: 1 | AP13: ==SUM(AF13:AO13)/7.5 -> 0.2 | BB13: ==SUM(AQ13:BA13)/7.5 -> 0 | BN13: ==SUM(BC13:BM13)/9 -> 0
A14: 76442 | B14: 韩文龙 | C14: 软件研发体系 | D14: 基础网络 | E14: NMC软件研发部 | G14: 软件开发工程师 | H14: 42184 | I14: ==SUM(X14:AD14) -> 1 | J14: ==VLOOKUP(A14,绩效计算表!A:AI,9,FALSE) -> B | K14: ==SUM(AF14:AO14) -> 2 | L14: ==VLOOKUP(A14,绩效计算表!A:AI,15,FALSE) -> B | M14: ==SUM(AQ14:BA14) -> 2 | N14: ==VLOOKUP(A14,绩效计算表!A:AI,23,FALSE) -> B+ | O14: ==SUM(BC14:BM14)+SUM(BO14:BP14) -> 3.5 | P14: ==VLOOKUP(A14,绩效计算表!A:AI,30,FALSE) -> A | Q14: ==I14+K14+M14+O14 -> 8.5 | R14: 控制器基本业务 小信云 | T14: 核心 | V14: B+ | W14: 有备份情况下，可以考虑转到其他部门 | X14: 0.5 | Z14: 0.5 | AE14: ==SUM(X14:AD14)/6 -> 0.16666667 | AF14: 0.5 | AI14: 1 | AM14: 0.5 | AP14: ==SUM(AF14:AO14)/7.5 -> 0.26666667 | AU14: 0.5 | AW14: 1 | AY14: 0.5 | BB14: ==SUM(AQ14:BA14)/7.5 -> 0.26666667 | BG14: 0.5 | BI14: 0.5 | BK14: 1 | BM14: 1 | BN14: ==SUM(BC14:BM14)/9 -> 0.33333333 | BP14: 0.5
A15: 77251 | B15: 陈金俊 | C15: 软件研发体系 | D15: 基础网络 | E15: NMC软件研发部 | G15: 软件开发工程师 | H15: 41099 | I15: ==SUM(X15:AD15) -> 4 | J15: ==VLOOKUP(A15,绩效计算表!A:AI,9,FALSE) -> B+ | K15: ==SUM(AF15:AO15) -> 4 | L15: ==VLOOKUP(A15,绩效计算表!A:AI,15,FALSE) -> B+ | M15: ==SUM(AQ15:BA15) -> 3.15 | N15: ==VLOOKUP(A15,绩效计算表!A:AI,23,FALSE) -> B+ | O15: ==SUM(BC15:BM15)+SUM(BO15:BP15) -> 3.5 | P15: ==VLOOKUP(A15,绩效计算表!A:AI,30,FALSE) -> B | Q15: ==I15+K15+M15+O15 -> 14.65 | R15: 控制器业务 小信云 问题兜底 | T15: 核心 | V15: B+ | W15: 在本部门担任架构师 | X15: 0.5 | Y15: 1 | Z15: 0.5 | AC15: 1 | AD15: 1 | AE15: ==SUM(X15:AD15)/6 -> 0.66666667 | AF15: 0.5 | AI15: 1 | AL15: 1 | AM15: 1 | AO15: 0.5 | AP15: ==SUM(AF15:AO15)/7.5 -> 0.53333333 | AS15: 0.5 | AT15: 0.5 | AU15: 1 | AX15: 1 | AY15: 0.15 | BB15: ==SUM(AQ15:BA15)/7.5 -> 0.42 | BD15: 1 | BG15: 0.5 | BJ15: 0.5 | BL15: 0.5 | BM15: 1 | BN15: ==SUM(BC15:BM15)/9 -> 0.38888889
A16: 95220 | B16: 温智皓 | C16: 软件研发体系 | D16: 基础网络 | E16: NMC软件研发部 | G16: 软件开发工程师 | H16: 44440 | I16: ==SUM(X16:AD16) -> 1 | J16: ==VLOOKUP(A16,绩效计算表!A:AI,9,FALSE) -> #N/A | K16: ==SUM(AF16:AO16) -> 3.5 | L16: ==VLOOKUP(A16,绩效计算表!A:AI,15,FALSE) -> #N/A | M16: ==SUM(AQ16:BA16) -> 0 | N16: ==VLOOKUP(A16,绩效计算表!A:AI,23,FALSE) -> #N/A | O16: ==SUM(BC16:BM16)+SUM(BO16:BP16) -> 0 | P16: ==VLOOKUP(A16,绩效计算表!A:AI,30,FALSE) -> #N/A | Q16: ==I16+K16+M16+O16 -> 4.5 | R16: 控制器基本业务 | T16: 高潜 | V16: A | W16: 可在无线/SW进一步培养 | AC16: 1 | AE16: ==SUM(X16:AD16)/6 -> 0.16666667 | AJ16: 1 | AM16: 1 | AN16: 1 | AO16: 0.5 | AP16: ==SUM(AF16:AO16)/7.5 -> 0.46666667 | BB16: ==SUM(AQ16:BA16)/7.5 -> 0 | BN16: ==SUM(BC16:BM16)/9 -> 0
A17: 20811 | B17: 黄宇成 | C17: 软件研发体系 | D17: 基础网络 | E17: NMC软件研发部 | G17: 软件开发工程师 | H17: 43983 | I17: ==SUM(X17:AD17) -> 1 | J17: ==VLOOKUP(A17,绩效计算表!A:AI,9,FALSE) -> B | K17: ==SUM(AF17:AO17) -> 0 | L17: ==VLOOKUP(A17,绩效计算表!A:AI,15,FALSE) -> B | M17: ==SUM(AQ17:BA17) -> 0 | N17: ==VLOOKUP(A17,绩效计算表!A:AI,23,FALSE) -> B | O17: ==SUM(BC17:BM17)+SUM(BO17:BP17) -> 0 | P17: ==VLOOKUP(A17,绩效计算表!A:AI,30,FALSE) -> B | Q17: ==I17+K17+M17+O17 -> 1 | R17: 控制器基本业务 | T17: 达标员工 | V17: B+ | W17: 可在无线/SW进一步培养 | AC17: 1 | AE17: ==SUM(X17:AD17)/6 -> 0.16666667 | AP17: ==SUM(AF17:AO17)/7.5 -> 0 | BB17: ==SUM(AQ17:BA17)/7.5 -> 0 | BN17: ==SUM(BC17:BM17)/9 -> 0
A18: 40226 | B18: 龙逸舒 | C18: 软件研发体系 | D18: 基础网络 | E18: NMC软件研发部 | G18: 软件开发工程师 | H18: 43934 | I18: ==SUM(X18:AD18) -> 0 | J18: ==VLOOKUP(A18,绩效计算表!A:AI,9,FALSE) -> #N/A | K18: ==SUM(AF18:AO18) -> 0 | L18: ==VLOOKUP(A18,绩效计算表!A:AI,15,FALSE) -> #N/A | M18: ==SUM(AQ18:BA18) -> 0 | N18: ==VLOOKUP(A18,绩效计算表!A:AI,23,FALSE) -> #N/A | O18: ==SUM(BC18:BM18)+SUM(BO18:BP18) -> 0 | P18: ==VLOOKUP(A18,绩效计算表!A:AI,30,FALSE) -> #N/A | Q18: ==I18+K18+M18+O18 -> 0 | AE18: ==SUM(X18:AD18)/6 -> 0 | AP18: ==SUM(AF18:AO18)/7.5 -> 0 | BB18: ==SUM(AQ18:BA18)/7.5 -> 0 | BN18: ==SUM(BC18:BM18)/9 -> 0
A19: 23418 | B19: 吴盾 | C19: 软件研发体系 | D19: 基础网络 | E19: NMC软件研发部 | F19: FEX | G19: 软件开发工程师 | H19: 45362 | I19: ==SUM(X19:AD19) -> 2.5 | J19: ==VLOOKUP(A19,绩效计算表!A:AI,9,FALSE) -> B+ | K19: ==SUM(AF19:AO19) -> 4.5 | L19: ==VLOOKUP(A19,绩效计算表!A:AI,15,FALSE) -> B+ | M19: ==SUM(AQ19:BA19) -> 1.5 | N19: ==VLOOKUP(A19,绩效计算表!A:AI,23,FALSE) -> B+ | O19: ==SUM(BC19:BM19)+SUM(BO19:BP19) -> 0 | P19: ==VLOOKUP(A19,绩效计算表!A:AI,30,FALSE) -> B | Q19: ==I19+K19+M19+O19 -> 8.5 | R19: 上手熟悉阶段 | T19: 高潜 | V19: B+ | W19: 可在无线/SW进一步培养 | Y19: 1 | Z19: 0.5 | AD19: 1 | AE19: ==SUM(X19:AD19)/6 -> 0.41666667 | AF19: 0.5 | AG19: 1 | AI19: 1 | AJ19: 1 | AM19: 1 | AP19: ==SUM(AF19:AO19)/7.5 -> 0.6 | AT19: 0.5 | AV19: 0.5 | BA19: 0.5 | BB19: ==SUM(AQ19:BA19)/7.5 -> 0.2 | BN19: ==SUM(BC19:BM19)/9 -> 0
A20: 92042 | B20: 唐小伟 | C20: 软件研发体系 | D20: 基础网络 | E20: NMC软件研发部 | F20: FEX | G20: 软件开发工程师 | H20: 43077 | I20: ==SUM(X20:AD20) -> 0 | J20: ==VLOOKUP(A20,绩效计算表!A:AI,9,FALSE) -> B | K20: ==SUM(AF20:AO20) -> 4 | L20: ==VLOOKUP(A20,绩效计算表!A:AI,15,FALSE) -> B | M20: ==SUM(AQ20:BA20) -> 1.5 | N20: ==VLOOKUP(A20,绩效计算表!A:AI,23,FALSE) -> B | O20: ==SUM(BC20:BM20)+SUM(BO20:BP20) -> 3.5 | P20: ==VLOOKUP(A20,绩效计算表!A:AI,30,FALSE) -> B | Q20: ==I20+K20+M20+O20 -> 9 | R20: 上手熟悉阶段 | T20: 高潜(UED处) | V20: B | W20: 后续会转会议主机 | AE20: ==SUM(X20:AD20)/6 -> 0 | AG20: 1 | AI20: 1 | AJ20: 1 | AM20: 1 | AP20: ==SUM(AF20:AO20)/7.5 -> 0.53333333 | AT20: 0.5 | AX20: 1 | BB20: ==SUM(AQ20:BA20)/7.5 -> 0.2 | BH20: 1 | BJ20: 0.5 | BL20: 1 | BM20: 1 | BN20: ==SUM(BC20:BM20)/9 -> 0.38888889
A21: 91418 | B21: 刘威 | C21: 软件研发体系 | D21: 基础网络 | E21: NMC软件研发部 | G21: 软件开发工程师 | H21: 44984 | I21: ==SUM(X21:AD21) -> 2.5 | J21: ==VLOOKUP(A21,绩效计算表!A:AI,9,FALSE) -> A | K21: ==SUM(AF21:AO21) -> 3.5 | L21: ==VLOOKUP(A21,绩效计算表!A:AI,15,FALSE) -> B+ | M21: ==SUM(AQ21:BA21) -> 1 | N21: ==VLOOKUP(A21,绩效计算表!A:AI,23,FALSE) -> A | O21: ==SUM(BC21:BM21)+SUM(BO21:BP21) -> 2.5 | P21: ==VLOOKUP(A21,绩效计算表!A:AI,30,FALSE) -> A | Q21: ==I21+K21+M21+O21 -> 9.5 | R21: 控制器基本业务 | T21: 高潜 | V21: B+ | W21: 未成长起来，后续可在无线/SW进一步培养 | X21: 0.5 | Y21: 1 | Z21: 0.5 | AC21: 0.5 | AE21: ==SUM(X21:AD21)/6 -> 0.41666667 | AF21: 0.5 | AI21: 1 | AJ21: 0.5 | AM21: 1 | AO21: 0.5 | AP21: ==SUM(AF21:AO21)/7.5 -> 0.46666667 | AV21: 0.5 | AY21: 0.5 | BB21: ==SUM(AQ21:BA21)/7.5 -> 0.13333333 | BC21: 0.5 | BH21: 1 | BL21: 1 | BN21: ==SUM(BC21:BM21)/9 -> 0.27777778
A22: 96208 | B22: 王维 | C22: 软件研发体系 | D22: 基础网络 | E22: NMC软件研发部 | G22: 软件开发工程师 | H22: 42191 | I22: ==SUM(X22:AD22) -> 2 | J22: ==VLOOKUP(A22,绩效计算表!A:AI,9,FALSE) -> B | K22: ==SUM(AF22:AO22) -> 0 | L22: ==VLOOKUP(A22,绩效计算表!A:AI,15,FALSE) -> B+ | M22: ==SUM(AQ22:BA22) -> 0 | N22: ==VLOOKUP(A22,绩效计算表!A:AI,23,FALSE) -> B+ | O22: ==SUM(BC22:BM22)+SUM(BO22:BP22) -> 0.25 | P22: ==VLOOKUP(A22,绩效计算表!A:AI,30,FALSE) -> B+ | Q22: ==I22+K22+M22+O22 -> 2.25 | R22: 控制器基本业务 网关业务 | T22: 核心 | V22: B+ | W22: 可转无线/SW发挥更大作用 | Y22: 0.5 | AB22: 1 | AD22: 0.5 | AE22: ==SUM(X22:AD22)/6 -> 0.33333333 | AP22: ==SUM(AF22:AO22)/7.5 -> 0 | BB22: ==SUM(AQ22:BA22)/7.5 -> 0 | BC22: 0.25 | BN22: ==SUM(BC22:BM22)/9 -> 0.027777778
A23: 53558 | B23: 伍连啟 | C23: 软件研发体系 | D23: 基础网络 | E23: NMC软件研发部 | G23: 软件开发工程师 | H23: 42919 | I23: ==SUM(X23:AD23) -> 0 | J23: ==VLOOKUP(A23,绩效计算表!A:AI,9,FALSE) -> B | K23: ==SUM(AF23:AO23) -> 0 | L23: ==VLOOKUP(A23,绩效计算表!A:AI,15,FALSE) -> B+ | M23: ==SUM(AQ23:BA23) -> 0 | N23: ==VLOOKUP(A23,绩效计算表!A:AI,23,FALSE) -> B | O23: ==SUM(BC23:BM23)+SUM(BO23:BP23) -> 0.5 | P23: ==VLOOKUP(A23,绩效计算表!A:AI,30,FALSE) -> B | Q23: ==I23+K23+M23+O23 -> 0.5 | R23: 控制器基本业务 交换机基本业务 | T23: 达标员工 | V23: B | W23: 潜力一般，放在本部门作基础开发 | AE23: ==SUM(X23:AD23)/6 -> 0 | AP23: ==SUM(AF23:AO23)/7.5 -> 0 | BB23: ==SUM(AQ23:BA23)/7.5 -> 0 | BJ23: 0.5 | BN23: ==SUM(BC23:BM23)/9 -> 0.055555556
A24: 19083 | B24: 陈加广 | C24: 软件研发体系 | D24: 基础网络 | E24: NMC软件研发部 | G24: 软件开发工程师 | H24: 44193 | I24: ==SUM(X24:AD24) -> 2 | J24: ==VLOOKUP(A24,绩效计算表!A:AI,9,FALSE) -> B | K24: ==SUM(AF24:AO24) -> 1 | L24: ==VLOOKUP(A24,绩效计算表!A:AI,15,FALSE) -> B | M24: ==SUM(AQ24:BA24) -> 0.5 | N24: ==VLOOKUP(A24,绩效计算表!A:AI,23,FALSE) -> B | O24: ==SUM(BC24:BM24)+SUM(BO24:BP24) -> 0 | P24: ==VLOOKUP(A24,绩效计算表!A:AI,30,FALSE) -> B | Q24: ==I24+K24+M24+O24 -> 3.5 | R24: 控制器基本业务 小信云 | T24: 达标员工 | U24: 云问题排查 | V24: B | W24: 学习能力不错，沟通能力一般，放在本部门支撑云相关基本业务 | Z24: 0.5 | AA24: 1 | AC24: 0.5 | AE24: ==SUM(X24:AD24)/6 -> 0.33333333 | AM24: 1 | AP24: ==SUM(AF24:AO24)/7.5 -> 0.13333333 | AR24: 0.5 | BB24: ==SUM(AQ24:BA24)/7.5 -> 0.066666667 | BN24: ==SUM(BC24:BM24)/9 -> 0
A25: 17795 | B25: 彭清华 | C25: 软件研发体系 | D25: 基础网络 | E25: NMC软件研发部 | G25: 软件开发工程师 | H25: 43245 | I25: ==SUM(X25:AD25) -> 1 | J25: ==VLOOKUP(A25,绩效计算表!A:AI,9,FALSE) -> B | K25: ==SUM(AF25:AO25) -> 2 | L25: ==VLOOKUP(A25,绩效计算表!A:AI,15,FALSE) -> B | M25: ==SUM(AQ25:BA25) -> 4.5 | N25: ==VLOOKUP(A25,绩效计算表!A:AI,23,FALSE) -> B+ | O25: ==SUM(BC25:BM25)+SUM(BO25:BP25) -> 4 | P25: ==VLOOKUP(A25,绩效计算表!A:AI,30,FALSE) -> B+ | Q25: ==I25+K25+M25+O25 -> 11.5 | R25: 控制器基本业务 网关业务 网关适配 | T25: 达标员工 | U25: 网关适配 | V25: B | W25: 潜力一般，放在本部门作基础开发 | AD25: 1 | AE25: ==SUM(X25:AD25)/6 -> 0.16666667 | AI25: 1 | AJ25: 1 | AP25: ==SUM(AF25:AO25)/7.5 -> 0.26666667 | AS25: 1 | AT25: 0.5 | AU25: 1 | AW25: 0.5 | AY25: 0.5 | AZ25: 1 | BB25: ==SUM(AQ25:BA25)/7.5 -> 0.6 | BG25: 1 | BH25: 1 | BK25: 1 | BM25: 1 | BN25: ==SUM(BC25:BM25)/9 -> 0.44444444
A26: 40624 | B26: 熊宽 | C26: 软件研发体系 | D26: 基础网络 | E26: NMC软件研发部 | G26: 软件开发工程师 | H26: 44746 | I26: ==SUM(X26:AD26) -> 0 | J26: ==VLOOKUP(A26,绩效计算表!A:AI,9,FALSE) -> #N/A | K26: ==SUM(AF26:AO26) -> 0 | L26: ==VLOOKUP(A26,绩效计算表!A:AI,15,FALSE) -> #N/A | M26: ==SUM(AQ26:BA26) -> 0 | N26: ==VLOOKUP(A26,绩效计算表!A:AI,23,FALSE) -> #N/A | O26: ==SUM(BC26:BM26)+SUM(BO26:BP26) -> 0 | P26: ==VLOOKUP(A26,绩效计算表!A:AI,30,FALSE) -> #N/A | Q26: ==I26+K26+M26+O26 -> 0 | R26: 控制器基本业务 | T26: 待激活员工 | V26: B | W26: 预计将离职 | AE26: ==SUM(X26:AD26)/6 -> 0 | AP26: ==SUM(AF26:AO26)/7.5 -> 0 | BB26: ==SUM(AQ26:BA26)/7.5 -> 0 | BN26: ==SUM(BC26:BM26)/9 -> 0
A27: 52012 | B27: 张浩 | C27: 软件研发体系 | D27: 基础网络 | E27: NMC软件研发部 | G27: 软件开发工程师 | H27: 45110 | I27: ==SUM(X27:AD27) -> 1 | J27: ==VLOOKUP(A27,绩效计算表!A:AI,9,FALSE) -> B+ | K27: ==SUM(AF27:AO27) -> 0 | L27: ==VLOOKUP(A27,绩效计算表!A:AI,15,FALSE) -> B | M27: ==SUM(AQ27:BA27) -> 0 | N27: ==VLOOKUP(A27,绩效计算表!A:AI,23,FALSE) -> B | O27: ==SUM(BC27:BM27)+SUM(BO27:BP27) -> 1 | P27: ==VLOOKUP(A27,绩效计算表!A:AI,30,FALSE) -> B+ | Q27: ==I27+K27+M27+O27 -> 2 | R27: 控制器基本业务 | T27: 高潜 | V27: B+ | W27: 可在进一步成长后，转部门进一步培养 | AC27: 1 | AE27: ==SUM(X27:AD27)/6 -> 0.16666667 | AP27: ==SUM(AF27:AO27)/7.5 -> 0 | BB27: ==SUM(AQ27:BA27)/7.5 -> 0 | BM27: 1 | BN27: ==SUM(BC27:BM27)/9 -> 0.11111111
A28: 99812 | B28: 赵呈祥 | C28: 软件研发体系 | D28: 基础网络 | E28: NMC软件研发部 | G28: 软件开发工程师 | H28: 44746 | I28: ==SUM(X28:AD28) -> 0 | J28: ==VLOOKUP(A28,绩效计算表!A:AI,9,FALSE) -> B | K28: ==SUM(AF28:AO28) -> 0 | L28: ==VLOOKUP(A28,绩效计算表!A:AI,15,FALSE) -> B | M28: ==SUM(AQ28:BA28) -> 1 | N28: ==VLOOKUP(A28,绩效计算表!A:AI,23,FALSE) -> B+ | O28: ==SUM(BC28:BM28)+SUM(BO28:BP28) -> 0 | P28: ==VLOOKUP(A28,绩效计算表!A:AI,30,FALSE) -> B | Q28: ==I28+K28+M28+O28 -> 1 | R28: 控制器基本业务 交换机基本业务 | T28: 达标员工 | V28: B | W28: 潜力一般，放在本部门作基础开发 | AE28: ==SUM(X28:AD28)/6 -> 0 | AP28: ==SUM(AF28:AO28)/7.5 -> 0 | AZ28: 1 | BB28: ==SUM(AQ28:BA28)/7.5 -> 0.13333333 | BN28: ==SUM(BC28:BM28)/9 -> 0
A29: 28062 | B29: 任海斌 | C29: 软件研发体系 | D29: 基础网络 | E29: NMC软件研发部 | G29: 软件开发工程师 | H29: 41827 | I29: ==SUM(X29:AD29) -> 6 | J29: ==VLOOKUP(A29,绩效计算表!A:AI,9,FALSE) -> #N/A | K29: ==SUM(AF29:AO29) -> 7.5 | L29: ==VLOOKUP(A29,绩效计算表!A:AI,15,FALSE) -> #N/A | M29: ==SUM(AQ29:BA29) -> 1.5 | N29: ==VLOOKUP(A29,绩效计算表!A:AI,23,FALSE) -> #N/A | O29: ==SUM(BC29:BM29)+SUM(BO29:BP29) -> 0 | P29: ==VLOOKUP(A29,绩效计算表!A:AI,30,FALSE) -> #N/A | Q29: ==I29+K29+M29+O29 -> 15 | R29: 控制器业务 无线业务 网关业务 | T29: 核心 | V29: A | W29: 在本部门继续担任组长 | X29: 0.5 | Y29: 1 | Z29: 0.5 | AA29: 1 | AB29: 1 | AC29: 1 | AD29: 1 | AE29: ==SUM(X29:AD29)/6 -> 1 | AF29: 0.5 | AG29: 1 | AH29: 1 | AI29: 1 | AJ29: 0.5 | AK29: 0.5 | AL29: 1 | AM29: 1 | AN29: 1 | AP29: ==SUM(AF29:AO29)/7.5 -> 1 | AT29: 0.5 | AU29: 1 | BB29: ==SUM(AQ29:BA29)/7.5 -> 0.2 | BN29: ==SUM(BC29:BM29)/9 -> 0
A30: 72949 | B30: 孟洋 | C30: 软件研发体系 | D30: 基础网络 | E30: NMC软件研发部 | G30: 软件开发工程师 | I30: ==SUM(X30:AD30) -> 0 | J30: ==VLOOKUP(A30,绩效计算表!A:AI,9,FALSE) -> 0 | K30: ==SUM(AF30:AO30) -> 0 | L30: ==VLOOKUP(A30,绩效计算表!A:AI,15,FALSE) -> 0 | M30: ==SUM(AQ30:BA30) -> 0 | N30: ==VLOOKUP(A30,绩效计算表!A:AI,23,FALSE) -> B | O30: ==SUM(BC30:BM30)+SUM(BO30:BP30) -> 0 | P30: ==VLOOKUP(A30,绩效计算表!A:AI,30,FALSE) -> B+ | Q30: ==I30+K30+M30+O30 -> 0 | BB30: ==SUM(AQ30:BA30)/7.5 -> 0 | BN30: ==SUM(BC30:BM30)/9 -> 0
A31: 77303 | B31: 李菁 | O31: ==SUM(BC31:BM31)+SUM(BO31:BP31) -> 0.5 | P31: 无绩效 | Q31: ==I31+K31+M31+O31 -> 0.5 | BN31: ==SUM(BC31:BM31)/9 -> 0 | BP31: 0.5
A32: 27724 | B32: 刘焕 | O32: ==SUM(BC32:BM32)+SUM(BO32:BP32) -> 0.5 | P32: 无绩效 | Q32: ==I32+K32+M32+O32 -> 0.5 | BN32: ==SUM(BC32:BM32)/9 -> 0 | BO32: 0.5
A33: 22026 | B33: 刘涛 | C33: 软件研发体系 | D33: 基础网络 | E33: NMC软件研发部 | G33: 软件开发工程师 | H33: 42561 | I33: ==SUM(X33:AD33) -> 6 | J33: ？ | K33: ==SUM(AF33:AO33) -> 5.5 | L33: ？ | M33: ==SUM(AQ33:BA33) -> 7.5 | N33: ？ | O33: ==SUM(BC33:BM33)+SUM(BO33:BP33) -> 10.5 | P33: ？ | Q33: ==I33+K33+M33+O33 -> 29.5 | R33: 控制器业务 无线业务 | T33: 核心 | X33: 0.5 | Y33: 1 | Z33: 0.5 | AA33: 1 | AB33: 1 | AC33: 1 | AD33: 1 | AE33: ==SUM(X33:AD33)/6 -> 1 | AF33: 0.5 | AG33: 1 | AI33: 1 | AK33: 0.5 | AM33: 1 | AN33: 1 | AO33: 0.5 | AP33: ==SUM(AF33:AO33)/7.5 -> 0.73333333 | AR33: 1 | AS33: 1 | AU33: 1 | AV33: 1 | AW33: 1 | AX33: 1 | AY33: 0.5 | AZ33: 1 | BB33: ==SUM(AQ33:BA33)/7.5 -> 1 | BC33: 0.5 | BD33: 1 | BE33: 0.5 | BF33: 1 | BG33: 1 | BH33: 1 | BI33: 1 | BJ33: 0.5 | BK33: 1 | BL33: 0.5 | BM33: 1 | BN33: ==SUM(BC33:BM33)/9 -> 1 | BO33: 1 | BP33: 0.5
A34: 93622 | B34: 黄涛 | C34: 软件研发体系 | D34: 基础网络 | E34: FEX | G34: 软件开发工程师 | H34: 42880 | I34: ==SUM(X34:AD34) -> 2.5 | J34: ==VLOOKUP(A34,绩效计算表!A:AI,9,FALSE) -> B+ | K34: ==SUM(AF34:AO34) -> 5 | L34: ==VLOOKUP(A34,绩效计算表!A:AI,15,FALSE) -> A | M34: ==SUM(AQ34:BA34) -> 3.5 | N34: ==VLOOKUP(A34,绩效计算表!A:AI,23,FALSE) -> A | O34: ==SUM(BC34:BM34)+SUM(BO34:BP34) -> 6 | P34: ==VLOOKUP(A34,绩效计算表!A:AI,30,FALSE) -> A | Q34: ==I34+K34+M34+O34 -> 17 | R34: JS技术指导、NMC业务支撑JS | S34: 性格特点：为人随和踏实、易沟通好相处 能力胜任：优秀 工作态度：优秀 思维逻辑：优秀 其他关键信息：责任心极强，主动加班攻坚 | T34: 核心 | V34: 前端疑难攻坚 | W34: NMC业务支撑主力JS APP业务备份 | Z34: 0.5 | AA34: 1 | AC34: 1 | AE34: ==SUM(X34:AD34)/6 -> 0.41666667 | AG34: 1 | AI34: 1 | AJ34: 0.5 | AL34: 1 | AM34: 1 | AN34: 0.5 | AP34: ==SUM(AF34:AO34)/7.5 -> 0.66666667 | AU34: 0.5 | AV34: 0.5 | AW34: 1 | AX34: 0.5 | BA34: 1 | BB34: ==SUM(AQ34:BA34)/7.5 -> 0.46666667 | BG34: 1 | BH34: 1 | BI34: 1 | BJ34: 0.5 | BK34: 0.5 | BL34: 1 | BM34: 1 | BN34: ==SUM(BC34:BM34)/9 -> 0.66666667
A35: 62340 | B35: 罗彦淋 | O35: ==SUM(BC35:BM35)+SUM(BO35:BP35) -> 1.5 | P35: 无绩效 | Q35: ==I35+K35+M35+O35 -> 1.5 | BM35: 1 | BN35: ==SUM(BC35:BM35)/9 -> 0.11111111 | BP35: 0.5
A36: 65248 | B36: 彭依岳 | C36: 软件研发体系 | D36: 基础网络 | E36: FEX | G36: 软件开发工程师 | H36: 43672 | I36: ==SUM(X36:AD36) -> 0 | J36: ==VLOOKUP(A36,绩效计算表!A:AI,9,FALSE) -> B | K36: ==SUM(AF36:AO36) -> 0 | L36: ==VLOOKUP(A36,绩效计算表!A:AI,15,FALSE) -> B+ | M36: ==SUM(AQ36:BA36) -> 0 | N36: ==VLOOKUP(A36,绩效计算表!A:AI,23,FALSE) -> B+ | O36: ==SUM(BC36:BM36)+SUM(BO36:BP36) -> 0 | P36: ==VLOOKUP(A36,绩效计算表!A:AI,30,FALSE) -> B+ | Q36: ==I36+K36+M36+O36 -> 0 | R36: 组件库维护/NMC业务支撑JS/网关业务支撑JS | S36: 性格特点：比较有自己的想法 能力胜任：优秀 工作态度：优秀 思维逻辑：优秀 其他关键信息：学习能力强、工作效率高 | T36: 高潜 | V36: 前端疑难攻坚 | W36: NMC业务支撑主力JS | AE36: ==SUM(X36:AD36)/6 -> 0 | AP36: ==SUM(AF36:AO36)/7.5 -> 0 | BB36: ==SUM(AQ36:BA36)/7.5 -> 0 | BN36: ==SUM(BC36:BM36)/9 -> 0
A37: 14659 | B37: 夏国富 | C37: 软件研发体系 | D37: 基础网络 | E37: FEX | G37: 软件开发工程师 | H37: 44265 | I37: ==SUM(X37:AD37) -> 3.5 | J37: ==VLOOKUP(A37,绩效计算表!A:AI,9,FALSE) -> A | K37: ==SUM(AF37:AO37) -> 3.5 | L37: ==VLOOKUP(A37,绩效计算表!A:AI,15,FALSE) -> B+ | M37: ==SUM(AQ37:BA37) -> 3.5 | N37: ==VLOOKUP(A37,绩效计算表!A:AI,23,FALSE) -> B+ | O37: ==SUM(BC37:BM37)+SUM(BO37:BP37) -> 2.5 | P37: ==VLOOKUP(A37,绩效计算表!A:AI,30,FALSE) -> B+ | Q37: ==I37+K37+M37+O37 -> 13 | R37: NMC业务支撑PHP | S37: 性格特点：为人随和踏实、易沟通好相处 能力胜任：优秀 工作态度：优秀 思维逻辑：达标 其他关键信息：责任心强 | T37: 高潜 | W37: NMC业务支撑主力PHP | Y37: 1 | Z37: 0.5 | AA37: 1 | AC37: 1 | AE37: ==SUM(X37:AD37)/6 -> 0.58333333 | AG37: 1 | AL37: 1 | AM37: 1 | AO37: 0.5 | AP37: ==SUM(AF37:AO37)/7.5 -> 0.46666667 | AU37: 1 | AV37: 1 | AX37: 1 | AZ37: 0.5 | BB37: ==SUM(AQ37:BA37)/7.5 -> 0.46666667 | BJ37: 0.5 | BL37: 1 | BM37: 1 | BN37: ==SUM(BC37:BM37)/9 -> 0.27777778
A38: 17855 | B38: 吕东锋 | C38: 软件研发体系 | D38: 基础网络 | E38: FEX | G38: 软件开发工程师 | H38: 43752 | I38: ==SUM(X38:AD38) -> 0.5 | J38: ==VLOOKUP(A38,绩效计算表!A:AI,9,FALSE) -> #N/A | K38: ==SUM(AF38:AO38) -> 2 | L38: ==VLOOKUP(A38,绩效计算表!A:AI,15,FALSE) -> #N/A | M38: ==SUM(AQ38:BA38) -> 1 | N38: ==VLOOKUP(A38,绩效计算表!A:AI,23,FALSE) -> #N/A | O38: ==SUM(BC38:BM38)+SUM(BO38:BP38) -> 0 | P38: ==VLOOKUP(A38,绩效计算表!A:AI,30,FALSE) -> #N/A | Q38: ==I38+K38+M38+O38 -> 3.5 | R38: 网关业务支撑JS | S38: 性格特点： 能力胜任：优秀 工作态度：优秀 思维逻辑：优秀 其他关键信息：有钻研精神、学习能量强 | T38: 高潜 | V38: 能力上有发展支撑后台业务的潜力 | W38: 后续转后台开发 | Z38: 0.5 | AE38: ==SUM(X38:AD38)/6 -> 0.083333333 | AI38: 1 | AM38: 1 | AP38: ==SUM(AF38:AO38)/7.5 -> 0.26666667 | AT38: 0.5 | AV38: 0.5 | BB38: ==SUM(AQ38:BA38)/7.5 -> 0.13333333 | BN38: ==SUM(BC38:BM38)/9 -> 0
A39: 70568 | B39: 黄双 | C39: 软件研发体系 | D39: 基础网络 | E39: FEX | G39: 软件开发工程师 | H39: 42499 | I39: ==SUM(X39:AD39) -> 2.5 | J39: ==VLOOKUP(A39,绩效计算表!A:AI,9,FALSE) -> B | K39: ==SUM(AF39:AO39) -> 2 | L39: ==VLOOKUP(A39,绩效计算表!A:AI,15,FALSE) -> B | M39: ==SUM(AQ39:BA39) -> 3.75 | N39: ==VLOOKUP(A39,绩效计算表!A:AI,23,FALSE) -> B | O39: ==SUM(BC39:BM39)+SUM(BO39:BP39) -> 2.5 | P39: ==VLOOKUP(A39,绩效计算表!A:AI,30,FALSE) -> B | Q39: ==I39+K39+M39+O39 -> 10.75 | R39: NMC业务支撑JS | S39: 性格特点：开朗活泼 能力胜任：优秀 工作态度：达标 思维逻辑：优秀 其他关键信息：有交互设计经验 | T39: 达标员工 | W39: NMC业务支撑JS | Z39: 0.5 | AA39: 1 | AD39: 1 | AE39: ==SUM(X39:AD39)/6 -> 0.41666667 | AG39: 1 | AL39: 1 | AP39: ==SUM(AF39:AO39)/7.5 -> 0.26666667 | AR39: 0.75 | AU39: 1 | AX39: 1 | AZ39: 1 | BB39: ==SUM(AQ39:BA39)/7.5 -> 0.5 | BF39: 1 | BK39: 0.5 | BM39: 1 | BN39: ==SUM(BC39:BM39)/9 -> 0.27777778
A40: 37038 | B40: 王永强 | C40: 软件研发体系 | D40: 基础网络 | E40: FEX | G40: 软件开发工程师 | H40: 42552 | I40: ==SUM(X40:AD40) -> 1.5 | J40: ==VLOOKUP(A40,绩效计算表!A:AI,9,FALSE) -> B+ | K40: ==SUM(AF40:AO40) -> 5.5 | L40: ==VLOOKUP(A40,绩效计算表!A:AI,15,FALSE) -> B+ | M40: ==SUM(AQ40:BA40) -> 2 | N40: ==VLOOKUP(A40,绩效计算表!A:AI,23,FALSE) -> B+ | O40: ==SUM(BC40:BM40)+SUM(BO40:BP40) -> 4.5 | P40: ==VLOOKUP(A40,绩效计算表!A:AI,30,FALSE) -> B+ | Q40: ==I40+K40+M40+O40 -> 13.5 | R40: 云管家/云工勘；无线业务支撑 | S40: 性格特点：为人随和踏实、易沟通好相处 能力胜任：优秀 工作态度：优秀 思维逻辑：优秀 其他关键信息：责任心极强，主动加班 | T40: 达标员工 | U40: 云管家 | W40: 无线业务支撑主力PHP 云管家/云工勘维护接口人 | Z40: 0.5 | AB40: 1 | AE40: ==SUM(X40:AD40)/6 -> 0.25 | AG40: 1 | AJ40: 1 | AL40: 1 | AM40: 1 | AN40: 1 | AO40: 0.5 | AP40: ==SUM(AF40:AO40)/7.5 -> 0.73333333 | AT40: 0.5 | AY40: 0.5 | BA40: 1 | BB40: ==SUM(AQ40:BA40)/7.5 -> 0.26666667 | BG40: 1 | BI40: 1 | BJ40: 0.5 | BL40: 1 | BM40: 1 | BN40: ==SUM(BC40:BM40)/9 -> 0.5
...

Sheet 离职、转部门员工备份
A1: 工号 | B1: 姓名 | C1: 职级 | D1: 一级部门 | E1: 二级部门 | F1: 三级部门 | G1: 原部门 | H1: 岗位 | I1: 入职时间 | J1: 离职时间 | K1: 25.02.10 | L1: 25.02.17 | M1: 25.02.24 | O1: 25.03.03 | Q1: 25.03.10 | S1: 25.03.17 | U1: 25.03.24 | W1: 25.03.31 | Y1: 25.04.7 | AA1: 25.04.14 | AC1: 25.04.21 | AE1: 25.04.27 | AG1: 25.05.06 | AI1: 25.05.12 | AK1: 25.05.19 | AM1: 25.05.26 | AO1: 25.06.03 | AQ1: 25.06.09 | AS1: 25.06.09 | AU1: 25.06.09
A2: 93641 | B2: 苏志卓 | C2: T2 | D2: 软件研发体系 | E2: 基础网络 | F2: NMC软件研发部 | G2: (实习) | J2: 2025年Q1 | W2: 价值 | X2: 小信GPT预言 | Y2: 价值 | Z2: 小信GPT预言 | AA2: 价值 | AB2: 小信GPT预言 | AC2: 价值 | AD2: 小信GPT预言 | AE2: 价值 | AF2: 小信GPT优化+预言 | AG2: 价值 | AH2: 小信GPT优化+预言 | AI2: 价值 | AJ2: 小信GPT优化+预言 | AK2: 休假 | AM2: 休假 | AO2: 休假 | AQ2: 上手 | AR2: 熟悉软件代码
A3: 57305 | B3: 吕明洋 | C3: T5 | D3: 软件研发体系 | E3: 基础网络 | F3: NMC软件研发部 | H3: 软件开发工程师 | I3: 43934 | J3: 2025年Q3 | K3: GPT | L3: GPT | M3: 价值 | N3: GPT AI Agent移植 | O3: 支援 | P3: 交换机ipv6 | Q3: 支援 | R3: 交换机ipv6 | S3: 支援 | T3: 交换机ipv6 | U3: 支援 | V3: 交换机ipv6 | W3: 支援 | X3: 交换机ipv6 | Y3: 支援 | Z3: 交换机ipv6 | AA3: 支援 | AB3: 交换机ipv6 | AC3: 支援 | AD3: 交换机ipv6 | AE3: 支援 | AF3: 交换机ipv6 | AG3: 支援 | AH3: 交换机ipv6 | AI3: 支援 | AJ3: 交换机ipv6 | AK3: 支援 | AL3: 交换机ipv6 | AM3: 支援 | AN3: 交换机ipv6 | AO3: 支援 | AP3: 交换机ipv6
A4: 28062 | B4: 任海斌 | C4: T8 | D4: 软件研发体系 | E4: 基础网络 | F4: NMC软件研发部 | H4: 软件开发工程师 | I4: 41827 | K4: 管理 | L4: 管理 | M4: 价值 | N4: Xmeeting移植 | O4: 价值 | P4: Xmeeting移植 | Q4: 价值 | R4: Xmeeting移植 | S4: 价值 | T4: Xmeeting移植 | U4: 管理 | V4: 管理 | W4: 管理 | X4: 管理 | Y4: 管理 | Z4: 管理 | AA4: 管理 | AB4: 管理 | AC4: 管理 | AD4: 管理 | AE4: 管理 | AF4: 管理 | AG4: 管理 | AH4: 管理 | AI4: 价值 | AJ4: 网关梯队调整 | AK4: 价值 | AL4: 网关梯队调整 | AM4: 价值 | AN4: 网关梯队调整 | AO4: 价值 | AP4: 网关梯队调整 | AQ4: 价值 | AR4: 网关梯队调整 | AS4: 价值 | AT4: 网关梯队调整 | AU4: 价值 | AV4: 网关梯队调整 | AW4: 价值 | AY4: 管理 | AZ4: 版本管理 | BA4: 管理 | BB4: 版本管理 | BC4: 管理 | BD4: 版本管理 | BE4: 管理 | BF4: 版本管理 | BG4: 管理 | BH4: 版本管理
