Workbook

Sheet sw-2026年OKR
B1: 维度 | C1: O | D1: 现状和差距 | E1: KR | F1: 举措
B2: 产品质量 | C2: O：面向客户业务和客户感知提升产品质量，消除影响客户满意度的关键质量问题， 明显提升客户口碑 | D2: 现状和差距排序： 1、topN问题：所谓环境类问题不能在第一时间有结论、光模块故障、堆叠健壮性、升级需断网， 2、大客户出现问题之后影响自动放大 3、一线、客户感知有滞后性，当前的质量感知对应的应该是过去一年的情况 4、质量版本修复到客户实际上架产生作用，时间也有大半年的偏移。（推广阻碍，升级阻碍） | E2: KR1：构建一线和渠道可使用的故障界定手段知识库，聚焦环境类问题快速界定故障发生在上下游哪个环节，覆盖TOP5环境类问题。后面持续扩充到断网类问题排障知识库
E3: KR2：堆叠、ospf、stp、策略路由、ROCE基于场景优化交付文档，通过标准化交付文档，错配漏配类问题减少20%
E4: KR3：迭代质量基线版本，解决已知top3软硬件结合类故障、冗余健壮性已知问题。 长期从架构上攻坚极致转控分离
E5: KR4： 降低客户质量修复难度，长期攻坚热补丁/故障隔离方案，26年确定非转发面补丁式升级方案。
B6: 产品竞争力 | C6: O1：聚焦超融合、存储融合组网需求，在高速无损能力方面构建竞争力，保障供应稳定 | D6: 现状和差距排序： 1、产品断供 2、国产化形态缺失 3、在开发中的国产化硬件缓存规格相比以前减少一办，无损能力性能受影响大 4、芯片供应不明朗，无相对长远应对举措 | E6: KR1：国产化平台的NS6820系列超融合交换机，聚焦超融合场景，尽量提前发布。底线时间7月。 --短期
E7: KR2：在无损算法性能层面攻坚，现有NS6820系列芯片缓存规格下降一半的前提下，通过软件调优尽可能减小差距，整体偏差5%内。并且持续做优化，形成具备竞争力的通用算法底座，（动态缓存、Headroom Buffer、）
E8: KR3：长期保障，应对芯片供应不稳定，软件需提速切换芯片的开发上市周期。当前阶段先做到周期缩短50%（按不同场景） --Q3做到
C9: O2：产品面向AI转型 | D9: 现状和差距排序： 1、当前产品形态对目前agent不友好，很多AIOps能力支持起来不通用。虽然未来AI应用会如何迭代还会有很大变数，但是我们产品当前已经和AI脱节 2、在AI网络方面我们涉足少，行业发展趋势下理论上有很多需求需要满足，这一块我们目前没有积累 | E9: KR1：AI赋能网络方向：AIOps能力支持，成为真正有AI标签的数通产品 | F9: 今年内完成agent对接基座搭建
F10: 利用AI在故障预测、智能诊断、配置优化方向（当前痛点），至少产出1项有效的产品创新，Q4产出mvp
E11: KR2：网络支撑AI方向：聚焦HCI和EDS场景，保持洞察AI业务发展，网络层面存在的痛点，通过和HCI、EDS协同，打造卖点。先从交付和流量模型这两个方向切入,找出至少一个客户痛点
B13: AI-Native转型 | C13: O：团队AINative开发，以4个场景化案例牵引，实际解决过去困扰效率的问题。在过程中构建最佳实践和部门AINative组织能力 | D13: 现状和差距排序： 1、AICoding部门正在推广，落地到生产项目并且成为开发流程，需要整个流程各环节的融合，包括测试实际自动化率、cicd环节建立 | E13: 更新-交换机部门2026年AICoding计划.htm
B14: 组织建设 | C14: O：构建以客户为中心、梯队有后劲的攻坚型团队 | D14: 现状和差距排序： 1、无固定客户零距离固定机制 2、短期业务需要高T、专家处理常规业务，有一定的冲突 3、核心岗位人员能力存在一些维度的差距 4、团队年轻成员占比较低 | E14: KR1: 产线核心岗位（规划、架构师、PMO、TL）季度走访客户，在教育、制造业、大客户，形成可内部分享的客户价值洞察报告、客户画像知识库，识别到的需求、问题转化为产品公共需求≥2项/季度，纳入产品roadmap
E15: KR2:高T人员通过高目标驱动，在产品客户体验典型痛点、竞争力短板、性能差距等维度攻克技术难题，T6及以上人员每人至少转化为一篇技术专利。
E16: KR3:关键岗位1:2后备，年轻人员比例大幅提升。Q2完成例行人才盘点，形成人才地图，核心岗位落实IDP培养计划

Sheet AD人力甘特图(2024)
A1: 整体人力甘特图
A3: 团队人力 | D3: 2024年
A4: 姓名 | B4: 岗位 | C4: 团队代号 | D4: 1月 | E4: 2月 | F4: 3月 | G4: 4月 | H4: 5月 | I4: 6月 | J4: 7月 | K4: 8月 | L4: 9月 | M4: 10月 | N4: 11月 | O4: 12月 | P4: 负责价值领域 | R4: 撤出时间 | S4: 下个工作
A5: 吴广华 | B5: 开发 | C5: coredump组 | D5: 定制项目 | E5: 定制项目 | F5: 定制项目 | G5: 快速响应/ 7026R2英 | H5: 快速响应/ 7026R2英 | I5: 快速响应/ 7026R2英 | J5: 快速响应/ 7026R2英 | K5: 快速响应/ 7026R3 | L5: 7026R3 | M5: 7026R3 | N5: 7026R3 | O5: 7026R3 | P5: 集群手动同步 | Q5: 7026R3 | R5: / | V5: 招行POC
A6: 刘文龙 | B6: lizhi | C6: coredump组 | D6: 7027 | E6: 7028 | F6: 7028 | G6: 7028 | H6: 7028 | I6: 7028 | J6: 7028 | K6: / | L6: / | M6: / | N6: / | O6: / | P6: RAS | R6: lizhi
A7: 雷斌亭 | B7: 开发 | C7: coredump组 | D7: 7027 | E7: 预研 | F7: 预研 | G7: 快速响应/ 定制 | H7: 快速响应/ 定制 | I7: 快速响应/ 定制 | J7: 预研 | K7: 预研 | L7: 云AD | M7: 云AD | N7: 云AD | O7: 云AD | P7: 半链接/排障能力/大项目 | Q7: 云AD | R7: /
A8: 樊晗生 | B8: 开发 | C8: coredump组 | D8: 7027 | E8: 定制项目 | F8: 定制项目 | G8: 7028 | H8: 7028 | I8: 7028 | J8: 快速响应/ 7026R3 | K8: 快速响应/ 7026R3 | L8: 7028 | M8: 7026R3 | N8: 7026R3 | O8: / | P8: 吉大key/动态路由稳定/大项目 | Q8: 7026R3/内核升级 | R8: /
A9: 高光毫 | B9: 开发 | C9: coredump组 | D9: 7027 | E9: 定制项目 | F9: 质量/KA客户 | G9: 7028 | H9: 7028 | I9: 7028 | J9: 7028 | K9: 技术支持 | L9: 7026R3 | M9: 7026R3 | N9: 预研 | O9: 预研 | P9: sslo | Q9: ipro性能优化 | R9: / | V9: 质量补丁
A10: 刘都都 | B10: 开发 | C10: coredump组 | D10: 7027 | E10: 定制项目 | F10: 定制项目 | G10: 快速响应/ 定制 | H10: 快速响应/ 定制 | I10: 快速响应/ 定制 | J10: 快速响应/ 定制 | K10: 快速响应/ 定制 | L10: 预研 | M10: 快速响应/ 定制 | N10: 预研 | O10: 7029 | P10: 国密三级/定制邮储 | Q10: FPGA/DPU | R10: / | V10: 国税定制
A11: 张新锐 | B11: 开发 | C11: coredump组 | D11: 7027 | E11: 定制项目 | F11: 定制项目 | G11: 快速响应/ 7026R2英 | H11: 快速响应/ 7026R2英 | I11: 快速响应/ 7026R2英 | J11: 快速响应/ 7026R2英 | K11: 快速响应/ 7026R3 | L11: 7026R3 | M11: 7026R3 | N11: 7026R3 | O11: 7026R3 | P11: SNMP定制 | Q11: 7026R3/协议栈 | R11: /
A12: 郑泳 | B12: 开发 | C12: coredump组 | D12: 7027 | E12: 定制项目 | F12: 定制项目 | G12: 快速响应/ 定制 | H12: 快速响应/ 定制 | I12: 快速响应/ 定制 | J12: 快速响应/ 定制 | K12: 快速响应/ 定制 | L12: 云AD | M12: 云AD | N12: 云AD | O12: 云AD | P12: CNAD | Q12: 云AD | R12: /
A13: 薛载路 | B13: 测试 | C13: coredump组 | D13: 7027 | E13: 7027 | F13: 定制/补丁 | G13: 7028 | H13: 快速响应/ 7026R3 | I13: 快速响应/ 定制 | J13: 快速响应/ 定制 | K13: 快速响应/ 7026R3 | L13: 快速响应/ 定制 | M13: 7026R3 | N13: 7026R3 | O13: 7026R3 | Q13: 移动入围 | R13: / | S13: 7026R3 | V13: 1
A14: 曹刚 | B14: 测试 | C14: coredump组 | D14: 7027 | E14: 7027 | F14: 定制/补丁 | G14: 7028 | H14: 快速响应/ 7026R2英 | I14: 快速响应/ 7026R2英 | J14: 快速响应/ 7026R2英 | K14: 快速响应/ 7026R3 | L14: 7026R3 | M14: 7026R3 | N14: 7026R3 | O14: 7026R3 | Q14: 7028 | R14: 45544 | S14: 7026R3 | V14: 2
A15: 刘思远 | B15: 测试 | C15: coredump组 | H15: 快速响应/ 7026R2英 | I15: 快速响应/ 7026R2英 | J15: 快速响应/ 7026R2英 | K15: 快速响应/ 7026R3 | L15: 7026R3 | M15: 7026R3 | N15: 7026R3 | O15: 7026R3 | Q15: 7026R3 | R15: / | S15: / | V15: 1.5
A16: 苏敏宁 | B16: 开发 | C16: 嘲风 | D16: 7028 | E16: 7028 | F16: 7028 | G16: 7028 | H16: 7028 | I16: 7028 | J16: 7028 | K16: 7028 | L16: 7028 | M16: 7026R3 | N16: 7026R3 | O16: 7026R3 | P16: 命令行/snmp/syslog/PM | Q16: 7026R3 | R16: /
A17: 王辉光 | B17: 开发 | C17: 嘲风 | D17: 定制项目 | E17: 定制项目 | F17: 7028 | G17: 7028 | H17: 7028 | I17: 7028 | J17: 7028 | K17: 预研 | L17: 7026R3 | M17: 7026R3 | N17: 7026R3 | O17: 7026R3 | P17: 排障能力 | Q17: 7026R3/抓包 | R17: / | V17: mac漂移补丁
A18: 彭文奕 | B18: 开发 | C18: 嘲风 | D18: 7027 | E18: 定制项目 | F18: 定制项目 | G18: 7028 | H18: 7028 | I18: 7028 | J18: 7028 | K18: 快速响应/ 质量 | L18: 快速响应/ 定制 | M18: 7026R3 | N18: 7026R3 | O18: 7026R3 | P18: 扩容/API | Q18: 7026R3/BUG | R18: /
A19: 叶鹏 | B19: 开发 | C19: 嘲风 | D19: 7027 | E19: 预研 | F19: 预研 | G19: 预研 | H19: 预研 | I19: 预研 | J19: 预研 | K19: 预研 | L19: 预研 | M19: 预研 | N19: 预研 | O19: 预研 | P19: 扩容/大项目 | Q19: 平安中信 | R19: / | V19: 招行POC
A20: 金红星 | B20: 开发 | C20: 嘲风 | D20: 定制项目 | E20: 定制项目 | F20: 定制项目 | G20: 快速响应/ 定制 | H20: 快速响应/ 定制 | I20: 快速响应/ 定制 | J20: 快速响应/ 定制 | K20: 快速响应/ 定制 | L20: 快速响应/ 定制 | M20: 快速响应/ 定制 | N20: 快速响应/ 定制 | O20: 快速响应/ 定制 | P20: GSLB | Q20: 安全/农行GLSB入围 | R20: / | V20: 安全/补丁
A21: 熊锐 | B21: 开发 | C21: 嘲风 | D21: 定制项目 | E21: 7027 | F21: 质量/安全 | G21: 快速响应/ 质量 | H21: 快速响应/ 质量 | I21: 快速响应/ 质量 | J21: 快速响应/ 质量 | K21: 快速响应/ 质量 | L21: 快速响应/ 质量 | M21: / | N21: / | O21: / | P21: 监视器/授权 | Q21: 护网/补丁/质量 /7026R3 | R21: / | S21: 快速响应团队
A22: 郑嘉颖 | B22: 测试 | C22: 嘲风 | D22: 7027 | E22: 7027 | F22: 定制/补丁 | G22: 快速响应/ 质量 | H22: 7028 | I22: 7028 | J22: 7028 | K22: 7028 | L22: 7026R3 | M22: 7026R3 | N22: 7026R3 | O22: 7026R3 | Q22: 7026R3 | R22: / | S22: / | V22: 1
A23: 杨乐w | B23: 测试 | C23: 嘲风 | L23: 快速响应/ 定制 | M23: 快速响应/ 定制 | N23: 快速响应/ 定制 | O23: 快速响应/ 定制 | Q23: 7026R3
A24: 唐柴袁 | B24: lizhi | C24: 嘲风 | D24: 质量补丁 | E24: 质量补丁 | F24: 定制/补丁 | G24: 快速响应/ 质量 | H24: 7028 | I24: 7028 | J24: 7028 | K24: 7028 | L24: / | M24: / | N24: / | O24: / | Q24: 728 | R24: lizhi
A25: 何伟 | B25: 开发 | C25: 嘲风 | I25: / | J25: / | K25: 快速响应/ 定制 | L25: 7026R3 | M25: 7026R3 | N25: 7026R3 | O25: 7026R3 | Q25: 7026R3/RAS | R25: /
A26: 曾泽铭w | B26: 开发 | C26: 嘲风 | D26: / | E26: / | F26: / | G26: / | H26: 快速响应/ 质量 | I26: 快速响应/ 质量 | J26: 快速响应/ 质量 | K26: 快速响应/ 定制 | L26: 7026R3 | M26: 7026R3 | N26: 7026R3 | O26: 7026R3 | P26: 硬件巡检 | Q26: 7026R3/离线巡检 | R26: /
A27: 李林林 | B27: 开发 | C27: 盘古 | D27: 7027 | E27: 7028 | F27: 定制项目 | G27: 7028 | H27: 7028 | I27: 7028 | J27: 7028 | K27: 7029 | L27: 7026R3 | M27: 7026R3 | N27: 7026R3 | O27: 7026R3 | P27: irule/F5默认参数 | Q27: 7026R3 | R27: /
A28: 田勤善 | B28: 开发 | C28: 盘古 | D28: 7027 | E28: 7027 | F28: 质量/补丁 | G28: 7028 | H28: 7028 | I28: 7028 | J28: 7028 | K28: 快速响应/ 定制 | L28: 7028 | M28: 云AD | N28: 云AD | O28: 云AD | P28: 低延时 | Q28: 7028 BUG | R28: /
A29: 郝春宇 | B29: 开发 | C29: 盘古 | D29: 定制项目 | E29: 质量/效能 | F29: 质量/效能 | G29: 快速响应/ 质量 | H29: 快速响应/ 质量 | I29: 快速响应/ 质量 | J29: 快速响应/ 质量 | K29: 快速响应/ 质量 | L29: 快速响应/ 质量 | M29: 快速响应/ 质量 | N29: 快速响应/ 质量 | O29: 快速响应/ 质量 | P29: 补丁自动化 | Q29: 效能自动化 | R29: /
A30: 何泳江 | B30: 开发 | C30: 盘古 | D30: 7027 | E30: 7028 | F30: 质量 | G30: 7028 | H30: 7028 | I30: 7028 | J30: 7028 | K30: 7028 | L30: 7026R3 | M30: 7026R3 | N30: 7026R3 | O30: 7026R3 | P30: sslo | Q30: 7026R3/TOA | R30: / | V30: 农行卸载
A31: 左乾江 | B31: 开发 | C31: 盘古 | D31: 7027 | E31: 7028 | F31: 定制项目 | G31: 7028 | H31: 7028 | I31: 7028 | J31: 7028 | K31: 7028 | L31: 7026R3 | M31: 7026R3 | N31: 7026R3 | O31: 7026R3 | P31: 配置转换 | Q31: 7026R3/集群手动同步 | R31: /
A32: 蒋品局 | B32: lizhi | C32: 盘古 | D32: 7027 | E32: 7028 | F32: 7028 | G32: 7028 | H32: 7028 | I32: 7028 | J32: / | K32: / | L32: / | M32: / | N32: / | O32: / | P32: 运维能力工具包 | Q32: 离线巡检 | R32: /
A33: 王鸿奇 | B33: 开发 | C33: 盘古 | D33: 7027 | E33: 定制项目 | F33: 定制项目 | G33: 7028 | H33: 快速响应/ 7026R3 | I33: 快速响应/ 定制 | J33: 快速响应/ 7026R3 | K33: 快速响应/ 7026R3 | L33: 云AD | M33: 云AD | N33: 云AD | O33: 云AD | P33: SSL七层/定制 | Q33: 云AD | R33: /
A34: 沈涛w（离职） | B34: 开发 | C34: 盘古 | L34: 7026R3 | M34: 7026R3 | N34: 7026R3 | O34: \ | Q34: 7026R3/BUG | R34: /
A35: 郑奇高 | B35: 测试 | C35: 盘古 | D35: 7027 | E35: 7028 | F35: 定制/补丁 | G35: 7028 | H35: 7028 | I35: 7028 | J35: 7028 | K35: 7028 | L35: 7026R3 | M35: 7026R3 | N35: 7026R3 | O35: 7026R3 | Q35: 7026R3 | R35: / | V35: 1
A36: 吴霖彬 | B36: 测试 | C36: 盘古 | D36: 定制项目 | E36: 质量补丁 | F36: 定制/补丁 | G36: 快速响应/ 定制 | H36: 快速响应/ 定制 | I36: 快速响应/ 定制 | J36: 快速响应/ 定制 | K36: 快速响应/ 定制 | L36: 快速响应/ 定制 | M36: 快速响应/ 定制 | N36: 快速响应/ 定制 | O36: 快速响应/ 定制 | Q36: 质量补丁/定制 | R36: /
A37: 肖志鹏 | B37: 开发 | C37: 盘古 | D37: 7027 | E37: 定制项目 | F37: 定制项目 | G37: 快速响应/ 7026R2英 | H37: 快速响应/ 7026R2英 | K37: 快速响应/ 定制 | L37: 7026R3 | M37: 7026R3 | N37: 7026R3 | O37: 7026R3 | Q37: 7026R3/硬件导入 | R37: / | V37: 农行卸载
A38: 刘亚 | B38: 测试 | C38: 效能质量团队 | D38: 7027 | E38: 7027 | F38: 7027 | G38: 7028 | H38: 7028 | I38: 7028 | J38: 7028 | K38: 7028 | L38: 快速响应/ 定制 | M38: 快速响应/ 定制 | N38: 快速响应/ 定制 | O38: 快速响应/ 定制 | Q38: 质量补丁/定制 | R38: /
A39: 臧韵琦 | B39: 测试 | C39: 效能质量团队 | D39: 管理 | E39: 管理 | F39: 管理 | G39: 管理 | H39: 管理 | I39: 管理 | J39: 管理 | K39: 管理 | L39: 管理 | M39: 管理 | N39: 管理 | O39: 管理 | Q39: 管理 | R39: /
A40: 周黎利 | B40: 开发 | C40: 系统架构组 | D40: 预研 | E40: 预研 | F40: 预研 | G40: 预研 | H40: 预研 | I40: 预研 | J40: 预研 | K40: 预研 | L40: 预研 | M40: 预研 | N40: 预研 | O40: 预研 | P40: 配置扩容 | Q40: 预研 | R40: /
A41: 李洪懋 | B41: 开发 | C41: 系统架构组 | D41: 7028 | E41: 7028 | F41: 定制项目 | G41: 7028 | H41: 快速响应/ 7026R3 | I41: 7028 | J41: 7028 | K41: 快速响应/ 7026R3 | L41: 预研 | M41: 预研 | N41: 预研 | O41: 预研 | P41: ssl | Q41: 预研 | R41: /
...

Sheet AD人力甘特图（2023）
A1: 整体人力甘特图
A3: 团队人力 | D3: 2023年
A4: 姓名 | B4: 岗位 | C4: 团队代号 | D4: 6月 | E4: 7月 | F4: 8月 | G4: 9月 | H4: 10月 | I4: 11月（中） | J4: 11月底 | K4: 12月
A5: 吴广华 | B5: 开发 | C5: 白泽 | D5: 7027 | E5: 7027 | F5: 7027 | G5: 7027 | H5: 7027 | I5: 7027 | J5: 7027 | K5: 7027 | L5: 集群手动同步/ras
A6: 张祺 | B6: 开发 | C6: 白泽 | D6: 7027 | E6: 定制项目 | F6: 定制项目 | G6: 7028 | H6: 7027 | I6: 7027 | J6: 7027 | K6: 定制项目 | L6: 真实场景流量/排障 | M6: 浪潮问题
A7: 刘文龙 | B7: 开发 | C7: 白泽 | D7: 7027 | E7: 7027 | F7: 7027 | G7: 7027 | H7: 7027 | I7: 7027 | J7: 7027 | K7: 定制项目 | L7: ras/机动人员 | M7: 移动定制 | P7: HW
A8: 郑嘉颖 | B8: 测试 | C8: 白泽 | D8: 7027 | E8: 7027 | F8: 7027 | G8: 7027 | H8: 7027 | I8: 7027 | J8: 7027 | K8: 定制项目 | M8: 建行
A9: 曹刚 | B9: 测试 | C9: 白泽 | D9: 7027 | E9: 定制项目 | F9: 定制项目 | G9: 7027 | H9: 7027 | I9: 7027 | J9: 7027 | K9: 定制项目 | M9: 移动定制
A10: 雷斌亭 | B10: 开发 | C10: coredump组 | D10: 7027 | E10: 7027 | F10: 7027 | G10: 7027 | H10: 7027 | I10: 7027 | J10: 预研 | K10: 预研 | L10: 半链接/排障能力/大项目
A11: 樊晗生 | B11: 开发 | C11: coredump组 | D11: 7027 | E11: 7027 | F11: 7027 | G11: 7027 | H11: 7027 | I11: 定制项目 | J11: 7027 | K11: 7027 | L11: 吉大key/动态路由稳定/大项目 | P11: HW
A12: 高光毫 | B12: 开发 | C12: coredump组 | D12: 7028 | E12: 7028 | F12: 7027 | G12: 定制项目 | H12: 7027 | I12: 定制项目 | J12: 定制项目 | K12: 7027 | L12: 低延时
A13: 王鸿奇 | B13: 开发 | C13: coredump组 | G13: 7028 | H13: 7028 | I13: 定制项目 | J13: 定制项目 | K13: 7028 | L13: 三级国密/定制 | M13: 农行-Irule
A14: 郑泳 | B14: 开发 | C14: coredump组 | D14: 定制项目 | E14: 定制项目 | F14: 定制项目 | G14: 定制项目 | H14: 定制项目 | I14: 定制项目 | J14: 定制项目 | K14: 定制项目 | L14: cnad | M14: 定制-广发CNAD | O14: 定制进行ing
A15: 王文强 | B15: 开发 | C15: coredump组 | D15: 7028 | E15: 质量补丁 | F15: 7027 | G15: 7028 | H15: 7027 | I15: 7027 | J15: 7028 | K15: 7027 | L15: 真实场景流量/硬件排障/机动 | M15: 性能问题
A16: 徐瑞准 | B16: 开发 | C16: coredump组 | D16: 7027 | E16: 7027 | F16: 7027 | G16: 定制项目 | H16: 7027 | I16: 定制项目 | J16: 7027 | K16: 定制项目 | L16: jszc | M16: 定制-兴业扩+曙光 | O16: 定制进行ing
A17: 刘都都 | B17: 开发 | C17: coredump组 | D17: 7027 | E17: 7027 | F17: 7027 | G17: 7027 | H17: 7027 | I17: 7027 | J17: 7027 | K17: 7027 | L17: 过载/HA/定制 | M17: dpdk
A18: 张新锐 | B18: 开发 | C18: coredump组 | D18: 7027 | E18: 7027 | F18: 7027 | G18: 7027 | H18: 7027 | I18: 定制项目 | J18: 定制项目 | K18: 定制项目 | L18: 半链接/机动人员 | M18: 建行 | P18: HW
A19: 方子健 | B19: 开发 | C19: coredump组 | D19: 7027 | E19: 7027 | F19: 7027 | G19: 7027 | H19: 7027 | I19: 7027 | J19: 7027 | K19: 7027 | L19: 1 | M19: 交行R7（硬件导入3系适配） | P19: HW
A20: 薛载路 | B20: 测试 | C20: coredump组 | D20: 7027 | E20: 7027 | F20: 7027 | G20: 7027 | H20: 7027 | I20: 7027 | J20: 7027 | K20: 定制项目 | M20: 农行POC
A21: 苏敏宁 | B21: 开发 | C21: 嘲风 | D21: 定制项目 | E21: 定制项目 | F21: 7028 | G21: 7028 | H21: 7026R2 | I21: 7026R2 | J21: 预研 | K21: 预研 | L21: snmp/syslog/PM | P21: HW
A22: 王辉光 | B22: 开发 | C22: 嘲风 | D22: 定制项目 | E22: 定制项目 | F22: 定制项目 | G22: 7027 | H22: 7027 | I22: 定制项目 | J22: 定制项目 | K22: 定制项目 | L22: 排障能力 | M22: 农行irule | P22: HW
A23: 彭文奕 | B23: 开发 | C23: 嘲风 | D23: 7028 | E23: 7028 | F23: 7027 | G23: 7027 | H23: 7027 | I23: 定制项目 | J23: 定制项目 | K23: 7027 | L23: 扩容/大项目 | P23: HW
A24: 叶鹏 | B24: 开发 | C24: 嘲风 | D24: 7028 | E24: 7027 | F24: 7027 | G24: 7027 | H24: 7028 | I24: 7028 | J24: 7028 | K24: 7028 | L24: 扩容 | M24: 补丁自动化 | P24: HW
A25: 金红星 | B25: 开发 | C25: 嘲风 | D25: 7027 | E25: 7027 | F25: 7027 | G25: 7027 | H25: 7027 | I25: 定制项目 | J25: 定制项目 | K25: 定制项目 | L25: gslb | M25: 农行-GSLB-同步 | P25: HW
A26: 唐柴袁 | B26: 测试 | C26: 嘲风 | D26: 质量补丁 | E26: 质量补丁 | F26: 质量补丁 | G26: 质量补丁 | H26: 质量补丁 | I26: 质量补丁 | J26: 质量补丁 | K26: 定制项目 | M26: 农行POC
A27: 叶佳卉 | B27: 测试 | C27: 嘲风 | D27: 定制项目 | E27: 定制项目 | F27: 7026R2 | G27: 定制项目 | H27: 定制项目 | I27: / | J27: / | K27: /
A28: 方鹏斌 | B28: 开发 | C28: 盘古 | D28: 7027 | E28: 7027 | F28: 7028 | G28: 7028 | H28: 定制项目 | I28: 定制项目 | J28: 7028 | K28: 预研 | L28: 兼容报告 | N28: 定制-国网SSLo | O28: 定制进行ing
A29: 李林林 | B29: 开发 | C29: 盘古 | D29: 7027 | E29: 7027 | F29: 7027 | G29: 7027 | H29: 7027 | I29: 定制项目 | J29: 定制项目 | K29: 定制项目 | L29: 七层性能优化 | M29: 农行-irule
A30: 田勤善 | B30: 开发 | C30: 盘古 | D30: 7027 | E30: 7027 | F30: 7027 | G30: 7027 | H30: 7027 | I30: 7027 | J30: 7027 | K30: 7027 | L30: irule/配置扩容
A31: 郝春宇 | B31: 开发 | C31: 盘古 | D31: 7027 | E31: 7027 | F31: 7027 | G31: 7027 | H31: 7027 | I31: 定制项目 | J31: 定制项目 | K31: 定制项目 | L31: 配置转换 | N31: 定制-国泰CNAD | O31: 定制进行ing
A32: 何泳江 | B32: 开发 | C32: 盘古 | D32: 7027 | E32: 7027 | F32: 定制项目 | G32: 定制项目 | H32: 7027 | I32: 定制项目 | J32: 定制项目 | K32: 7027 | L32: sslo | P32: HW
A33: 左乾江 | B33: 开发 | C33: 盘古 | F33: 定制项目 | G33: 定制项目 | H33: 定制项目 | I33: 定制项目 | J33: 7027 | K33: 定制项目 | L33: 补丁自动化/调度优化 | M33: 河南烟草局定制 | P33: HW
A34: 蒋品局 | B34: 开发 | C34: 盘古 | D34: 定制项目 | E34: 定制项目 | F34: 定制项目 | G34: 定制项目 | H34: 7027 | I34: 定制项目 | J34: 定制项目 | K34: 定制项目 | L34: acheck工具/定制 | M34: 护网 | P34: HW
A35: 郑奇高 | B35: 测试 | C35: 盘古 | D35: 7027 | E35: 7027 | F35: 7027 | G35: 7027 | H35: 7027 | I35: 7027 | J35: 7027 | K35: 定制项目 | M35: SSLO定制
A36: 吴霖彬 | B36: 测试 | C36: 盘古 | D36: 7027 | E36: 7027 | F36: 7027 | G36: 7027 | H36: 7027 | I36: 7027 | J36: 定制项目 | K36: 定制项目 | M36: SSLO定制
A37: 刘亚 | B37: 测试 | C37: 效能质量团队 | D37: 7027 | E37: 7027 | F37: 7027 | G37: 7027 | H37: 7027 | I37: 7027 | J37: 7027 | K37: 7027
A38: 骆俊 | B38: 测试 | C38: 效能质量团队 | D38: 7027 | E38: 7027 | F38: 7027 | G38: 7027 | H38: 7027 | I38: 7027 | J38: 7027 | K38: 定制项目 | M38: 农行
A39: 周黎利 | B39: 开发 | C39: 系统架构组 | D39: 定制项目 | E39: 定制项目 | F39: 预研 | G39: 预研 | H39: 预研 | I39: 定制项目 | J39: 预研 | K39: 预研 | L39: 配置扩容 | M39: 建行
A40: 李洪懋 | B40: 开发 | C40: 系统架构组 | D40: 7028 | E40: 7028 | F40: 7028 | G40: 7028 | H40: 7028 | I40: 7028 | J40: 7028 | K40: 7028 | L40: ssl
A41: 李雪莲 | B41: 开发 | C41: 系统架构组 | D41: 休产假 | E41: 休产假 | F41: 7027 | G41: 7027 | H41: 定制项目 | I41: 定制项目 | J41: 定制项目 | K41: 定制项目 | L41: 1 | M41: 护网 | P41: HW
...

Sheet 项目日历-周
A1: 版本 | B1: 类型 | C1: 优先级 | D1: 当前阶段 | E1: 计划发布 | F1: 01月份 | H1: 02月份 | J1: 03月份 | L1: 04月份 | N1: 05月份 | P1: 06月份 | R1: 07月份 | T1: 08月份 | V1: 09月份 | X1: 10月份 | Z1: 11月份 | AB1: 负责人 | AC1: 项目进展概述 | AD1: 关键风险&路径 | AE1: 举措&跟踪进展
F2: 开发 | G2: 测试 | H2: 开发 | I2: 测试 | J2: 开发 | K2: 测试 | L2: 开发 | M2: 测试 | N2: 开发 | O2: 测试 | P2: 开发 | Q2: 测试 | R2: 开发 | S2: 测试 | T2: 开发 | U2: 测试 | V2: 开发 | W2: 测试 | X2: 开发 | Y2: 测试 | Z2: 开发 | AA2: 测试
A3: AD7.0.26R1 | B3: 正式 | C3: 高 | D3: 已发布 | E3: 5月15日 | F3: 4 | G3: 1 | H3: 2 | I3: 1 | J3: 2 | K3: 1 | L3: 2 | M3: 1 | AB3: 苏敏宁 | AC3: 5月19已正式发布
A4: AD7.0.26R2 | B4: 正式 | C4: 低 | D4: 需求 | E4: 未启动 | F4: 4 | G4: 1 | H4: 2 | I4: 1 | J4: 2 | K4: 1 | L4: 2 | M4: 1 | AB4: 苏敏宁 | AC4: 暂定，待规划 | AD4: 需求阶段，cssp合入，oscp，研华硬件导入
A5: AD7.0.27 | B5: 正式 | C5: 高 | D5: 编码联调 | E5: 08月31 | F5: 4 | G5: 3 | H5: 4 | I5: 3 | J5: 5 | K5: 3 | L5: 2 | M5: 1 | N5: 4 | O5: 3 | P5: 3 | Q5: 3 | R5: 2 | S5: 2 | T5: 1 | U5: 2 | AB5: 吴广华 | AC5: 关键价值： 1、合入Platos1.3系统，工具链+dpdk升级 2、GA410吞吐优化 3、P5000硬件导入、全平台网讯网卡支持 4、ARM新导入平台支持D2000等 | AD5: 详见周报 https://docs.atrust.sangfor.com/pages/viewpage.action?pageId=273336281 | AE5: 同左
B6: 正式 | D6: 编码联调 | E6: 08月31 | F6: 5 | G6: 2 | H6: 2 | I6: 2 | J6: 3 | K6: 2 | L6: 5 | M6: 0 | N6: 2 | O6: 2 | P6: 5 | Q6: 2 | R6: 4 | S6: 2 | T6: 2 | U6: 2 | AB6: 方鹏斌
B7: 正式 | D7: 编码联调 | E7: 08月31 | F7: 4 | G7: 1 | H7: 4 | I7: 0 | J7: 4 | K7: 0 | L7: 5 | M7: 0 | N7: 4 | O7: 1 | P7: 6 | Q7: 1 | R7: 6 | S7: 1 | T7: 4 | U7: 1 | AB7: 雷斌亭
B8: 正式 | D8: 编码联调 | E8: 08月31 | F8: 2 | G8: 0 | H8: 2 | I8: 0 | J8: 2 | K8: 0 | L8: 2 | M8: 0 | N8: 2 | O8: 0 | P8: 2 | Q8: 0 | R8: 2 | S8: 1 | T8: 2 | U8: 1 | AB8: 苏敏宁
A9: AD7.0.28 | B9: 正式 | C9: 中 | D9: 预研 | E9: 待定 | L9: 1 | M9: 0 | N9: 5 | O9: 2 | P9: 5 | Q9: 0 | R9: 5 | S9: 0 | T9: 8 | U9: 1 | V9: 10 | W9: 2 | X9: 10 | Y9: 4 | Z9: 10 | AA9: 4 | AB9: 雷斌亭 | AC9: 关键预研项ssl高性能，API性能优化，网卡检测等 | AD9: 1，计划8月开始立项，目前看研发测的人员到位风险比较大，需求池需求还没投入RAT拆解，特别是信创硬件可靠性 2,国密 ECC-SM4-SM3 算法套件加密方向硬件卸载已调通，目前测出来的国密吞吐性能大于 18Gbps ，相比优化前的 6.6Gbps ，提升了 2 倍以上，此时 P5000 cpu 占用在 50% 出头，并未跑满压力（前端加密设备 cpu 已满）。 | AE9: 1，每周例行7028例会，对齐需求及预研排期风险
A10: 护网补丁/质量补丁 | B10: 补丁 | C10: 高 | D10: / | E10: / | F10: 2 | H10: 2 | I10: 2 | J10: 3 | K10: 2 | L10: 2 | M10: 5 | N10: 2 | O10: 2 | P10: 2 | Q10: 2 | R10: 2 | S10: 1 | T10: 1 | U10: 1 | V10: 1 | W10: 1 | X10: 1 | Y10: 1 | Z10: 1 | AA10: 1 | AB10: 王辉光 | AC10: 重保计划中 质量补丁验收
A11: 定制项目--华为移动入围 | B11: 定制 | C11: 高 | D11: 开发 | E11: 5月15 | H11: 1 | L11: 2 | M11: 1 | R11: 1 | S11: 1 | AB11: 陈红伟 | AC11: 测试进行中，cg和zq出差
A12: 定制项目--东方航空 | B12: 定制 | C12: 高 | D12: 测试 | E12: 7月28 | AB12: 苏敏宁 | AC12: 测试进行中
A13: 定制项目--邮储自动化对接 | B13: 定制
A14: 定制项目--北京PAASAD定制 | B14: 定制
A15: 其他外部POC支撑 | B15: 外部支撑 | C15: 低 | D15: 测试 | E15: \ | P15: 2 | AB15: 臧韵琦
A16: 预研（RAT） | B16: 预研 | C16: 中 | D16: 预研 | F16: 2 | H16: 2 | J16: 2 | L16: 2 | N16: 2 | P16: 1 | R16: 1 | T16: 1 | V16: 1 | X16: 1 | Z16: 1 | AB16: 周黎利 | AD16: 商密国密性能提升优化预研
B17: 预研 | C17: 中 | D17: 预研 | F17: 0 | H17: 0 | J17: 0 | L17: 0 | N17: 2 | P17: 0 | R17: 1 | T17: 1 | V17: 1 | X17: 1 | Z17: 1 | AB17: 雷斌亭
B18: 预研 | C18: 中 | D18: 预研 | F18: 1 | H18: 0 | J18: 0 | L18: 0 | N18: 1 | P18: 0 | R18: 1 | T18: 1 | V18: 1 | X18: 1 | Z18: 1 | AB18: 方鹏斌 | AD18: 盘古： 1、方鹏斌（SSLO二层方案）-7月上旬完成编码自测
B19: 预研 | C19: 中 | D19: 预研 | F19: 1 | H19: 1 | J19: 1 | L19: 1 | N19: 1 | P19: 0 | R19: 1 | T19: 1 | V19: 1 | X19: 1 | Z19: 1 | AB19: 苏敏宁 | AD19: 嘲风： API缓存设计、代码梳理（为后续API性能优化做准备）
B20: 预研 | C20: 中 | D20: 预研 | F20: 1 | H20: 0 | J20: 0 | L20: 0 | N20: 1 | P20: 0 | R20: 1 | T20: 1 | V20: 1 | X20: 1 | Z20: 1 | AB20: 吴广华 | AD20: 白泽： 1、吴广华（集群手动同步方案）--暂停
A21: 管理 | B21: 管理 | F21: 2 | H21: 2 | J21: 2 | L21: 2 | N21: 2 | P21: 2 | R21: 2 | T21: 2 | V21: 2 | X21: 2 | Z21: 2 | AB21: 陆树军
A22: UI | B22: UI | F22: 1 | H22: 1 | J22: 1 | L22: 1 | N22: 1 | P22: 1 | R22: 1 | T22: 1 | V22: 1 | X22: 1 | Z22: 1 | AB22: 陈浩林
A23: 技术支持 | B23: 技术支持 | F23: 3 | H23: 3 | J23: 3 | L23: 3 | N23: 3 | P23: 3 | R23: 3 | T23: 3 | V23: 3 | X23: 3 | Z23: 3 | AB23: 王超杰
A24: 效能质量组 | B24: 效能 | G24: 2 | I24: 2 | K24: 2 | M24: 2 | O24: 2 | Q24: 2 | S24: 2 | U24: 2 | W24: 2 | Y24: 2 | AA24: 2 | AB24: 臧韵琦 | AD24: 1、用例责任田制度落地的统计功能进展滞后 2、外置设备构建自动化效率问题 3、升级流水线在部分版本会出现后台无法启用的问题 | AE24: 1、保证人力投入 2、梳理记录问题解决 3、解决bug
A25: 计划人力 | F25: ==SUM(F3:F24) -> 36 | G25: ==SUM(G3:G24) -> 10 | H25: ==SUM(H3:H24) -> 28 | I25: ==SUM(I3:I24) -> 11 | J25: ==SUM(J3:J24) -> 30 | K25: ==SUM(K3:K24) -> 11 | L25: ==SUM(L3:L24) -> 32 | M25: ==SUM(M3:M24) -> 11 | ... AA25: ==SUM(AA3:AA24) -> 7
A26: 当前人力 | F26: 35 | G26: 11 | H26: 34 | I26: 10 | J26: 34 | K26: 10 | L26: 34 | M26: 10 | N26: 34 | O26: 10 | P26: 33 | Q26: 10 | R26: 33 | S26: 10 | T26: 33 | U26: 10 | V26: 33 | W26: 10 | X26: 33 | Y26: 10 | Z26: 33 | AA26: 10
A27: 人员缺口 | F27: ==F26-F25 -> -1 | G27: ==G26-G25 -> 1 | H27: ==H26-H25 -> 6 | I27: ==I26-I25 -> -1 | J27: ==J26-J25 -> 4 | K27: ==K26-K25 -> -1 | L27: ==L26-L25 -> 2 | M27: ==M26-M25 -> -1 | ... AA27: ==AA26-AA25 -> 3

Sheet 快速响应资源池
A1: 产线现状 | B1: 按工作类型划分，主要是分为【主线版本】, 【 大项目/定制/质量版/外部支撑】 2大类工作； 按团队划分，主要是分为三个特新团队,3个TL分别管理10人的团队 存在问题: 1，2类工作由于不同时期投入优先级不一样，后者往往会抢占主线版本的人力，从去年7027的抽调影响可见非常大；2023年统计2类问题平均占比编制9人，最高峰时期如工行POC入围几乎全部门投入 2，人力抽调的策略无事前规划（看到谁技术强就抽谁，工作安排也较少考虑人才备份培养），人员工作相互切换成本高，人员感知不好，承诺的时间更变频繁，工作积极性受一定影响，主线项目管理难度较大，进度延期较多 3，以前也有快速响应团队和外包团队，隔离主线版本人力，有一定效果。但管理上需要一个兼职PM，圈定为此团队组员的氛围不佳，技术成长受限，离职率较高； 3，自从22年变革调整为TL 特性团队后，再无定制团队或快速响应团队，但从产线发展阶段现状，非主线版本工作内容有增无减少，而版本规划特性又集中在某些价值领域并非完全按特性责任田区分隔离，团队组员之间工作调动交叉也较多，对TL和PM的管理提出较大挑战 好的方面 1，40人力编制，3个TL分别管理10人的团队，大PM和TL的管理工作也相对合适 2，特性团队相对独立的快速响应团队有优势，强调onetrack和开发高质量要求，凝聚力,技术工作氛围和员工归属感较强 3，团队的精英化和组织结构简单文化
A2: 期望目标 | B2: 对当前组织架构适当优化，有相对的人力资源隔离，有分层的人力抽调策略决策依据，减少沟通协作成本，使事务及人力效率运作最大化；
A3: 向外看 | B3: 绝大多数产线都有定制和快速响应团队，拿AF,AC此类网关类产品做了对比，AC还有独立的外包团队（10人左右，但他们做的定制要求标准等相对AD没这么高），基本上都是对2类工作做了资源隔离，专人专事等；但AD主攻KA，针对大部分2类工作的能力和质量要求都较高，其他产线的组织架构不一定的借鉴意义； 产品的架构决定了组织结构，当前敏捷的特性团队划分实际上并没有很好解决责任田和人效问题
A4: 思路 | B4: 1， 建立虚拟的快速响应团队人力资源池，按半年版本规划情况流动，相对固定（季度），名单由我们共同定期维护(不传递给组员+结合人才培养计划) 人员投入分布，质量版本 3人，定制 3人，外部支撑 3~4人（含合作方） 2，PM/TL从2类需求池（定制/质量/外部事项）中按高到低优先级选择分发组员；开发工作默认情况下按主线版本特性上车合入主线(传递时注意，工作按主干开发标准的高要求，而非杂事琐事) 3，无新的需求承接时，人员切回主线版本新特性拆解/修复遗留问题等工作任务，不承接版本关键路径工作（占比10~20%左右） 4，紧急事项抽调分层策略，快速响应团队人力->预研人力->主版本人力，允许特事特办

Sheet 主线版本
A1: 产线 | B1: 方向 | C1: 版本号 | D1: 关键价值 | E1: 项目里程碑计划 | F1: 变更 | G1: 整体进展概述 | H1: 关键风险和举措 | I1: 责任人 | J1: 预研项和进展 | K1: BP解码进展 | L1: DCP2价值立项进展 | M1: TR3进展 | N1: DCP3项目计划进展 | O1: TR5-A进展 | P1: TR6进展 | Q1: DCP4 Beta发布进展 | R1: DCP5 上市进展 | S1: DCP6 默认发货进展
A2: 应用交付产品研发部 | C2: AD7.0.27 | D2: 一、保硬件供应 1、网讯网卡支持 2、P5000国密网关型号导入 二、性价比和硬件质量提升 1、自研FT D2000 8核平台导入 2、FT2000 4核平台导入（1500a停产） 3、SSL新建/吞吐性能优化（国密/非国密） 4、GA410吞吐优化和延时优化 三、客户交付和POC 1、工商银行P5000平台适配及剩余功能主线化： 2、建设银行POC运维相关功能补齐 四、合入Platos1.3系统 1、合入平台部Platos1.3系统，建设通用的硬件导入、自主国产化的系统能力（工具链升级、dpdk升级） | E2: DCP过点的里程碑计划 DCP2（价值立项）：2022.12.09 DCP3(计划决策)：2023.2.16 DCP4（预发布）：2023.11.17 DCP5（小批量上市）：2023.12.30 DCP6（正式上市）：2024.1.30 新增需求/护网/入围大项目等影响：变更电子流 DCP4（预发布）：2024.02.29 宕机问题影响估计DCP4（预发布）：2024.03.29 | F2: 变更至2月29 https://itsm.atrust.sangfor.com/#/ticket/detail?id=64544&from=myCreatedTicket&project_id=0 https://itsm.atrust.sangfor.com/itsm/#/ticket/detail?id=74220 | G2: 1、 项目当前进展： 已经dcp4-beta发布 2、关键价值进展：新功能价值基本已完成测试及收敛，无风险； 3、关键质量保障：beta计划的执行 4、 跨部门协作项：无 5、变更：已走2次变更 6、人员投入：开发(16人)、测试(5人)；人员投入抽调较多，新增需求/护网/入围大项目等影响 | H2: 【跨部门协作】 在beta开局期间，需导入新硬件平台研华P5000、兆芯），可能存在质量和进度风险。 -举措： 1、出补丁支持新硬件型号； 2、与项目管理部和测试中心提前备案，申请延长beta周期 | I2: 产线：陆树军 | J2: 2023年已完成（NA） | K2: 2023年已完成（NA） | L2: 2023年已完成（NA） | M2: 2023年已完成（NA） | N2: 2023年已完成（NA） | O2: 完成 已组织评审；IPD电子流已走完 | P2: 完成 | Q2: 完成（4.28） | R2: 进行中
C3: AD7.0.28（战略） | D3: [F5替换] 1、F5默认参数对齐 2、F5配置转换工具优化，扩大F5版本等 3、F5 irules兼容支持[HTTP类和TCP类] 4、相关对比报告输出(F5和友商) 5、低时延，大容量(3w) [运维体验对齐]-KA 24小时排障，90%的问题一次性信息获取，向前覆盖708R和7026R 1、黑盒优化和离线巡检，对齐F5 2、设备强制offline 3、命令行简化，对齐F5 4、光衰统计等 5、SNAT端口使用率预警，对齐F5 6、太平等客户共性运维诉求_抓包优化对齐F5 [性能优化] 1、SSL吞吐性能提升 2、国密性能提升 [稳定性可视] 1、故障隔离(ECC内存、PCIE和网卡故障、硬盘) 2、硬件组件监控完善（RAS） [信创增强] 1、研华兆芯6780A 2、研华5/7系 [SSLO优化] 1、SSLO二层接入 [VAD标准化] 1、X86和arm版本 //需要和HCI对接 | E3: DCP2（价值立项）：2024.04.07 DCP3(计划决策)：2024.04.30 DCP4（预发布）：2024.07.15 DCP5（小批量上市）：2024.09.15 预计： DCP3(计划决策)：2024.5.15 | F3: 无 | G3: 1、 项目当前进展：已完成DCP2立项，当前系统需求&设计阶段TR2~TR3，DCP3计划在5-15完成； 2、关键价值进展：系统需求拆解中 3、关键质量保障：版本缺陷预防计划制定及评审 4、 跨部门协作项：已完成跨部门需求基线握手，并且在立项前完成流程研讨达成共识 5、变更：无变更 6、人员投入：开发(10人)、测试(2人) | H3: 【进度风险】 部分关键模块人员投入晚，拆解+缺陷预防工作量估算偏差以及人员抽调，可能影响到28项目计划调整。 -举措：核心模块的需求拆解完成后，根据实际工作量估算，再上平台梳理计划，并与BG及立项团队沟通。 【技术/质量风险】 SSL性能优化模块，转测较晚，目前估算要到6.10号左右转测，且质量风险比较大。 -措施：和BG对齐需求基线，梳理模块剩余工作量以及改动列表，制定详细缺陷预防计划，架构师重点参与，测试人员提前介入等措施保证模块质量 | I3: 产线：陆树军 | J3: 1、SSL高性能（国密&商密）已完成预研； 部分信创国密信号的商密和国密吞吐，距离农行POC要求有一定差距，是否合入非信创已有的性能优化价值先在7028推出（BG还在决策） 2、SSLO二层已完成预研 3、低时延已完成预研 4、大容量及F5兼容报告这2个需求在28版本不承诺，所对应的预研项尚未完成 | K3: 2023年已完成（NA） | L3: 已完成 4-7号下午线下立项评审通过 | M3: 进行中 | N3: 进行中

Sheet 责任田分析
A1: 团队-TL | B1: 责任田 | C1: 维度 | D1: 维度细分 | E1: 当前现状 | F1: 下一步举措
A2: 样例 | F2: 【技术债】 1，针对TOP核心场景技术债务问题，每月度持续运营，RMT决策输出到版本规划侧； 【效率】 1，增加排障手段和日志？模块微重构？ 2，落入acheck巡检工具？ 【人才厚度】 1，针对核心模块，人员有双备份（拉通部门层面资源）；非关键模块（未圈定在年度规划或者非涉及关键质量问题模块可不过多投入） 2，通过线上问题实战演练，安排组员通过网上问题的排障，锻炼对外能力，识别排障效率问题做到自闭环； 【客户满意度】 1，联合技术支持，外部质量问题月度运营，针对TOP模块的P1P2关键问题进行复盘活动，识别影响客户满意度的因素（包括排障效率，日志信息，模块遗留bug等） 2，
A3: 架构平台-王奕贤 | B3: 堆叠管理 框架构：DTM、DM、帧通路、knet ovsdb架构管理 arp、mac管理同步 wns-nsl适配层 带外管理 协议帧管理 mlag 聚合、负载 高可用 等 | C3: 客户满意度 | D3: 质量/SLA/根查率
D4: 客户问题反馈
C5: 效率
C6: 团队 | D6: 人才厚度、梯度
A7: 无损网络-向健鹏 | B7: ECN/PFC 超融合场景交付 roce性能优化 超融合组网价值融合 | C7: 客户满意度 | D7: 质量/SLA/根查率
D8: 价值体验
C9: 效率 | D9: 代码复杂度
D10: 自动化率（2.5） <20% 1-2 <40% 3-4 <60% 5-6 <80% 7-8 <100% 9-10
D11: 问题修复效率/排障效率（8） (2-5]天：9-10分 (5-8]天：7-8分 (8-11]天：5-6分 (11-15]天：3-4分 (15-20]天：1-2分
C12: 团队 | D12: 人才厚度、梯度（6）
A13: 芯片/sdk-彭雨林 | B13: acl 端口 以太网管理所有功能 缓存管理 芯片流水线线管 sdk | C13: 客户满意度 | D13: 外部问题反馈
D14: 质量/SLA/根查率
C16: 效率 | D16: 代码复杂度
D17: 可测试性
D18: TD修复效率
C19: 团队 | D19: 人才厚度、梯度
A20: 业务/协议-何海坤 | B20: L2/L3所有网络协议 认证类 感知类功能 安全类功能 瘦架构管理 等 | C20: 客户满意度 | D20: 外部问题反馈
D21: 质量/SLA/根查率
C23: 效率 | D23: 代码复杂度
D24: 可测试性
D25: TD修复效率
C26: 团队 | D26: 人才厚度、梯度

Sheet 业务投资地图(2024H2)
A1: 业务投资分解 | J1: 人力分布 | P1: 目标客户
A2: 类型 | B2: 上半年总投/人天 | C2: 目标投入 | D2: 业务方向 | E2: 开发目标投入 | F2: 子方向 | G2: 开发 | H2: TL | I2: 测试 | J2: 开发 | K2: Q3 | L2: Q4 | M2: 测试 | N2: Q3 | O2: Q4 | P2: 1，7028：默认配置，RAS，sslo二层，配置转换工具 - -8月
A3: AD7.0.26R3 | D3: 长稳版本迭代 | E3: ==SUM(G3:G15) -> 9 | F3: 农行特性 | G3: 1 | H3: 0 | I3: 5 | J3: 苏敏宁 | K3: 1 | L3: 1 | P3: 农行负载/卸载特性9月 中行行负载/卸载，国密三级等 中信POC入围（8月中） 周期：8~10月； 投入开发10人，测试5人
F4: 中行/中信特性 | G4: 1 | H4: 0 | J4: 李林林 | K4: 1 | L4: 1 | M4: 郑奇高 | N4: 1 | O4: 1 | T4: 1
F5: irules兼容 | G5: 1 | H5: 0 | J5: 何伟 | K5: 1 | L5: 1 | M5: 郑嘉颖 | N5: 1 | O5: 1 | T5: 1
G6: 1 | H6: 0 | J6: 张新锐 | K6: 1 | L6: 1 | M6: 吴霖彬 | N6: 1 | O6: 1 | T6: 1
G7: 1 | H7: 0 | J7: 何泳江 | K7: 1 | L7: 1 | M7: 薛载路 | N7: 1 | O7: 1 | T7: 1
G8: 1 | H8: 0 | J8: 樊晗生 | K8: 1 | L8: 1 | M8: 曹刚 | N8: 1 | O8: 1 | T8: 7028
G9: 1 | H9: 0 | J9: 左乾江 | K9: 1 | L9: 1 | M9: 刘思远 | N9: 1 | O9: 1 | T9: 1
G10: 1 | H10: 0 | J10: 彭文奕 | K10: 1 | L10: 1 | T10: 待定
H11: 0 | J11: 田勤善 | K11: 1 | T11: 待定
F12: 集群手动同步 | G12: 1 | H12: 0 | J12: 吴广华 | K12: 1 | L12: 1 | T12: 1
F13: 低时延合入 | H13: 0 | J13: 肖志鹏(临时) | P13: 何泳江 | T13: 1
F14: F5预研落地 | H14: 0 | J14: 曾泽铭w(临时) | P14: 豪哥&张新锐 | T14: 1
F15: 手动抓包 | H15: 0
A16: 长期投入& 核心竞争力 | D16: 物理AD 技术预研 友商分析 | E16: 7 | F16: C3000优化版导入 | G16: 1 | H16: 0 | J16: 张琪 | K16: 1 | L16: 1 | P16: AD7.0.29
F17: FPGA导入 | G17: 1 | H17: 0 | J17: 刘都都 | K17: 1 | L17: 1 | P17: AD7.0.29
F18: F5预研落地 | P18: AD7.0.26R3
F19: 七层性能优化/IPRO优化 | G19: 1 | H19: 0 | J19: 高光毫 | K19: 1 | L19: 1 | P19: 部分
F20: 量子加密场景 | P20: AD7.0.29，lhm
F21: 配置扩容 | G21: 1 | H21: 0 | J21: 叶鹏 | K21: 1 | L21: 1 | P21: 定制;pwy释放到版本
F22: 抓包/客户流量异常场景的自证 | G22: 1 | H22: 0 | J22: 王辉光 | K22: 1 | L22: 1
F23: SSL性能优化 | G23: 1 | H23: 0 | J23: 李洪懋 | K23: 1 | L23: 1
F24: SSLO七层反代
F25: 集群手动同步 | G25: 0 | H25: 0 | P25: AD7.0.26R3
F26: 排障工具的继续开发 | G26: 0 | H26: 0 | P26: 技术支持团队
D27: 云化AD 新控制面架构VAD,PASSAD,CNAD | E27: 5 | F27: 标准化容器云接入场景方案 | G27: 1 | H27: 0 | J27: 郑泳 | K27: 1 | L27: 1
G28: 1 | H28: 0 | J28: 王鸿奇 | K28: 1 | L28: 1
G29: 1 | H29: 0 | J29: 田勤善 | K29: 0 | L29: 1
F30: 控制面新架构 | G30: 1 | H30: 0 | J30: 雷斌亭 | K30: 1 | L30: 1
F31: 数据面新架构 | G31: 1 | H31: 0 | J31: 周黎利 | K31: 1 | L31: 1
A32: 公共支撑 | D32: 大项目支撑 质量运营(安全/工具/硬件巡检/效能) | E32: 5 | F32: KA大项目支撑 | G32: 1 | H32: 0 | I32: 1 | J32: 金红星 | K32: 1 | L32: 1 | M32: 杨乐w | N32: 1 | O32: 1 | P32: 正在投入 中国移动入围华为鲲鹏适配（2024.6） 移动POC入围（8月中下旬标前） 邮储定制（7月底），应急管理部定制（7月底） 待投入 中信POC入围（8月中） 农行负载发货（9月10号）农行卸载测试（9月测试）--irule 中国银行负载和卸载，预计Q3，想有个项目型，后面有框架入围 交通银行（预计11月） 兴业银行框架标(扩容) 工行卸载
G33: 1 | H33: 0 | J33: 肖志鹏 | K33: 1 | L33: 1
H34: 0 | J34: 沈涛 | K34: 1 | L34: 1
H35: 0
F36: 质量运营(安全/工具/硬件巡检/效能 | G36: 1 | H36: 0 | I36: 1 | J36: 熊锐 | K36: 1 | L36: / | M36: 刘亚 | N36: 1 | O36: 1 | P36: 1，护网安全，SP护网补丁 0.5人 2，质量运营，SP质量补丁，硬件变更，acheck巡检/软硬件巡检能力（长期） 2人 3，效能，平台工具，0.5人
G37: 1 | H37: 0 | J37: 曾泽铭w | K37: 1 | L37: 1
G38: 1 | H38: 0 | J38: 郝春宇 | K38: 1 | L38: 1
G39: 0 | H39: 0
D40: 技术支持 | E40: 3 | F40: 技术支持 | G40: 1 | H40: 0 | I40: 0 | J40: 王超杰 | K40: 1 | L40: 1
...

Sheet 业务投资地图(2026-预测)
A1: 业务投资分解 | J1: 人力分布 | P1: 目标客户
A2: 业务 | B2: 上半年总投/人天 | C2: 目标投入 | D2: 业务方向 | E2: 承载版本 | F2: 预期 | G2: 子方向 | H2: 开发（人月） | I2: 测试（人月） | J2: 开发 | K2: Q3 | L2: Q4 | M2: 测试 | N2: Q3 | O2: Q4
A3: 超融合交换机 （主线版本） | D3: 无损网络保供应 | E3: 框支持ROCE+25G(48X-NE，12C) | F3: 2026年1月-4月 | G3: 25G兼容健壮性 | H3: 3 | I3: 3
G4: 48X-NE、12C线卡roce能力支持 | H4: 8 | I4: 5
G5: 框架构兼容、堆叠 | H5: 4 | I5: 4
G6: 质量改进 | H6: 5 | I6: 8
D7: 无损网络国产化超融合交换机 | E7: NS6820 | F7: 2026年1月-7月 | G7: knet： 1、tx\rx、dcb 2、vkent通讯 3、性能 | H7: 8 | I7: ==H7/2 -> 4
G8: acl： 1、模板适配 2、组配置，entry芯片对接 | H8: 12 | I8: ==H8/2 -> 6
G9: 设备管理： 1、光模块管理 2、风扇相关管理 3、温感管理 | H9: 8 | I9: ==H9/2 -> 4
G10: wns-nsl适配层: 1、新版本sdk接口封装、逻辑打通 2、自动化接口基座 3、表项特性设计，lpm表项hit机制等、规格设计 4、业务对接 | H10: 15 | I10: ==H10/2 -> 7.5
G11: 主动稳定性： 1、SDK主动稳定性 2、单元测试、接口逻辑测试、随机调用测试支持 3、性能测试可观测设计 | H11: 8 | I11: ==H11/4 -> 2
G12: cpu架构&性能优化提升： 1、大小核调度 2、内核驱动 | H12: 5 | I12: ==H12/2 -> 2.5
G13: 技术债和质量改进： 1、历史bug合入 2、sdk bug列表 3、框bug合入 | H13: 15 | I13: ==H13/3 -> 5
G14: 业务适配： 1、聚焦超融合场景的l2/l3业务 | H14: 12 | I14: 3
E15: 国产化超融合-迭代： | F15: 2026年8月-2027年2月 | G15: mlag 1、架构重构 2、L2/L3表项同步 3、本地优先转发 4、冗余接管性能指标 | H15: 15 | I15: ==H15/2 -> 7.5
G16: 技术债和质量改进 | H16: 6 | I16: ==H16/1 -> 6
A17: 国产化梯队 | D17: 国产化框 | E17: 国产化3槽+线卡（基础一IPV6） | F17: 46174 | G17: M3主控： | H17: 8 | I17: ==H17/2 -> 4
F18: 2026/12月 | G18: 7132线卡： 1、bsp、sdk适配 2、knet、acl、wns-nsl、堆叠 3、设备管理 4、帧通道 | H18: 18 | I18: ==H18/1 -> 18
G19: 架构适配： 1、堆叠、knet、帧通道、DM\DTM 2、资源管理、带外管理 3、混插、协议帧性能 | H19: 10 | I19: ==H19/2 -> 5
G20: 基础业务适配： 1、IPV4全业务 2、基础IPV6 3、协议性能、主备倒换性能、冗余接管性能 | H20: 8 | I20: ==H20/1 -> 8
E21: 国产化框IPV6补齐 | F21: 2026年9月-2027年2月 | G21: ipv6协议补齐： 1、OSPF v3 2、SLAAC(客户端) 3、DHCPv6(客户端) 4、DHCP中继(新加) 5、ACL6合入、策略路由 6、ICMPv6、NDP（上个版本未做完） | H21: 12 | I21: 7
E22: S6主控+8120线卡 | F22: /
D23: 锋速新硬件 | E23: HS5120-PoF | F23: 2026年1月-2026年8月 | G23: HS5120-PoF、全光方案： 端口形态：24个2.5G电口 改为 2.5G bosa光，加一个管理网口。前面12口支持BT，改为24个口全部支持BT | H23: 6 | I23: ==H23/2 -> 3
E24: HS3100--芯片升级 | G24: HS3100--芯片升级： 1，千加万：8个千兆电（POE）+2个万兆光 2，千加万：8个千兆电（非POE）+2个万兆光 | H24: 5 | I24: ==H24/2 -> 2.5
E25: HS3100--8口远端模块 | G25: HS3100--8口远端新型号： 千加万：8*千兆电（4poe）+1*10G光+1*2.5G PO | H25: 3 | I25: ==H25/2 -> 1.5
F26: / | G26: …… | I26: ==H26/3 -> 0
A27: 质量迭代 | D27: 常规质量迭代 | E27: 质量基线版本 | G27: 1 全系ROCE ，芯片支持的都做 2 健壮性方案 , 3 堆叠心跳、优先级逻辑优化 4 版本问题 5 框升级问题 6 架构优化 7 稳定性bug，定制合入 | H27: 25 | I27: ==H27/2 -> 12.5
E28: 硬件物料更新 | G28: 框硬件物料更新 | I28: 12
D29: 国产化质量迭代 | E29: 国产化质量迭代 | G29: 国产化质量迭代 | H29: 10 | I29: ==H29/2 -> 5
A30: 精品化 | D30: 补短板 | E30: super-vlan | F30: 46174 | G30: super-vlan | H30: 1 | I30: 5
E31: 安全证书 | F31: 2026年8月-12 | G31: 安全检测过认证 | H31: 4 | I31: 4
F32: / | G32: 多机堆叠-定制方案
F33: / | G33: BGP
F34: / | G34: ERPS
D35: 控制器易用性版本 | H35: 4 | I35: ==H35/1 -> 4
A36: 探索 | D36: AI赋能网络 | G36: AI故障预测、智能诊断 | H36: 18 | I36: ==H36/3 -> 6
A38: 长期投入& 核心竞争力 | D38: 技术预研 | G38: 新硬件适配全流程 AINative大幅提效 | H38: 3 | I38: ==H38/3 -> 1
G39: 故障隔离 | H39: 6 | I39: ==H39/3 -> 2
G40: agent基座 | H40: 6 | I40: ==H40/3 -> 2
G41: 极致转控分离 | H41: 6 | I41: ==H41/3 -> 2
...

Sheet AI项目人力
A1: 整体人力甘特图
A3: 团队人力 | D3: 2025年
A4: 姓名 | B4: 岗位 | C4: 团队代号 | D4: 1月 | E4: 2月 | F4: 3月 | G4: 4月 | H4: 5月 | I4: 6月 | J4: 负责价值领域 | K4: 当前工作 | L4: 备注
A5: 吴广华 | B5: 开发 | C5: coredump组 | D5: 7029 | E5: 7029 | F5: 7029 | G5: 7030 | H5: 7030 | I5: 7030 | J5: 集群 | K5: DPU版本 | L5: NA
A6: 左乾江 | B6: 开发 | C6: coredump组 | D6: 7026R3 | E6: 7026R3 | F6: 7026R3 | G6: 7030 | H6: 7030 | I6: 7030 | J6: 四七层吞吐性能优化(LRO/GSO) 、集群手动同步 | K6: 预研-CPU过载 | L6: OK
A7: 肖志鹏 | B7: 开发 | C7: coredump组 | D7: 7026R3 | E7: 7026R3 | F7: 7026R3 | G7: 7030 | H7: 7030 | I7: 7030 | J7: C3000平台(硬件导入类) | K7: 浪潮定制ARP代理 | L7: OK
A8: 王辉光 | B8: 开发 | C8: 盘古 | D8: 7026R3 | E8: 7026R3 | F8: 7026R3 | G8: 7030 | H8: 7030 | I8: 7030 | J8: SSLO反代 | K8: 7026R3/预研-SSLO反代 | L8: OK
A9: 叶鹏 | B9: 开发 | C9: 盘古 | D9: 预研 | E9: 预研 | F9: 预研 | G9: 7030 | H9: 7030 | I9: 7030 | J9: 配置大容量 | K9: 预研-大容量 | L9: NA
A10: 彭文弈 | B10: 开发 | C10: 盘古 | D10: 7026R3 | E10: 7026R3 | F10: 7026R3 | G10: 7030 | H10: 7030 | I10: 7030 | K10: 预研-大容量 | L10: OK
A11: 张新锐 | B11: 开发 | C11: 盘古 | D11: 7026R3 | E11: 7026R3 | F11: 7026R3 | G11: 7030 | H11: 7030 | I11: 7030 | J11: 业务效果一致(Profile行为一致性、usleep低延时改进) | K11: sslbypass定制补丁 | L11: OK
A12: 田勤善 | B12: 开发 | C12: 云化小组 | D12: AD云化 多主集群 | E12: AD云化 多主集群 | F12: AD云化 多主集群 | G12: AD云化 多主集群 | H12: AD云化 AD容器化预研 | I12: AD云化 AD容器化预研 | J12: 云化/VAD+多主集群 | K12: 多主集群 | L12: NA
A13: 王鸿奇 | B13: 开发 | C13: 云化小组 | D13: AD云化 API性能预研 | E13: AD云化 API性能预研 | F13: AD云化 API性能预研 | G13: AD云化 拓展API | H13: AD云化 拓展API | I13: AD云化 拓展API | J13: 云化/拓展API | K13: 扩容API | L13: OK
A14: 郑泳 | B14: 开发 | C14: 云化小组 | D14: AD云化 PAASAD标准化 | E14: AD云化 PAASAD标准化 | F14: AD云化 PAASAD标准化 | G14: AD云化PAASAD标准化 | H14: AD云化 PAASAD标准化 | I14: AD云化 PAASAD标准化 | J14: 云化/PAASAD+CNAD | K14: 国泰君安定制 | L14: NA
A15: 何伟 | B15: 开发 | C15: 云化小组 | D15: AD云化 VAD标准化 | E15: AD云化 VAD标准化 | F15: AD云化 VAD标准化 | G15: AD云化PAASAD标准化 | H15: AD云化PAASAD标准化 | I15: AD云化PAASAD标准化 | J15: 云化/VAD | K15: 平台识别和授权识 | L15: OK

Sheet sw人力甘特图(2026)
A1: 整体人力甘特图
A3: 团队人力 | D3: 2025年 | S3: 总数 | T3: 2级 | U3: 3级 | V3: 4级 | W3: 总分 | X3: 团队总分
A4: 姓名 | B4: 岗位 | C4: 职级 | D4: 资源组 | E4: 1月 | F4: 2月 | G4: 3月 | H4: 4月 | I4: 5月 | J4: 6月 | K4: 7月 | L4: 8月 | M4: 9月 | N4: 10月 | O4: 11月 | P4: 12月 | Q4: 1月 | R4: 2月 | S4: 负责主价值领域 | T4: 当前工作
A5: 何海坤 | B5: 业务组长 | C5: T4 | D5: 业务/协议 | E5: 盛科盒式 | F5: 盛科盒式 | G5: NS6820 | H5: NS6820 | I5: NS6820 | J5: NS6820 | K5: NS6820 | L5: 国产框IPV6 | M5: 国产框IPV6 | N5: 国产框IPV6 | O5: 国产框IPV6 | P5: 国产框IPV6 | S5: 协议、IPV6
A6: 王惠杰 | B6: 开发 | C6: T3 | D6: 业务/协议 | E6: 盛科盒式 | F6: 盛科盒式 | G6: NS6820 | H6: NS6820 | I6: NS6820 | J6: NS6820 | K6: NS6820 | L6: 国产化质量 | M6: 国产化质量 | N6: 国产化质量 | O6: 国产化质量 | P6: 国产化质量 | S6: 瘦架构业务
A7: 凌通 | B7: 开发 | C7: T4 | D7: 业务/协议 | E7: 盛科盒式 | F7: 盛科盒式 | G7: NS6820 | H7: NS6820 | I7: NS6820 | J7: NS6820 | K7: NS6820 | L7: 国产化质量 | M7: 国产化质量 | N7: 国产化质量 | O7: 国产化质量 | P7: 国产化质量 | S7: 协议、IPV6
A8: 蔡东强 | B8: 开发 | C8: T4 | D8: 业务/协议 | E8: 盛科盒式 | F8: 盛科盒式 | G8: NS6820 | H8: NS6820 | I8: NS6820 | J8: NS6820 | K8: NS6820 | L8: 国产框IPV6 | M8: 国产框IPV6 | N8: 国产框IPV6 | O8: 国产框IPV6 | P8: 国产框IPV6 | S8: 协议、IPV6
A9: 刘瑞航 | B9: 开发 | C9: T2 | D9: 业务/协议 | E9: 盛科盒式 | F9: 盛科盒式 | G9: 框支持ROCE | H9: 框支持ROCE | I9: NS6820-迭代 | J9: NS6820-迭代 | K9: NS6820-迭代 | L9: NS6820-迭代 | M9: NS6820-迭代 | N9: NS6820-迭代 | O9: NS6820-迭代 | P9: NS6820-迭代 | S9: 瘦架构业务
A10: 肖劲 | B10: 开发 | C10: T2 | D10: 业务/协议 | E10: 盛科盒式 | F10: 盛科盒式 | G10: 锋速新硬件 | H10: 锋速新硬件 | I10: 锋速新硬件 | J10: 锋速新硬件 | K10: 锋速新硬件 | L10: 锋速新硬件 | M10: 定制预留 | N10: 定制预留 | O10: 定制预留 | P10: 定制预留 | S10: 瘦架构业务
A11: 杨巡 | B11: 开发 | C11: T2 | D11: 业务/协议 | E11: super-vlan | F11: super-vlan | G11: 国产3槽框 | H11: 国产3槽框 | I11: 国产3槽框 | J11: 国产3槽框 | K11: 定制预留 | L11: 定制预留 | M11: 定制预留 | N11: 定制预留 | O11: 定制预留 | P11: 定制预留 | S11: 瘦架构业务
A12: 祝满 | B12: TSE | C12: T5 | D12: 业务/协议 | E12: 盛科盒式 | F12: 盛科盒式 | G12: NS6820 | H12: NS6820 | I12: NS6820 | J12: NS6820 | K12: 质量版本 | L12: 质量版本 | M12: 质量版本 | N12: 质量版本 | O12: 质量版本 | P12: 超融合组网 | S12: 超融合场景
A13: 张文杰 | B13: 测试 | C13: T5 | D13: 业务/协议 | E13: 盛科盒式 | F13: 盛科盒式 | G13: 框支持ROCE | H13: 国产3槽框 | I13: 国产3槽框 | J13: 国产3槽框 | K13: 国产3槽框 | L13: 国产3槽框 | M13: 国产3槽框 | N13: 国产3槽框 | O13: 国产3槽框 | P13: 国产框ipv6 | S13: IPv6
A14: 李鹏铉 | B14: 测试 | C14: T2 | D14: 业务/协议 | G14: 国产3槽框 | H14: NS6820 | I14: NS6820 | J14: NS6820 | K14: 国产3槽框 | L14: 国产3槽框 | M14: 国产3槽框 | N14: 国产3槽框 | O14: 国产3槽框 | P14: 国产3槽框 | S14: 二层协议
A15: 胡厚捷 | B15: 测试 | C15: T2 | D15: 业务/协议 | E15: 盛科盒式 | F15: 盛科盒式 | G15: 框支持ROCE | H15: NS6820 | I15: NS6820 | J15: NS6820 | K15: 国产3槽框 | L15: 国产3槽框 | M15: 国产3槽框 | N15: 国产3槽框 | O15: 国产3槽框 | P15: 国产3槽框 | S15: 三层协议
A16: 王伟臣 | B16: 测试 | C16: T2 | D16: 业务/协议 | E16: 盛科盒式 | F16: 盛科盒式 | G16: 框支持ROCE | H16: 国产3槽框 | I16: 国产3槽框 | J16: 国产3槽框 | K16: 国产3槽框 | L16: 国产3槽框 | M16: 国产3槽框 | N16: 国产3槽框 | O16: 国产3槽框 | P16: 国产3槽框 | S16: 堆叠场景
A17: 高士杰 | B17: 测试 | C17: T3 | D17: 业务/协议 | E17: 盛科盒式 | F17: 盛科盒式 | G17: 框支持ROCE | H17: NS6820 | I17: NS6820 | J17: NS6820 | K17: 国产3槽框 | L17: 国产3槽框 | M17: 国产3槽框 | N17: 国产3槽框 | O17: 国产3槽框 | P17: 国产3槽框 | S17: 堆叠场景
A18: 陈云飞 | B18: 测试 | C18: T4 | D18: 业务/协议 | E18: 盛科盒式 | F18: 盛科盒式 | G18: 框支持ROCE | H18: NS6820 | I18: NS6820 | J18: NS6820 | K18: 质量版本 | L18: 质量版本 | M18: 质量版本 | N18: 质量版本 | O18: 质量版本 | P18: 质量版本 | S18: RDMA
A19: 许家豪 | B19: 外包测试 | C19: / | D19: 业务/协议 | E19: 盛科盒式 | F19: 盛科盒式 | G19: 锋速新硬件 | H19: 锋速新硬件 | I19: 控制器易用性版本 | J19: 控制器易用性版本 | K19: 锋速新硬件 | L19: 锋速新硬件 | M19: 精品化改进 | N19: 精品化改进 | O19: 精品化改进 | P19: 精品化改进 | S19: 新硬件测试
A20: 李坤 | B20: 外包测试 | C20: / | D20: 业务/协议 | E20: 盛科盒式 | F20: 盛科盒式 | G20: 锋速新硬件 | H20: 锋速新硬件 | I20: 硬件导入承接 | J20: 硬件导入承接 | K20: 锋速新硬件 | L20: 锋速新硬件 | M20: 精品化改进 | N20: 精品化改进 | O20: 精品化改进 | P20: 精品化改进 | S20: 新硬件测试
A21: 彭雨林 | B21: 业务组长 | C21: T7 | D21: 芯片/sdk | E21: 框支持ROCE | F21: 框支持ROCE | G21: 框支持ROCE | H21: 框支持ROCE | I21: 预研-热补丁 | J21: 预研-热补丁 | K21: 预研-热补丁 | L21: 预研-故障隔离 | M21: 预研-故障隔离 | N21: 预研-故障隔离 | O21: 预研-故障隔离 | P21: 预研-故障隔离 | S21: acl、芯片流水线
A22: 张润萌 | B22: 开发 | C22: T5 | D22: 芯片/sdk | E22: 锋速新硬件 | F22: 锋速新硬件 | G22: 锋速新硬件 | H22: 锋速新硬件 | I22: 锋速新硬件 | J22: 锋速新硬件 | K22: 锋速新硬件 | L22: 锋速新硬件 | M22: 预研-适配流程 | N22: 预研-适配流程 | O22: 预研-适配流程 | P22: 预研-适配流程 | S22: sdk平台支撑
A23: 余龙 | B23: 开发 | C23: T4 | D23: 芯片/sdk | E23: 国产3槽框 | F23: 国产3槽框 | G23: NS6820 | H23: NS6820 | I23: NS6820 | J23: NS6820 | K23: NS6820 | L23: 国产3槽框 | M23: 国产3槽框 | N23: 国产3槽框 | O23: 国产3槽框 | P23: 国产3槽框 | S23: sdk平台支撑
A24: 黎柏成 | B24: 开发 | C24: T6 | D24: 芯片/sdk | E24: 盛科盒式 | F24: 盛科盒式 | G24: NS6820 | H24: NS6820 | I24: NS6820 | J24: NS6820 | K24: NS6820 | L24: 国产3槽框 | M24: 国产3槽框 | N24: 国产3槽框 | O24: 国产3槽框 | P24: 国产3槽框 | S24: 端口、PHY驱动
A25: 张家龙 | B25: 开发 | C25: T3 | D25: bsp | E25: 国产3槽框 | F25: 国产3槽框 | G25: NS6820 | H25: NS6820 | I25: NS6820 | J25: NS6820 | K25: NS6820 | L25: 质量版本 | M25: 质量版本 | N25: 质量版本 | O25: 质量版本 | P25: 质量版本 | S25: bsp
A26: 向健鹏 | B26: TL | C26: T4 | D26: 无损网络 | E26: 框支持ROCE | F26: 框支持ROCE | G26: 框支持ROCE | H26: 框支持ROCE | I26: 超融合融合组网 | J26: 超融合融合组网 | K26: 超融合融合组网 | L26: 超融合融合组网 | M26: 超融合融合组网 | N26: 超融合融合组网 | O26: 超融合融合组网 | P26: 超融合融合组网 | S26: 超融合、无损网络、acl
... A44: 郭柏材 | B44: 测试 | C44: T4 | D44: 技术支持 | E44: 技术支持 | F44: 技术支持 | G44: 技术支持 | H44: 技术支持 | I44: 技术支持 | J44: 技术支持 | K44: 技术支持 | L44: 技术支持 | M44: 技术支持 | N44: 技术支持 | O44: 技术支持 | P44: 技术支持 | S44: 技术支持
A45: 吴亮 | B45: 项目主管 | C45: M6 | D45: 管理 | E45: 管理 | F45: 管理 | G45: 管理 | H45: 管理 | I45: 管理 | J45: 管理 | K45: 管理 | L45: 管理 | M45: 管理 | N45: 管理 | O45: 管理 | P45: 管理
A46: 韩云飞 | B46: 开发 | C46: T8 | D46: 管理 | E46: 管理 | F46: 管理 | G46: 管理 | H46: 管理 | I46: 管理 | J46: 管理 | K46: 管理 | L46: 管理 | M46: 管理 | N46: 管理 | O46: 管理 | P46: 管理
A47: 陈金标 | B47: 测试经理 | C47: M5 | D47: 管理 | E47: 管理 | F47: 管理 | G47: 管理 | H47: 管理 | I47: 管理 | J47: 管理 | K47: 管理 | L47: 管理 | M47: 管理 | N47: 管理 | O47: 管理 | P47: 管理 | S47: 测试全流程AI化
A57: 版本人力甘特图
A59: 版本-人力 | D59: 2025年 | S59: 战场 | T59: 研发人数 | U59: 占比 | V59: 开发 | W59: 测试 | Y59: 人力
A60: 版本 | B60: 岗位 | C60: 当月占比 | D60: 1月 | E60: 2月 | F60: 3月 | G60: 4月 | H60: 5月 | I60: 6月 | J60: 7月 | K60: 8月 | L60: 9月 | M60: 10月 | N60: 11月 | O60: 12月 | S60: 超融合交换机 （主线版本） | T60: 15.958333 | U60: 0.35267035 | V60: 10.333333 | W60: 5.625 | Y60: 15.958333
A61: 国产化超融合：NS6820 | B61: 开发 | C61: ==D61/D87 -> 0.27777778 | D61: 5 | E61: 5 | F61: 12 | G61: 12 | H61: 12 | I61: 12 | J61: 12 | S61: 国产化梯队 | T61: 9.9166667 | U61: 0.21915285 | V61: 5.8333333 | W61: 4.0833333 | Y61: 9.9166667
B62: 测试 | C62: ==D62/D88 -> 0 | D62: 0 | E62: 0 | F62: 1 | G62: 5 | H62: 10 | I62: 10 | J62: 3 | S62: 质量迭代 | T62: 5.375 | U62: 0.125 | V62: 2.9166667 | W62: 2.4583333 | Y62: 5.375
A63: 框支持ROCE+25G(48X-NE，12C) | B63: 开发 | C63: ==D63/D87 -> 0.27777778 | D63: 5 | E63: 5 | F63: 5 | G63: 5 | S63: 精品化 | T63: 1.8333333 | U63: 0.040515654 | V63: 0.75 | W63: 1.0833333 | Y63: 1.8333333
B64: 测试 | C64: ==D64/D88 -> 0 | D64: 0 | E64: 3 | F64: 10 | G64: 5 | S64: 探索 | T64: 2 | U64: 0.044198895 | V64: 1.5 | W64: 0.5
A65: 国产化3槽+线卡（2）（迭代一IPV6） | B65: 开发 | C65: ==D65/D87 -> 0.22222222 | D65: 4 | E65: 3 | F65: 1 | G65: 1 | H65: 1 | I65: 1 | J65: 1 | K65: 6 | L65: 6 | M65: 6 | N65: 6 | O65: 6 | S65: 长期投入& 核心竞争力 | T65: 2.6666667 | U65: 0.05893186 | V65: 2 | W65: 0.66666667
B66: 测试 | C66: ==D66/D88 -> 0 | F66: 1 | G66: 1 | H66: 1 | I66: 1 | J66: 4 | K66: 7 | L66: 7 | M66: 8 | N66: 7 | O66: 6 | S66: 效能和质量运营 | T66: 4.5 | U66: 0.099447514 | V66: 3.3333333 | W66: 1.1666667
A67: 锋速新硬件4款（5120优先，pof降本） | B67: 开发 | C67: ==D67/D87 -> 0.055555556 | D67: 1 | E67: 1 | F67: 2 | G67: 2 | H67: 2 | I67: 2 | J67: 2 | K67: 2 | S67: 管理 | T67: 3 | U67: 0.066298343 | V67: 2 | W67: 1 | Y67: 3
B68: 测试 | C68: ==D68/D88 -> 0 | F68: 2 | G68: 2 | H68: 0 | I68: 0 | J68: 2 | K68: 2 | S68: 总人数 | T68: 45.25 | U68: 1 | V68: 28.666667 | W68: 16.583333 | Y68: 45.25
...

Sheet 2026--roadmap-4.7
A1: 维度 | B1: 项目 | C1: 排序 | D1: 人员 | E1: 启动时间 | F1: 预期发布时间 | G1: 资源 | H1: 2026.1 | I1: 2月 | J1: 3月 | K1: 4月 | L1: 5月 | M1: 6月 | N1: 7月 | O1: 8月 | P1: 9月 | Q1: 10月 | R1: 11月 | S1: 12月 | T1: 2027.1月 | U1: 2月 | V1: 3月 | W1: 4月 | X1: 5月 | Y1: 6月 | Z1: 7月 | AA1: 8月 | AB1: 9月 | AC1: 10月
B2: 国产化超融合： 1，NS6820，E2000Q+CTC8120 NS6820-56CQ-EI-48X 48万兆光+8个100G光 NS6820-56CQ-EI-48V 48个25G光+8个100G光 2，协议 ECN/PFC (超融合软件版本，NS6820默认发超融合版本， 有需要的按需升级价值版本) | C2: 1 | D2: 王奕贤14815 蔡东强53792 王惠杰19906 凌通14339 何海坤47669 刘玉训92838 张家龙94038 陈炜俊17980 黎柏成52605 李一虎13117 梁怀光 余龙71592 | E2: 45992 | F2: 2026.7.30 | G2: SW开发 | H2: 5 | I2: 5 | J2: 12 | K2: 12 | L2: 12 | M2: 12 | N2: 12
G3: SW测试 | H3: 0 | I3: 0 | J3: 1 | K3: 6 | L3: 11 | M3: 11 | N3: 6
B4: 框支持ROCE+25G(48X-NE，12C) | C4: 1 | D4: 向健鹏 彭雨林 温志浩 黄安 刘瑞杭 | E4: 2026.1 | F4: 2026.4 | G4: SW开发 | H4: 5 | I4: 5 | J4: 5 | K4: 5
G5: SW测试 | H5: 0 | I5: 5 | J5: 10 | K5: 5
A6: 2 | B6: 国产化3槽+线卡（2）（迭代一IPV6） | C6: 2 | D6: 陈保光 杨巡89772 | E6: 45992 | F6: 2026.12.30 | G6: SW开发 | H6: 4 | I6: 3 | J6: 1 | K6: 1 | L6: 1 | M6: 1 | N6: 1 | O6: 6 | P6: 6 | Q6: 6 | R6: 6 | S6: 6
G7: SW测试 | N7: 1 | O7: 8 | P7: 8 | Q7: 8 | R7: 6 | S7: 6
B8: 锋速新硬件（5120优先，pof降本） | C8: 2 | D8: 张润萌 肖劲 | E8: 2026.1 | F8: 2026.8 | G8: SW开发 | H8: 1 | I8: 1 | J8: 2 | K8: 2 | L8: 2 | M8: 2 | N8: 2 | O8: 2
G9: SW测试 | J9: 1 | K9: 2 | L9: 2 | M9: 2 | N9: 2 | O9: 2
B10: 质量版本： 8 板卡ROCE ，芯片支持的都做--优先级调到最高-2025.12.1更新 1 健壮性方案 , 2 交换机组件补丁升级 3 堆叠心跳、优先级逻辑优化 4 版本问题 5 框升级问题 6 架构优化 7 稳定性bug，定制合入 | C10: 2 | E10: 2026.3 | F10: 2026.12 | G10: SW开发 | I10: 0 | J10: 1 | K10: 0 | L10: 3 | M10: 3 | N10: 3 | O10: 3 | P10: 3 | Q10: 3 | R10: 3 | S10: 3 | T10: 3 | U10: 3
G11: SW测试 | N11: 4 | O11: 4 | P11: 4 | Q11: 4 | R11: 4 | S11: 4 | T11: 4 | U11: 4
B12: 控制器易用性版本 | C12: 2 | D12: 金龙飞 | G12: SW开发 | H12: 0 | J12: 1 | K12: 1 | L12: 1
G13: SW测试 | H13: 0 | I13: 0 | J13: 0 | K13: 0 | L13: 1 | M13: 1 | N13: 1
B14: super vlan | C14: 3 | G14: SW开发 | H14: 3 | I14: 3
G15: SW测试 | H15: 1 | I15: 1 | J15: 1 | K15: 1 | L15: 1
B16: 多机堆叠-定制方案 | C16: 3 | G16: SW开发
G17: SW测试
B18: 硬件导入（光模块、内存条、flash、型号改制、OEM软硬件交换机等） | C18: 3 | G18: SW开发
G19: SW测试 | H19: 1 | I19: 1 | J19: 1 | K19: 1 | L19: 1 | M19: 1 | N19: 1 | O19: 1 | P19: 1 | Q19: 1 | R19: 1 | S19: 1
B20: 国产化超融合-迭代： 1、 mlag, 2、 质量迭代 | C20: 4 | F20: 2027.2.28 | G20: SW开发 | O20: 3 | P20: 3 | Q20: 3 | R20: 3 | S20: 3 | T20: 3 | U20: 3
G21: SW测试 | R21: 2 | S21: 1 | T21: 5 | U21: 5
B22: 国产化质量版本 | C22: 4 | E22: 46204 | F22: 46386 | G22: SW开发 | O22: 2 | P22: 2 | Q22: 2 | R22: 2 | S22: 2 | T22: 2 | U22: 2
G23: SW测试 | S23: 1 | T23: 3 | U23: 3
B24: 国产框IPV6补齐 | C24: 5 | F24: 2026.12.30 | G24: SW开发 | P24: 2 | Q24: 2 | R24: 2 | S24: 2 | T24: 2 | U24: 2
G25: SW测试 | S25: 1 | T25: 3 | U25: 3
B26: 盛科盒式IPV6补齐 | C26: 5 | G26: SW开发
G27: SW测试
B28: 国产化S6+国产化线卡（4张） | C28: 6 | E28: 待定 | F28: 待定 | G28: SW开发
G29: SW测试
B30: 国产化S9（12槽优先级放低） | C30: 6 | E30: 待定 | F30: 待定 | G30: SW开发
G31: SW测试
B32: 精品化改进（博通+盛科）: | C32: 6 | E32: 待定 | F32: 待定 | G32: SW开发 | O32: 1 | P32: 1 | Q32: 1 | R32: 1 | S32: 1
G33: SW测试 | O33: 0 | P33: 2 | Q33: 2 | R33: 2 | S33: 2
B34: BGP | C34: 7 | E34: 待定 | F34: 待定 | G34: SW开发
G35: SW测试
B36: 标准VXLAN | C36: 8 | E36: 待定 | F36: 待定 | G36: SW开发
G37: SW测试
B38: 易用性改进 | C38: 8 | E38: 待定 | F38: 待定 | G38: SW开发
G39: SW测试
B40: 价值补齐： 1、ERPS （同优先级BGP） | C40: 8 | E40: 待定 | F40: 待定 | G40: SW开发
...

Sheet 业务投资地图（2024H1）
A1: 业务投资分解 | J1: 人力分布 | Q1: 目标客户
A2: 类型 | B2: 上半年总投/人天 | C2: 目标投入 | D2: 业务方向 | E2: 子方向目标投入 | F2: 子方向 | G2: 开发 | H2: TL | I2: 测试 | J2: 开发 | K2: 开发 | L2: 开发 | M2: 开发 | N2: TL | O2: 测试 | P2: 测试
A3: AD7.0.28 | B3: ==SUM('AD人力甘特图(2024)'!D65:I66)*22 -> 1100 | C3: 15 | D3: 替换F5 | E3: ==SUM(G3:G11)+H3+I3 -> 15 | F3: 默认参数对齐 | G3: 1 | H3: 2 | I3: 4 | J3: 彭文奕 | N3: 李林林 | O3: 郑奇高
F4: 离线巡检 | G4: 1 | J4: 蒋品局 | N4: 苏敏宁 | O4: 刘亚
F5: f5配置转换 | G5: 1 | J5: 左乾江 | O5: 郑嘉颖
F6: 低延时优化 | G6: 1 | J6: 田勤善 | O6: 唐柴袁
F7: irule支持（HTTP，TCP） | G7: 1 | J7: 何泳江
F8: RAS | G8: 1 | J8: 刘文龙
F9: SSLO二层 | G9: 1 | J9: 高光毫
F10: 运维排障优化 | G10: 1 | J10: 王辉光
F11: 硬件导入 | G11: 1 | J11: 樊晗生
A12: AD7.0.26R3 | B12: ==SUM('AD人力甘特图(2024)'!H59:I60)*22 -> 66 | C12: 3 | D12: 质量改进 | E12: ==SUM(G12:G13)+H12+I12 -> 3 | F12: 技术债 | G12: 1 | H12: 0 | I12: 1 | J12: 李洪懋 | K12: 王鸿奇 | O12: 薛载路
F13: 定制削减 | G13: 1 | H13: 0
A14: AD7.0.26R2EN | B14: ==SUM('AD人力甘特图(2024)'!G61:I62)*22 -> 264 | C14: 4 | D14: 海外市场 | E14: ==SUM(G14)+H14+I14 -> 4 | F14: 海外市场 | G14: 2 | H14: 0 | I14: 2 | J14: 吴广华 | K14: 张新锐 | O14: 曹刚 | P14: 刘思远 | Q14: 宝马香港
A15: 长期投入& 核心竞争力 | B15: ==SUM('AD人力甘特图(2024)'!D73:I73)*22 -> 396 | C15: 3 | D15: 技术预研 友商分析 | E15: ==SUM(G15:G21)+SUM(H15:H21)+I15 -> 4 | F15: 配置大容量 | G15: 2 | H15: 0 | I15: 0 | J15: 叶鹏 | K15: 周黎利
F16: SSL高性能（商密&国密） | G16: 0 | H16: 0
F17: FPGA | G17: 1 | H17: 0 | J17: 刘都都
F18: C3000（交换芯片） | G18: 0 | H18: 0
F19: F5分析 | G19: 1 | H19: 0 | J19: 张祺
F20: 迪普分析 | G20: 0 | H20: 0
F21: 可信token | G21: 0 | H21: 0
A22: 公共支撑 | B22: ==SUM('AD人力甘特图(2024)'!D69:I72,'AD人力甘特图(2024)'!D74:I74,'AD人力甘特图(2024)'!D75:I76)*22 -> 2266 | C22: 15 | D22: KA定制 | E22: ==SUM(G22)+H22+I22 -> 3 | F22: KA定制 | G22: 2 | H22: 1 | I22: 0 | K22: 金红星 | L22: 郑泳 | N22: 雷斌亭 | O22: 吴霖彬 | Q22: 正在投入 建设银行信创负载（2024.6）--正在测试 交行 708系列 曙光GA220 /GA320--已做完，待测试 中国银联信总-命令行对接（2024.5） 中国移动入围华为鲲鹏适配（2024.6） 广发定制（TOA透传）（2024.5） 中储粮SSLO定制(二期)（2024.6） OGCIO SNI扩容到1000或者1500（2024.6） CNAD持续 待投入--6月 兴业银行框架标(扩容)，中信POC入围（8月） 华为AD替换F5定制补丁（多租户优化） 移动POC入围（6月中下旬标前）
D23: 覆盖性市场定制 | E23: ==SUM(G23)+H23+I23 -> 0 | F23: 覆盖性市场定制 | G23: 0 | H23: 0 | I23: 0
D24: 质量运营(安全/工具/硬件巡检） | E24: ==SUM(G24)+H24+I24 -> 4 | F24: (安全/工具/硬件巡检） | G24: 4 | H24: 0 | I24: 0 | J24: 熊锐 | K24: 曾泽铭w | L24: 郝春宇 | M24: 余杰w | Q24: SP护网补丁，SP质量补丁， 硬件ECN变更， acheck巡检/软硬件巡检能力（长期）
D25: 技术支持 | E25: ==SUM(G25)+H25+I25 -> 3 | F25: 技术支持 | G25: 3 | H25: 0 | I25: 0 | J25: 王超杰 | K25: 徐瑞准 | L25: 石佳晨
D26: 测试团队 | E26: ==SUM(G26)+H26+I26 -> 1 | F26: 测试(定制+质量) | G26: 0 | H26: 0 | I26: 1
D27: 管理团队 | E27: ==SUM(G27)+H27+I27 -> 3 | F27: 管理团队 | G27: 2 | H27: 0 | I27: 1 | J27: 方鹏斌 | K27: 陆树军 | O27: 臧韵琦
A28: 合计 | B28: ==SUM(B3:B27) -> 4092 | C28: ==SUM(C3:C27) -> 40 | D28: - | E28: ==SUM(E3:E27) -> 40 | F28: - | G28: ==SUM(G3:G27) -> 28 | H28: ==SUM(H3:H27) -> 3 | I28: ==SUM(I3:I27) -> 9
G29: ==SUM(G28:H28) -> 31 | I29: ==SUM(I28) -> 9

Sheet 物理AD分组人员（废弃）
A1: 姓名 | B1: 产品 | C1: 岗位 | D1: 职称 | E1: 合作方 | F1: 团队代号 | G1: 技术田 | H1: 备注 | I1: 其他 | J1: 当前版本 | K1: 下个版本 | L1: 到位时间
A2: 吴广华 | B2: AD | C2: 开发 | D2: T5 | E2: 否 | F2: 白泽 | G2: 架构责任田：mad 业务责任田：节点池、业务主机、SSL虚拟服务（不包含http）、ssl策略、ssl证书管理、高可用、硬件导入--加速卡、国密卡、网卡、sdk（含上层架构） | H2: TL | I2: 预研，高可用支持手动同步 | J2: 7027
A3: 张祺 | B3: AD | C3: 开发 | D3: T6 | E3: 否 | F3: 白泽 | G3: dpdJ升级1 | I3: dpdk升级、全平台网卡适配 | J3: 7027 | K3: 7028 | L3: 6月中
A4: 刘文龙 | B4: AD | C4: 开发 | D4: T4以下 | E4: 否 | F4: 白泽 | G4: 硬件导入 | I4: 工具链升级（母盘镜像制作） | J4: 7027
A5: 郑嘉颖 | B5: AD | C5: 测试 | D5: T4 | E5: 否 | F5: 白泽 | H5: 测试TSE | I5: 测试设计,效能改进 | J5: 7027
A6: 曹刚 | B6: AD | C6: 测试 | D6: T4以下 | E6: 否 | F6: 白泽 | I6: 网络，性能可靠性 | J6: 定制 | K6: 7027 | L6: 移动入围出差7月中
A7: 苏敏宁 | B7: AD | C7: 开发 | D7: M5 | E7: 否 | F7: 嘲风 | G7: 架构责任田：状态中心、API框架、系统配置中心、报表、调试框架（iproc、日志框架等） 业务责任田：dns服务、dns代理、系统管理、硬件导入 | H7: TL | J7: 7026R2 | K7: 7026R2
A8: 王辉光 | B8: AD | C8: 开发 | D8: T5 | E8: 否 | F8: 嘲风 | I8: 国密SDK | J8: 护网
A9: 彭文奕 | B9: AD | C9: 开发 | D9: T4 | E9: 否 | F9: 嘲风 | I9: 7027 | J9: 7028 | K9: 7028 | L9: 已到位，预研
A10: 陈健绍 | B10: AD | C10: 开发 | D10: T4 | E10: 否 | F10: 嘲风 | I10: 硬件适配，snmp | J10: 7026R2 | K10: 7026R2
A11: 叶鹏 | B11: AD | C11: 开发 | D11: T4 | E11: 否 | F11: 嘲风 | I11: 硬件，补丁升级改进 | J11: 7027 | K11: 7028 | L11: 已到位，预研
A12: 金红星 | B12: AD | C12: 开发 | D12: T4以下 | E12: 否 | F12: 嘲风 | I12: 7027 | J12: 7027
A13: 唐柴袁 | B13: AD | C13: 测试 | D13: T4以下 | E13: 是 | F13: 嘲风 | I13: 性能专项，补丁/母盘，外部测试支撑 | J13: 定制 | K13: 7028
A14: 叶佳卉 | B14: AD | C14: 测试 | D14: T4以下 | E14: 否 | F14: 嘲风 | H14: 测试TSE | I14: 测试设计，护网，母盘，API预研验收 | J14: 7026R2 | K14: 7028
A15: 方鹏斌 | B15: AD | C15: 开发 | D15: T6 | E15: 否 | F15: 盘古 | G15: 架构责任田：监视器、adappd配置中心、openad、ADM、ipro 业务责任田：L7虚拟服务协议、安全策略、自定义内容、优化策略（除tcp）、天窗/8583、SSLO、OCSP | H15: TL | I15: 预研，SSLO二层方案 | J15: 7027
A16: 李林林 | B16: AD | C16: 开发 | D16: T5 | E16: 否 | F16: 盘古 | I16: sslo | J16: 定制
A17: 田勤善 | B17: AD | C17: 开发 | D17: T4以下 | E17: 否 | F17: 盘古 | I17: 工具链升级（版本升级） | J17: 7027
A18: 郝春宇 | B18: AD | C18: 开发 | D18: T4以下 | E18: 否 | F18: 盘古 | J18: 7027
A19: 何泳江 | B19: AD | C19: 开发 | D19: T4 | E19: 否 | F19: 盘古 | J19: 7027
A20: 蒋品局 | B20: AD | C20: 开发 | D20: T4以下 | E20: 否 | F20: 盘古 | J20: 7026R2 | K20: 7027 | L20: cssp
A21: 郑奇高 | B21: AD | C21: 测试 | D21: T5 | E21: 否 | F21: 盘古 | H21: 测试TSE | I21: 性能可靠性专项 | J21: 7027
A22: 吴霖彬 | B22: AD | C22: 测试 | D22: T4以下 | E22: 是 | F22: 盘古 | I22: 测试设计 | J22: 7027
A23: 雷斌亭 | B23: AD | C23: 开发 | D23: T6 | E23: 否 | F23: coredump组 | G23: 架构责任田：dpdk、内存管理、消息队列、netfilter、协议栈、多租户、paasad 业务责任田：链路负载-智能路由、规则地址库、网络接口、l3、l4虚拟服务协议、tcp优化策略 | H23: TL | I23: CTO | J23: 7027
A24: 樊晗生 | B24: AD | C24: 开发 | D24: T4以下 | E24: 否 | F24: coredump组 | I24: 动态路由 | J24: 7027
A25: 高光毫 | B25: AD | C25: 开发 | D25: T4 | E25: 否 | F25: coredump组 | G25: TCP协议栈 | I25: 预研, 引用计数、下载协议优化， 交行正向代理路由池定制 | J25: 定制 | K25: 7029 | L25: 6-5,低时延
A26: 郑泳 | B26: AD | C26: 开发 | D26: T4 | E26: 否 | F26: coredump组 | I26: 工具链升级（多分区） | J26: 7027 | K26: 1111
A27: 王文强 | B27: AD | C27: 开发 | D27: T6 | E27: 否 | F27: coredump组 | I27: 预研, 疑难问题，网上问题响应 | J27: 7028 | K27: 7028
A28: 徐瑞准 | B28: AD | C28: 开发 | D28: T4 | E28: 否 | F28: coredump组 | G28: 路由 | J28: 7027
A29: 刘都都 | B29: AD | C29: 开发 | D29: T4以下 | E29: 否 | F29: coredump组 | G29: 过载保护 | J29: 7027 | L29: dpdk后备（待定）
A30: 张新锐 | B30: AD | C30: 开发 | D30: T4以下 | E30: 否 | F30: coredump组 | J30: 7027
A31: 方子健 | B31: AD | C31: 开发 | D31: T4以下 | E31: 否 | F31: coredump组 | J31: 7027
A32: 薛载路 | B32: AD | C32: 测试 | D32: T4 | E32: 否 | F32: coredump组 | I32: 性能可靠性专项 | J32: 7027 | K32: 7028
A33: 刘亚 | B33: AD | C33: 测试 | D33: T5 | E33: 否 | F33: 效能质量团队 | G33: 主线TSE、质量看护 | I33: 效能，自动化 | J33: 7027
A34: 骆俊 | B34: AD | C34: 测试 | D34: T4 | E34: 否 | F34: 效能质量团队 | I34: 效能改进 | J34: 7027
A35: 石佳晨 | B35: AD | C35: 开发 | D35: T4以下 | E35: 否 | F35: 技术支持组 | J35: 技术支持 | K35: 技术支持
A36: 熊锐 | B36: AD | C36: 开发 | D36: T4 | E36: 否 | F36: 技术支持组 | J36: 技术支持 | K36: 技术支持
A37: 周黎利 | B37: AD | C37: 开发 | D37: T6 | E37: 否 | F37: 系统架构组 | G37: APPD、FPGA、DPDJ、API、内核、工具链、预研 | H37: 架构师 | J37: 预研 | K37: 预研
A38: 王超杰 | B38: AD | C38: 开发 | D38: T6 | E38: 否 | F38: 系统架构组 | H38: RAT | J38: 技术支持 | K38: 技术支持
A39: 李洪懋 | B39: AD | C39: 开发 | D39: T5 | E39: 否 | F39: 系统架构组 | I39: 预研,ssl性能优化 | J39: 预研 | K39: 7028
A40: 李雪莲 | B40: AD | C40: 开发 | D40: T4 | E40: 否 | F40: 系统架构组 | I40: 定制 | J40: 定制 | K40: 定制 | L40: 休产假
...
